{"topic":"orderbook.50.BTCUSDT","ts":1786191785896,"type":"delta","data":{"s":"BTCUSDT","b":[["64975.9","3.462376"]],"a":[],"u":184066864,"seq":112464949575},"cts":1786191785877}
{"topic":"orderbook.50.BTCUSDT","ts":1786191785916,"type":"delta","data":{"s":"BTCUSDT","b":[],"a":[["64976","2.006397"]],"u":184066865,"seq":112464949578},"cts":1786191785903}
{"topic":"orderbook.50.BTCUSDT","ts":1786191785956,"type":"delta","data":{"s":"BTCUSDT","b":[["64975.9","3.463136"]],"a":[],"u":184066866,"seq":112464949585},"cts":1786191785955}
{"topic":"orderbook.50.BTCUSDT","ts":1786191785976,"type":"delta","data":{"s":"BTCUSDT","b":[["64975.9","3.466936"]],"a":[],"u":184066867,"seq":112464949591},"cts":1786191785960}
{"topic":"orderbook.50.BTCUSDT","ts":1786191786016,"type":"delta","data":{"s":"BTCUSDT","b":[["64975.9","3.468344"]],"a":[],"u":184066868,"seq":112464949595},"cts":1786191786014}
{"topic":"orderbook.50.BTCUSDT","ts":1786191786035,"type":"delta","data":{"s":"BTCUSDT","b":[["64975.9","3.465304"]],"a":[],"u":184066869,"seq":112464949600},"cts":1786191786032}
{"topic":"orderbook.50.BTCUSDT","ts":1786191786076,"type":"delta","data":{"s":"BTCUSDT","b":[["64966.7","0.099705"],["64964.1","0"]],"a":[],"u":184066870,"seq":112464949605},"cts":1786191786063}
{"topic":"orderbook.50.BTCUSDT","ts":1786191786095,"type":"delta","data":{"s":"BTCUSDT","b":[["64975.9","3.464544"],["64966.7","0"],["64964.1","0.099706"]],"a":[],"u":184066871,"seq":112464949611},"cts":1786191786091}
{"topic":"orderbook.50.BTCUSDT","ts":1786191786116,"type":"delta","data":{"s":"BTCUSDT","b":[["64974.4","0.2"]],"a":[],"u":184066872,"seq":112464949613},"cts":1786191786106}
{"topic":"orderbook.50.BTCUSDT","ts":1786191786156,"type":"delta","data":{"s":"BTCUSDT","b":[["64975.9","3.463784"]],"a":[],"u":184066873,"seq":112464949618},"cts":1786191786151}
{"topic":"orderbook.50.BTCUSDT","ts":1786191786296,"type":"delta","data":{"s":"BTCUSDT","b":[["64975.9","3.466599"]],"a":[],"u":184066874,"seq":112464949634},"cts":1786191786290}
{"topic":"orderbook.50.BTCUSDT","ts":1786191786336,"type":"delta","data":{"s":"BTCUSDT","b":[["64973.9","0.123013"],["64960.6","0"]],"a":[],"u":184066875,"seq":112464949643},"cts":1786191786329}
{"topic":"orderbook.50.BTCUSDT","ts":1786191786375,"type":"delta","data":{"s":"BTCUSDT","b":[["64975.9","3.468119"]],"a":[],"u":184066876,"seq":112464949650},"cts":1786191786371}
{"topic":"orderbook.50.BTCUSDT","ts":1786191786396,"type":"delta","data":{"s":"BTCUSDT","b":[["64975.9","3.470399"]],"a":[],"u":184066877,"seq":112464949655},"cts":1786191786391}
{"topic":"orderbook.50.BTCUSDT","ts":1786191786456,"type":"delta","data":{"s":"BTCUSDT","b":[["64975.9","3.467359"]],"a":[],"u":184066878,"seq":112464949665},"cts":1786191786454}
{"topic":"orderbook.50.BTCUSDT","ts":1786191786476,"type":"delta","data":{"s":"BTCUSDT","b":[["64975.9","3.473439"]],"a":[],"u":184066879,"seq":112464949675},"cts":1786191786467}
{"topic":"orderbook.50.BTCUSDT","ts":1786191786535,"type":"delta","data":{"s":"BTCUSDT","b":[["64975.9","3.469639"]],"a":[],"u":184066880,"seq":112464949683},"cts":1786191786533}
