{"success":true,"ret_msg":"subscribe","conn_id":"d97jqsmfroiqmeginmkg-5og9a","op":"subscribe"}
{"topic":"orderbook.50.BTCUSDT","ts":1786191748636,"type":"snapshot","data":{"s":"BTCUSDT","b":[["64978.8","0.705782"],["64978.7","0.000093"],["64978.5","0.000324"],["64978.4","0.000186"],["64978","0.021478"],["64977.9","0.000093"],["64977.4","0.004303"],["64977.3","0.013557"],["64977","0.003078"],["64976.9","0.160899"],["64976.3","0.000099"],["64976","0.023774"],["64975.9","0.119547"],["64975.2","0.142233"],["64975.1","0.1282"],["64975","0.000232"],["64974.7","0.006"],["64974.4","0.2"],["64973.7","0.038487"],["64973.6","0.393443"],["64973.5","0.014783"],["64973.2","0.001924"],["64972.3","0.01135"],["64972","0.023899"],["64971.2","0.123013"],["64970.9","0.384446"],["64970.3","0.038488"],["64970.2","0.123048"],["64970","0.03828"],["64969.7","0.076976"],["64968.9","0.011"],["64968.8","0.000324"],["64968.5","0.000116"],["64968.3","0.15079"],["64967.8","0.099703"],["64967.7","0.123013"],["64967.3","0.0194"],["64966.8","0.037082"],["64966.6","0.002407"],["64966.3","0.151991"],["64966.2","0.384446"],["64965.5","0.000324"],["64965.2","0.038989"],["64965.1","0.202904"],["64964","0.038669"],["64963.7","0.001448"],["64963.6","0.000029"],["64963.5","0.390085"],["64963.4","0.123013"],["64963.3","0.004984"]],"a":[["64978.9","1.280772"],["64979","0.860664"],["64979.7","0.018349"],["64980","15.642452"],["64980.9","0.008298"],["64981","0.866142"],["64981.3","0.000093"],["64981.7","0.02283"],["64982","1.419551"],["64982.7","0.000186"],["64983","0.068846"],["64983.1","0.0025"],["64983.2","0.0025"],["64983.4","0.000093"],["64983.6","0.038488"],["64983.7","0.038488"],["64983.9","0.023426"],["64984.1","0.038488"],["64984.2","0.000093"],["64984.3","0.000186"],["64984.6","0.0025"],["64985","0.000324"],["64985.1","0.014783"],["64985.4","0.019149"],["64985.6","0.000279"],["64985.9","0.407203"],["64986","1.325677"],["64986.8","0.038487"],["64986.9","7.174355"],["64987","30"],["64987.3","0.000116"],["64987.8","0.0025"],["64988","0.373905"],["64988.3","0.000324"],["64988.5","0.000678"],["64989","1.138152"],["64989.4","0.0025"],["64989.6","0.150033"],["64989.7","0.03"],["64989.8","0.0025"],["64990","0.895423"],["64990.3","0.018892"],["64990.4","0.005603"],["64990.8","0.034776"],["64990.9","1.330965"],["64991","3"],["64991.4","0.246239"],["64991.5","0.000324"],["64991.9","0.02743"],["64992.6","0.0025"]],"u":184065882,"seq":112464940147},"cts":1786191748633}
{"topic":"orderbook.50.BTCUSDT","ts":1786191748656,"type":"delta","data":{"s":"BTCUSDT","b":[["64978.8","0.702742"],["64973.6","0.214623"]],"a":[],"u":184065883,"seq":112464940159},"cts":1786191748654}
{"topic":"orderbook.50.BTCUSDT","ts":1786191748676,"type":"delta","data":{"s":"BTCUSDT","b":[["64978.8","0.703502"]],"a":[],"u":184065884,"seq":112464940173},"cts":1786191748663}
{"topic":"orderbook.50.BTCUSDT","ts":1786191748696,"type":"delta","data":{"s":"BTCUSDT","b":[["64978.8","0.702742"]],"a":[["64978.9","1.347437"]],"u":184065885,"seq":112464940177},"cts":1786191748693}
{"topic":"orderbook.50.BTCUSDT","ts":1786191748716,"type":"delta","data":{"s":"BTCUSDT","b":[["64978.8","0.707302"],["64976.1","0.003586"],["64963.3","0"]],"a":[],"u":184065886,"seq":112464940189},"cts":1786191748715}
{"topic":"orderbook.50.BTCUSDT","ts":1786191748736,"type":"delta","data":{"s":"BTCUSDT","b":[["64978.8","0.706542"]],"a":[["64979.5","0.001542"],["64992.6","0"]],"u":184065887,"seq":112464940203},"cts":1786191748734}
{"topic":"orderbook.50.BTCUSDT","ts":1786191748776,"type":"delta","data":{"s":"BTCUSDT","b":[["64978.8","0.708822"],["64978","0.024555"],["64977","0"],["64974.8","0.002868"]],"a":[],"u":184065888,"seq":112464940212},"cts":1786191748774}
{"topic":"orderbook.50.BTCUSDT","ts":1786191748796,"type":"delta","data":{"s":"BTCUSDT","b":[["64978.8","0.703502"]],"a":[],"u":184065889,"seq":112464940222},"cts":1786191748793}
{"topic":"orderbook.50.BTCUSDT","ts":1786191748816,"type":"delta","data":{"s":"BTCUSDT","b":[["64978.8","0.705022"]],"a":[],"u":184065890,"seq":112464940227},"cts":1786191748809}
{"topic":"orderbook.50.BTCUSDT","ts":1786191748856,"type":"delta","data":{"s":"BTCUSDT","b":[["64978.8","0.703502"],["64973.5","0.016934"]],"a":[],"u":184065891,"seq":112464940237},"cts":1786191748852}
{"topic":"orderbook.50.BTCUSDT","ts":1786191748876,"type":"delta","data":{"s":"BTCUSDT","b":[["64978.8","0.708062"]],"a":[],"u":184065892,"seq":112464940244},"cts":1786191748874}
{"topic":"orderbook.50.BTCUSDT","ts":1786191748896,"type":"delta","data":{"s":"BTCUSDT","b":[["64978.8","0.706542"]],"a":[],"u":184065893,"seq":112464940249},"cts":1786191748892}
{"topic":"orderbook.50.BTCUSDT","ts":1786191748936,"type":"delta","data":{"s":"BTCUSDT","b":[["64972.2","0.001434"],["64963.4","0"]],"a":[],"u":184065894,"seq":112464940259},"cts":1786191748927}
{"topic":"orderbook.50.BTCUSDT","ts":1786191748956,"type":"delta","data":{"s":"BTCUSDT","b":[["64978.8","0.700462"]],"a":[],"u":184065895,"seq":112464940270},"cts":1786191748951}
{"topic":"orderbook.50.BTCUSDT","ts":1786191748976,"type":"delta","data":{"s":"BTCUSDT","b":[["64978.8","0.702742"]],"a":[],"u":184065896,"seq":112464940273},"cts":1786191748972}
{"topic":"orderbook.50.BTCUSDT","ts":1786191748995,"type":"delta","data":{"s":"BTCUSDT","b":[["64978.8","0.703502"]],"a":[["64978.9","1.352367"]],"u":184065897,"seq":112464940276},"cts":1786191748994}
{"topic":"orderbook.50.BTCUSDT","ts":1786191749055,"type":"delta","data":{"s":"BTCUSDT","b":[["64978.8","0.701222"],["64967.8","0"],["64966.9","0.099704"]],"a":[],"u":184065898,"seq":112464940308},"cts":1786191749053}
{"topic":"orderbook.50.BTCUSDT","ts":1786191749076,"type":"delta","data":{"s":"BTCUSDT","b":[["64978.8","0.707302"],["64967.8","0.099703"],["64966.9","0"]],"a":[["64980.2","0.004108"],["64991.9","0"]],"u":184065899,"seq":112464940319},"cts":1786191749068}
{"topic":"orderbook.50.BTCUSDT","ts":1786191749096,"type":"delta","data":{"s":"BTCUSDT","b":[["64978.8","0.708822"],["64967.8","0"],["64966.9","0.099704"]],"a":[],"u":184065900,"seq":112464940323},"cts":1786191749094}
{"topic":"orderbook.50.BTCUSDT","ts":1786191749116,"type":"delta","data":{"s":"BTCUSDT","b":[["64975.2","0.526679"]],"a":[["64985.6","0.000186"]],"u":184065901,"seq":112464940326},"cts":1786191749109}
{"topic":"orderbook.50.BTCUSDT","ts":1786191749136,"type":"delta","data":{"s":"BTCUSDT","b":[["64978.8","0.706542"],["64976.9","0.292697"],["64968.4","0.099702"],["64966.9","0"]],"a":[],"u":184065902,"seq":112464940348},"cts":1786191749134}
{"topic":"orderbook.50.BTCUSDT","ts":1786191749156,"type":"delta","data":{"s":"BTCUSDT","b":[["64978.8","0.700462"],["64963.5","0.13544"]],"a":[["64981.5","0.003287"],["64991.5","0"]],"u":184065903,"seq":112464940363},"cts":1786191749154}
{"topic":"orderbook.50.BTCUSDT","ts":1786191749176,"type":"delta","data":{"s":"BTCUSDT","b":[["64978.8","0.702742"]],"a":[],"u":184065904,"seq":112464940368},"cts":1786191749175}
{"topic":"orderbook.50.BTCUSDT","ts":1786191749196,"type":"delta","data":{"s":"BTCUSDT","b":[["64978.8","0.703502"]],"a":[],"u":184065905,"seq":112464940371},"cts":1786191749185}
{"topic":"orderbook.50.BTCUSDT","ts":1786191749216,"type":"delta","data":{"s":"BTCUSDT","b":[["64978.8","0.704262"],["64968.4","0"],["64967.8","0.099702"]],"a":[],"u":184065906,"seq":112464940377},"cts":1786191749214}
{"topic":"orderbook.50.BTCUSDT","ts":1786191749236,"type":"delta","data":{"s":"BTCUSDT","b":[["64978.8","0.706542"]],"a":[["64978.9","1.352323"],["64982.8","0.002465"],["64991.4","0"]],"u":184065907,"seq":112464940386},"cts":1786191749223}
{"topic":"orderbook.50.BTCUSDT","ts":1786191749255,"type":"delta","data":{"s":"BTCUSDT","b":[["64978.8","0.705022"]],"a":[],"u":184065908,"seq":112464940393},"cts":1786191749254}
{"topic":"orderbook.50.BTCUSDT","ts":1786191749276,"type":"delta","data":{"s":"BTCUSDT","b":[["64978.8","0.708062"]],"a":[],"u":184065909,"seq":112464940400},"cts":1786191749260}
{"topic":"orderbook.50.BTCUSDT","ts":1786191749296,"type":"delta","data":{"s":"BTCUSDT","b":[["64978.8","0.705782"]],"a":[["64984.1","0.040131"]],"u":184065910,"seq":112464940407},"cts":1786191749293}
{"topic":"orderbook.50.BTCUSDT","ts":1786191749316,"type":"delta","data":{"s":"BTCUSDT","b":[["64978.8","0.706542"]],"a":[],"u":184065911,"seq":112464940413},"cts":1786191749315}
{"topic":"orderbook.50.BTCUSDT","ts":1786191749336,"type":"delta","data":{"s":"BTCUSDT","b":[["64978.8","0.705022"]],"a":[],"u":184065912,"seq":112464940423},"cts":1786191749332}
{"topic":"orderbook.50.BTCUSDT","ts":1786191749356,"type":"delta","data":{"s":"BTCUSDT","b":[["64978.8","0.703502"]],"a":[],"u":184065913,"seq":112464940426},"cts":1786191749344}
{"topic":"orderbook.50.BTCUSDT","ts":1786191749396,"type":"delta","data":{"s":"BTCUSDT","b":[["64978.8","0.702742"]],"a":[],"u":184065914,"seq":112464940432},"cts":1786191749395}
{"topic":"orderbook.50.BTCUSDT","ts":1786191749419,"type":"delta","data":{"s":"BTCUSDT","b":[["64978.8","0.705022"]],"a":[],"u":184065915,"seq":112464940446},"cts":1786191749418}
{"topic":"orderbook.50.BTCUSDT","ts":1786191749436,"type":"delta","data":{"s":"BTCUSDT","b":[],"a":[["64979.7","0"],["64991.4","0.246239"]],"u":184065916,"seq":112464940447},"cts":1786191749432}
{"topic":"orderbook.50.BTCUSDT","ts":1786191749456,"type":"delta","data":{"s":"BTCUSDT","b":[["64978.8","0.70152"]],"a":[],"u":184065917,"seq":112464940472},"cts":1786191749455}
{"topic":"orderbook.50.BTCUSDT","ts":1786191749476,"type":"delta","data":{"s":"BTCUSDT","b":[["64978.8","0.70228"]],"a":[],"u":184065918,"seq":112464940475},"cts":1786191749460}
{"topic":"orderbook.50.BTCUSDT","ts":1786191749496,"type":"delta","data":{"s":"BTCUSDT","b":[["64978.8","0.69848"]],"a":[],"u":184065919,"seq":112464940481},"cts":1786191749493}
{"topic":"orderbook.50.BTCUSDT","ts":1786191749536,"type":"delta","data":{"s":"BTCUSDT","b":[["64978.8","0.69468"]],"a":[["64978.9","1.346354"]],"u":184065920,"seq":112464940490},"cts":1786191749532}
{"topic":"orderbook.50.BTCUSDT","ts":1786191749576,"type":"delta","data":{"s":"BTCUSDT","b":[["64978.8","0.69772"]],"a":[],"u":184065921,"seq":112464940495},"cts":1786191749574}
{"topic":"orderbook.50.BTCUSDT","ts":1786191749596,"type":"delta","data":{"s":"BTCUSDT","b":[],"a":[["64978.9","1.345585"]],"u":184065922,"seq":112464940496},"cts":1786191749586}
{"topic":"orderbook.50.BTCUSDT","ts":1786191749615,"type":"delta","data":{"s":"BTCUSDT","b":[["64978.8","0.7038"]],"a":[],"u":184065923,"seq":112464940505},"cts":1786191749614}
{"topic":"orderbook.50.BTCUSDT","ts":1786191749635,"type":"delta","data":{"s":"BTCUSDT","b":[["64978.4","0.000372"]],"a":[],"u":184065924,"seq":112464940507},"cts":1786191749619}
{"topic":"orderbook.50.BTCUSDT","ts":1786191749656,"type":"delta","data":{"s":"BTCUSDT","b":[["64978.8","0.70228"]],"a":[],"u":184065925,"seq":112464940514},"cts":1786191749653}
{"topic":"orderbook.50.BTCUSDT","ts":1786191749676,"type":"delta","data":{"s":"BTCUSDT","b":[["64978.8","0.714686"]],"a":[],"u":184065926,"seq":112464940517},"cts":1786191749668}
{"topic":"orderbook.50.BTCUSDT","ts":1786191749696,"type":"delta","data":{"s":"BTCUSDT","b":[["64978.8","0.708606"]],"a":[],"u":184065927,"seq":112464940526},"cts":1786191749694}
{"topic":"orderbook.50.BTCUSDT","ts":1786191749716,"type":"delta","data":{"s":"BTCUSDT","b":[["64978.8","0.709366"]],"a":[],"u":184065928,"seq":112464940529},"cts":1786191749707}
{"topic":"orderbook.50.BTCUSDT","ts":1786191749737,"type":"delta","data":{"s":"BTCUSDT","b":[["64978.8","0.707846"]],"a":[],"u":184065929,"seq":112464940533},"cts":1786191749734}
{"topic":"orderbook.50.BTCUSDT","ts":1786191749756,"type":"delta","data":{"s":"BTCUSDT","b":[["64978.8","0.724004"]],"a":[["64978.9","1.321703"]],"u":184065930,"seq":112464940540},"cts":1786191749754}
{"topic":"orderbook.50.BTCUSDT","ts":1786191749796,"type":"delta","data":{"s":"BTCUSDT","b":[["64978.8","0.723244"]],"a":[],"u":184065931,"seq":112464940541},"cts":1786191749781}
{"topic":"orderbook.50.BTCUSDT","ts":1786191749816,"type":"delta","data":{"s":"BTCUSDT","b":[["64978.8","0.707086"]],"a":[],"u":184065932,"seq":112464940548},"cts":1786191749815}
{"topic":"orderbook.50.BTCUSDT","ts":1786191749836,"type":"delta","data":{"s":"BTCUSDT","b":[["64978.8","0.712406"],["64965.4","0.001077"],["64963.5","0"]],"a":[],"u":184065933,"seq":112464940557},"cts":1786191749826}
{"topic":"orderbook.50.BTCUSDT","ts":1786191749916,"type":"delta","data":{"s":"BTCUSDT","b":[["64978.8","0.713166"]],"a":[],"u":184065934,"seq":112464940578},"cts":1786191749912}
{"topic":"orderbook.50.BTCUSDT","ts":1786191749956,"type":"delta","data":{"s":"BTCUSDT","b":[["64968.4","0.099702"],["64967.8","0"]],"a":[],"u":184065935,"seq":112464940618},"cts":1786191749953}
{"topic":"orderbook.50.BTCUSDT","ts":1786191749975,"type":"delta","data":{"s":"BTCUSDT","b":[["64968.4","0"],["64967.8","0.099702"]],"a":[],"u":184065936,"seq":112464940622},"cts":1786191749974}
{"topic":"orderbook.50.BTCUSDT","ts":1786191749996,"type":"delta","data":{"s":"BTCUSDT","b":[["64978.8","0.707086"]],"a":[["64978.9","1.255038"]],"u":184065937,"seq":112464940634},"cts":1786191749991}
{"topic":"orderbook.50.BTCUSDT","ts":1786191750076,"type":"delta","data":{"s":"BTCUSDT","b":[["64978.8","0.712406"]],"a":[],"u":184065938,"seq":112464940650},"cts":1786191750074}
{"topic":"orderbook.50.BTCUSDT","ts":1786191750116,"type":"delta","data":{"s":"BTCUSDT","b":[["64977.9","0"],["64963.5","0.390085"]],"a":[["64985.6","0"],["64991.5","0.000324"]],"u":184065939,"seq":112464940655},"cts":1786191750110}
{"topic":"orderbook.50.BTCUSDT","ts":1786191750156,"type":"delta","data":{"s":"BTCUSDT","b":[["64978.8","0.707086"]],"a":[],"u":184065940,"seq":112464940666},"cts":1786191750154}
{"topic":"orderbook.50.BTCUSDT","ts":1786191750176,"type":"delta","data":{"s":"BTCUSDT","b":[["64978.8","0.710886"]],"a":[],"u":184065941,"seq":112464940675},"cts":1786191750173}
{"topic":"orderbook.50.BTCUSDT","ts":1786191750196,"type":"delta","data":{"s":"BTCUSDT","b":[],"a":[["64979.1","0.000093"],["64980.1","0.000093"],["64991.4","0"],["64991.5","0"]],"u":184065942,"seq":112464940677},"cts":1786191750185}
{"topic":"orderbook.50.BTCUSDT","ts":1786191750236,"type":"delta","data":{"s":"BTCUSDT","b":[["64978.8","0.711646"],["64969","0.099701"],["64967.8","0"],["64963.5","0.13544"]],"a":[],"u":184065943,"seq":112464940696},"cts":1786191750232}
{"topic":"orderbook.50.BTCUSDT","ts":1786191750256,"type":"delta","data":{"s":"BTCUSDT","b":[["64978.8","0.709366"],["64969","0"],["64968.4","0.099701"]],"a":[],"u":184065944,"seq":112464940705},"cts":1786191750253}
{"topic":"orderbook.50.BTCUSDT","ts":1786191750276,"type":"delta","data":{"s":"BTCUSDT","b":[["64978.8","0.713166"]],"a":[],"u":184065945,"seq":112464940715},"cts":1786191750265}
{"topic":"orderbook.50.BTCUSDT","ts":1786191750316,"type":"delta","data":{"s":"BTCUSDT","b":[["64978.8","0.711646"]],"a":[],"u":184065946,"seq":112464940722},"cts":1786191750313}
{"topic":"orderbook.50.BTCUSDT","ts":1786191750336,"type":"delta","data":{"s":"BTCUSDT","b":[["64978.8","0.707846"],["64968.4","0"],["64967.8","0.099703"]],"a":[],"u":184065947,"seq":112464940732},"cts":1786191750333}
{"topic":"orderbook.50.BTCUSDT","ts":1786191750356,"type":"delta","data":{"s":"BTCUSDT","b":[["64978.8","0.711963"],["64967.8","0"],["64967.4","0.099703"],["64965.4","0"],["64963.4","0.123013"]],"a":[],"u":184065948,"seq":112464940742},"cts":1786191750355}
{"topic":"orderbook.50.BTCUSDT","ts":1786191750376,"type":"delta","data":{"s":"BTCUSDT","b":[["64968.4","0.099702"],["64967.4","0"]],"a":[],"u":184065949,"seq":112464940744},"cts":1786191750359}
{"topic":"orderbook.50.BTCUSDT","ts":1786191750416,"type":"delta","data":{"s":"BTCUSDT","b":[["64978.8","0.714243"],["64968.4","0"],["64967.8","0.099702"]],"a":[],"u":184065950,"seq":112464940752},"cts":1786191750415}
{"topic":"orderbook.50.BTCUSDT","ts":1786191750436,"type":"delta","data":{"s":"BTCUSDT","b":[["64978.8","0.711203"]],"a":[],"u":184065951,"seq":112464940761},"cts":1786191750431}
{"topic":"orderbook.50.BTCUSDT","ts":1786191750495,"type":"delta","data":{"s":"BTCUSDT","b":[["64978.8","0.708163"]],"a":[],"u":184065952,"seq":112464940768},"cts":1786191750491}
{"topic":"orderbook.50.BTCUSDT","ts":1786191750516,"type":"delta","data":{"s":"BTCUSDT","b":[["64978.8","0.712273"]],"a":[],"u":184065953,"seq":112464940773},"cts":1786191750510}
{"topic":"orderbook.50.BTCUSDT","ts":1786191750535,"type":"delta","data":{"s":"BTCUSDT","b":[["64978.8","0.713033"]],"a":[],"u":184065954,"seq":112464940775},"cts":1786191750519}
{"topic":"orderbook.50.BTCUSDT","ts":1786191750576,"type":"delta","data":{"s":"BTCUSDT","b":[["64978.8","0.713793"]],"a":[],"u":184065955,"seq":112464940779},"cts":1786191750574}
{"topic":"orderbook.50.BTCUSDT","ts":1786191750596,"type":"delta","data":{"s":"BTCUSDT","b":[["64978.8","0.712273"]],"a":[],"u":184065956,"seq":112464940788},"cts":1786191750591}
{"topic":"orderbook.50.BTCUSDT","ts":1786191750616,"type":"delta","data":{"s":"BTCUSDT","b":[["64978.8","0.714243"]],"a":[],"u":184065957,"seq":112464940795},"cts":1786191750612}
{"topic":"orderbook.50.BTCUSDT","ts":1786191750636,"type":"delta","data":{"s":"BTCUSDT","b":[["64978.8","0.715003"]],"a":[],"u":184065958,"seq":112464940797},"cts":1786191750618}
{"topic":"orderbook.50.BTCUSDT","ts":1786191750656,"type":"delta","data":{"s":"BTCUSDT","b":[["64978.8","0.712723"],["64967.8","0"],["64966.9","0.099704"]],"a":[],"u":184065959,"seq":112464940804},"cts":1786191750653}
{"topic":"orderbook.50.BTCUSDT","ts":1786191750696,"type":"delta","data":{"s":"BTCUSDT","b":[["64978.8","0.708163"],["64967.8","0.099702"],["64966.9","0"]],"a":[],"u":184065960,"seq":112464940815},"cts":1786191750691}
{"topic":"orderbook.50.BTCUSDT","ts":1786191750716,"type":"delta","data":{"s":"BTCUSDT","b":[["64978.8","0.712723"]],"a":[],"u":184065961,"seq":112464940821},"cts":1786191750714}
{"topic":"orderbook.50.BTCUSDT","ts":1786191750796,"type":"delta","data":{"s":"BTCUSDT","b":[["64978.8","0.708163"],["64977.8","0.000093"],["64976.8","0.000093"],["64963.5","0"],["64963.4","0"]],"a":[],"u":184065962,"seq":112464940836},"cts":1786191750790}
{"topic":"orderbook.50.BTCUSDT","ts":1786191750856,"type":"delta","data":{"s":"BTCUSDT","b":[["64978.8","0"],["64978.7","0"],["64978.5","0"],["64978.4","0"],["64978","0.52603"],["64972.3","0"],["64971.5","0.0081"],["64968.6","0.038489"],["64968.3","0.1282"],["64966.1","0.019983"],["64963.5","0.13544"],["64963.4","0.123013"]],"a":[["64978.1","0.780526"],["64978.8","0.175"],["64978.9","0.108228"],["64981.9","0.038489"],["64984.6","0.0106"],["64985.3","0.007799"],["64985.4","0"],["64990.8","0"],["64990.9","0"],["64991","0"]],"u":184065963,"seq":112464941031},"cts":1786191750854}
{"topic":"orderbook.50.BTCUSDT","ts":1786191750876,"type":"delta","data":{"s":"BTCUSDT","b":[["64976.3","0"],["64975.5","0.000118"],["64963.5","0.390085"]],"a":[["64978.1","0.860408"],["64978.9","0.028346"],["64981.8","0.000324"],["64984.6","0.018399"],["64985.3","0"]],"u":184065964,"seq":112464941056},"cts":1786191750874}
{"topic":"orderbook.50.BTCUSDT","ts":1786191750916,"type":"delta","data":{"s":"BTCUSDT","b":[["64978","0.738584"]],"a":[],"u":184065965,"seq":112464941070},"cts":1786191750914}
{"topic":"orderbook.50.BTCUSDT","ts":1786191750936,"type":"delta","data":{"s":"BTCUSDT","b":[["64978","0.740864"],["64977.4","0"],["64967.8","0"],["64966.4","0.099705"],["64963.5","0.13544"],["64962.3","0.015713"]],"a":[],"u":184065966,"seq":112464941102},"cts":1786191750934}
{"topic":"orderbook.50.BTCUSDT","ts":1786191750956,"type":"delta","data":{"s":"BTCUSDT","b":[["64978","0.741624"],["64966.9","0.099704"],["64966.4","0"]],"a":[],"u":184065967,"seq":112464941107},"cts":1786191750950}
{"topic":"orderbook.50.BTCUSDT","ts":1786191750976,"type":"delta","data":{"s":"BTCUSDT","b":[["64978","0.749984"]],"a":[],"u":184065968,"seq":112464941120},"cts":1786191750968}
{"topic":"orderbook.50.BTCUSDT","ts":1786191750996,"type":"delta","data":{"s":"BTCUSDT","b":[["64967.4","0.099703"],["64966.9","0"]],"a":[],"u":184065969,"seq":112464941124},"cts":1786191750991}
{"topic":"orderbook.50.BTCUSDT","ts":1786191751018,"type":"delta","data":{"s":"BTCUSDT","b":[["64978","0.747704"],["64976.1","0"],["64962","0.000116"]],"a":[["64978.8","0.0468"]],"u":184065970,"seq":112464941132},"cts":1786191751017}
{"topic":"orderbook.50.BTCUSDT","ts":1786191751036,"type":"delta","data":{"s":"BTCUSDT","b":[["64978","0.744664"]],"a":[],"u":184065971,"seq":112464941140},"cts":1786191751032}
{"topic":"orderbook.50.BTCUSDT","ts":1786191751056,"type":"delta","data":{"s":"BTCUSDT","b":[["64978","0.738584"]],"a":[],"u":184065972,"seq":112464941154},"cts":1786191751051}
{"topic":"orderbook.50.BTCUSDT","ts":1786191751076,"type":"delta","data":{"s":"BTCUSDT","b":[["64976.8","0"],["64961.6","0.004984"]],"a":[],"u":184065973,"seq":112464941157},"cts":1786191751074}
{"topic":"orderbook.50.BTCUSDT","ts":1786191751096,"type":"delta","data":{"s":"BTCUSDT","b":[["64974.8","0"],["64960.6","0.164757"]],"a":[],"u":184065974,"seq":112464941159},"cts":1786191751080}
{"topic":"orderbook.50.BTCUSDT","ts":1786191751116,"type":"delta","data":{"s":"BTCUSDT","b":[["64978","0.740104"]],"a":[],"u":184065975,"seq":112464941164},"cts":1786191751110}
{"topic":"orderbook.50.BTCUSDT","ts":1786191751136,"type":"delta","data":{"s":"BTCUSDT","b":[["64978","0.745424"],["64967.8","0.099703"],["64967.4","0"]],"a":[],"u":184065976,"seq":112464941175},"cts":1786191751132}
{"topic":"orderbook.50.BTCUSDT","ts":1786191751156,"type":"delta","data":{"s":"BTCUSDT","b":[["64973.5","0.014783"],["64968.4","0.099702"],["64967.8","0"]],"a":[],"u":184065977,"seq":112464941182},"cts":1786191751153}
{"topic":"orderbook.50.BTCUSDT","ts":1786191751196,"type":"delta","data":{"s":"BTCUSDT","b":[["64978","0.740104"]],"a":[],"u":184065978,"seq":112464941191},"cts":1786191751194}
{"topic":"orderbook.50.BTCUSDT","ts":1786191751216,"type":"delta","data":{"s":"BTCUSDT","b":[["64978","0.742384"],["64968.4","0"],["64967.8","0.099702"]],"a":[],"u":184065979,"seq":112464941201},"cts":1786191751213}
{"topic":"orderbook.50.BTCUSDT","ts":1786191751236,"type":"delta","data":{"s":"BTCUSDT","b":[["64972.2","0"],["64960.5","0.617969"]],"a":[],"u":184065980,"seq":112464941204},"cts":1786191751233}
{"topic":"orderbook.50.BTCUSDT","ts":1786191751256,"type":"delta","data":{"s":"BTCUSDT","b":[["64967.8","0"],["64967.4","0.099704"]],"a":[],"u":184065981,"seq":112464941218},"cts":1786191751252}
{"topic":"orderbook.50.BTCUSDT","ts":1786191751276,"type":"delta","data":{"s":"BTCUSDT","b":[["64978","0.744664"]],"a":[],"u":184065982,"seq":112464941224},"cts":1786191751273}
{"topic":"orderbook.50.BTCUSDT","ts":1786191751296,"type":"delta","data":{"s":"BTCUSDT","b":[["64978","0.740864"]],"a":[],"u":184065983,"seq":112464941229},"cts":1786191751288}
{"topic":"orderbook.50.BTCUSDT","ts":1786191751316,"type":"delta","data":{"s":"BTCUSDT","b":[["64978","0.743144"]],"a":[],"u":184065984,"seq":112464941234},"cts":1786191751307}
{"topic":"orderbook.50.BTCUSDT","ts":1786191751336,"type":"delta","data":{"s":"BTCUSDT","b":[],"a":[["64978.9","0.023416"]],"u":184065985,"seq":112464941237},"cts":1786191751331}
{"topic":"orderbook.50.BTCUSDT","ts":1786191751356,"type":"delta","data":{"s":"BTCUSDT","b":[],"a":[["64983.4","0"],["64984.2","0"],["64990.8","0.034776"],["64990.9","1.330965"]],"u":184065986,"seq":112464941245},"cts":1786191751354}
{"topic":"orderbook.50.BTCUSDT","ts":1786191751376,"type":"delta","data":{"s":"BTCUSDT","b":[["64978","0.76194"]],"a":[["64978.1","0.876715"]],"u":184065987,"seq":112464941252},"cts":1786191751370}
{"topic":"orderbook.50.BTCUSDT","ts":1786191751396,"type":"delta","data":{"s":"BTCUSDT","b":[["64978","0.7589"]],"a":[["64978.1","0.892786"],["64980.2","0"],["64991","3"]],"u":184065988,"seq":112464941263},"cts":1786191751391}
{"topic":"orderbook.50.BTCUSDT","ts":1786191751436,"type":"delta","data":{"s":"BTCUSDT","b":[["64967.8","0.099703"],["64967.4","0"]],"a":[],"u":184065989,"seq":112464941268},"cts":1786191751430}
{"topic":"orderbook.50.BTCUSDT","ts":1786191751455,"type":"delta","data":{"s":"BTCUSDT","b":[["64978","0.75586"]],"a":[],"u":184065990,"seq":112464941277},"cts":1786191751453}
{"topic":"orderbook.50.BTCUSDT","ts":1786191751476,"type":"delta","data":{"s":"BTCUSDT","b":[["64978","0.7589"]],"a":[["64981.5","0"],["64991.1","0.006"]],"u":184065991,"seq":112464941285},"cts":1786191751464}
{"topic":"orderbook.50.BTCUSDT","ts":1786191751496,"type":"delta","data":{"s":"BTCUSDT","b":[["64978","0.76042"]],"a":[["64978.1","0.909812"]],"u":184065992,"seq":112464941289},"cts":1786191751480}
{"topic":"orderbook.50.BTCUSDT","ts":1786191751536,"type":"delta","data":{"s":"BTCUSDT","b":[["64978","0.75662"]],"a":[["64982.8","0"],["64991.4","0.246239"]],"u":184065993,"seq":112464941300},"cts":1786191751533}
{"topic":"orderbook.50.BTCUSDT","ts":1786191751556,"type":"delta","data":{"s":"BTCUSDT","b":[],"a":[["64978.1","0.892786"]],"u":184065994,"seq":112464941301},"cts":1786191751540}
{"topic":"orderbook.50.BTCUSDT","ts":1786191751576,"type":"delta","data":{"s":"BTCUSDT","b":[["64978","0.7589"]],"a":[],"u":184065995,"seq":112464941308},"cts":1786191751575}
{"topic":"orderbook.50.BTCUSDT","ts":1786191751617,"type":"delta","data":{"s":"BTCUSDT","b":[["64978","0.75966"]],"a":[["64984.1","0.038488"]],"u":184065996,"seq":112464941312},"cts":1786191751609}
{"topic":"orderbook.50.BTCUSDT","ts":1786191751636,"type":"delta","data":{"s":"BTCUSDT","b":[],"a":[["64978.1","0.876715"]],"u":184065997,"seq":112464941314},"cts":1786191751633}
{"topic":"orderbook.50.BTCUSDT","ts":1786191751656,"type":"delta","data":{"s":"BTCUSDT","b":[["64978","0.75662"]],"a":[],"u":184065998,"seq":112464941320},"cts":1786191751652}
{"topic":"orderbook.50.BTCUSDT","ts":1786191751676,"type":"delta","data":{"s":"BTCUSDT","b":[["64978","0.76042"]],"a":[],"u":184065999,"seq":112464941327},"cts":1786191751664}
{"topic":"orderbook.50.BTCUSDT","ts":1786191751696,"type":"delta","data":{"s":"BTCUSDT","b":[["64978","0.75966"]],"a":[],"u":184066000,"seq":112464941329},"cts":1786191751688}
{"topic":"orderbook.50.BTCUSDT","ts":1786191751716,"type":"delta","data":{"s":"BTCUSDT","b":[["64978","0.76118"]],"a":[],"u":184066001,"seq":112464941331},"cts":1786191751713}
{"topic":"orderbook.50.BTCUSDT","ts":1786191751736,"type":"delta","data":{"s":"BTCUSDT","b":[["64978","0.76042"],["64976.6","0.004303"],["64960.5","0"]],"a":[],"u":184066002,"seq":112464941346},"cts":1786191751734}
{"topic":"orderbook.50.BTCUSDT","ts":1786191751796,"type":"delta","data":{"s":"BTCUSDT","b":[["64978","0.75814"]],"a":[],"u":184066003,"seq":112464941354},"cts":1786191751791}
{"topic":"orderbook.50.BTCUSDT","ts":1786191751818,"type":"delta","data":{"s":"BTCUSDT","b":[["64978","0.75966"],["64975.3","0.003586"],["64960.6","0"]],"a":[],"u":184066004,"seq":112464941365},"cts":1786191751812}
{"topic":"orderbook.50.BTCUSDT","ts":1786191751876,"type":"delta","data":{"s":"BTCUSDT","b":[["64978","0.76042"]],"a":[],"u":184066005,"seq":112464941374},"cts":1786191751874}
{"topic":"orderbook.50.BTCUSDT","ts":1786191751896,"type":"delta","data":{"s":"BTCUSDT","b":[["64978","0.75586"],["64974","0.002868"],["64961.6","0"]],"a":[],"u":184066006,"seq":112464941384},"cts":1786191751890}
{"topic":"orderbook.50.BTCUSDT","ts":1786191751916,"type":"delta","data":{"s":"BTCUSDT","b":[],"a":[["64978.9","0.023509"]],"u":184066007,"seq":112464941386},"cts":1786191751902}
{"topic":"orderbook.50.BTCUSDT","ts":1786191751956,"type":"delta","data":{"s":"BTCUSDT","b":[["64978","0.7551"],["64972.7","0.002151"],["64962","0"]],"a":[],"u":184066008,"seq":112464941396},"cts":1786191751951}
{"topic":"orderbook.50.BTCUSDT","ts":1786191751975,"type":"delta","data":{"s":"BTCUSDT","b":[["64978","0.75586"]],"a":[],"u":184066009,"seq":112464941397},"cts":1786191751972}
{"topic":"orderbook.50.BTCUSDT","ts":1786191751996,"type":"delta","data":{"s":"BTCUSDT","b":[["64978","0.75738"]],"a":[],"u":184066010,"seq":112464941400},"cts":1786191751984}
{"topic":"orderbook.50.BTCUSDT","ts":1786191752036,"type":"delta","data":{"s":"BTCUSDT","b":[["64971.4","0.001434"],["64962.3","0"]],"a":[],"u":184066011,"seq":112464941401},"cts":1786191752021}
{"topic":"orderbook.50.BTCUSDT","ts":1786191752056,"type":"delta","data":{"s":"BTCUSDT","b":[["64978","0.75586"]],"a":[],"u":184066012,"seq":112464941406},"cts":1786191752051}
{"topic":"orderbook.50.BTCUSDT","ts":1786191752076,"type":"delta","data":{"s":"BTCUSDT","b":[["64978","0.7627"]],"a":[],"u":184066013,"seq":112464941416},"cts":1786191752065}
{"topic":"orderbook.50.BTCUSDT","ts":1786191752116,"type":"delta","data":{"s":"BTCUSDT","b":[],"a":[["64978.1","0.881645"]],"u":184066014,"seq":112464941418},"cts":1786191752096}
{"topic":"orderbook.50.BTCUSDT","ts":1786191752136,"type":"delta","data":{"s":"BTCUSDT","b":[["64978","0.75738"]],"a":[],"u":184066015,"seq":112464941425},"cts":1786191752131}
{"topic":"orderbook.50.BTCUSDT","ts":1786191752156,"type":"delta","data":{"s":"BTCUSDT","b":[["64978","0.7551"]],"a":[],"u":184066016,"seq":112464941429},"cts":1786191752141}
{"topic":"orderbook.50.BTCUSDT","ts":1786191752176,"type":"delta","data":{"s":"BTCUSDT","b":[["64978","0.75586"]],"a":[["64979.4","0.004108"],["64991.4","0"]],"u":184066017,"seq":112464941431},"cts":1786191752173}
{"topic":"orderbook.50.BTCUSDT","ts":1786191752196,"type":"delta","data":{"s":"BTCUSDT","b":[["64978","0.75814"]],"a":[],"u":184066018,"seq":112464941436},"cts":1786191752190}
{"topic":"orderbook.50.BTCUSDT","ts":1786191752256,"type":"delta","data":{"s":"BTCUSDT","b":[["64978","0.7551"]],"a":[["64980.7","0.003287"],["64991.1","0"]],"u":184066019,"seq":112464941442},"cts":1786191752251}
{"topic":"orderbook.50.BTCUSDT","ts":1786191752276,"type":"delta","data":{"s":"BTCUSDT","b":[["64978","0.76194"]],"a":[],"u":184066020,"seq":112464941452},"cts":1786191752266}
{"topic":"orderbook.50.BTCUSDT","ts":1786191752296,"type":"delta","data":{"s":"BTCUSDT","b":[],"a":[["64978.1","0.881798"]],"u":184066021,"seq":112464941455},"cts":1786191752293}
{"topic":"orderbook.50.BTCUSDT","ts":1786191752316,"type":"delta","data":{"s":"BTCUSDT","b":[["64978","0.746184"]],"a":[["64982","1.422016"],["64984.3","0.000093"]],"u":184066022,"seq":112464941463},"cts":1786191752315}
{"topic":"orderbook.50.BTCUSDT","ts":1786191752336,"type":"delta","data":{"s":"BTCUSDT","b":[["64978","0.742384"]],"a":[],"u":184066023,"seq":112464941469},"cts":1786191752334}
{"topic":"orderbook.50.BTCUSDT","ts":1786191752356,"type":"delta","data":{"s":"BTCUSDT","b":[["64978","0.739344"]],"a":[],"u":184066024,"seq":112464941477},"cts":1786191752354}
{"topic":"orderbook.50.BTCUSDT","ts":1786191752376,"type":"delta","data":{"s":"BTCUSDT","b":[["64978","0.740104"],["64968.4","0.099702"],["64967.8","0"]],"a":[],"u":184066025,"seq":112464941482},"cts":1786191752373}
{"topic":"orderbook.50.BTCUSDT","ts":1786191752396,"type":"delta","data":{"s":"BTCUSDT","b":[["64978","0.746634"],["64971.5","0.01135"]],"a":[["64978.1","0.886048"],["64983.3","0.001643"],["64984.6","0.022649"],["64991","0"]],"u":184066026,"seq":112464941495},"cts":1786191752393}
{"topic":"orderbook.50.BTCUSDT","ts":1786191752416,"type":"delta","data":{"s":"BTCUSDT","b":[["64978","0.751714"],["64968.4","0"],["64967.8","0.099703"]],"a":[["64978.4","0.000093"],["64990.9","0"]],"u":184066027,"seq":112464941506},"cts":1786191752415}
{"topic":"orderbook.50.BTCUSDT","ts":1786191752436,"type":"delta","data":{"s":"BTCUSDT","b":[],"a":[["64978.8","0.048337"]],"u":184066028,"seq":112464941507},"cts":1786191752427}
{"topic":"orderbook.50.BTCUSDT","ts":1786191752456,"type":"delta","data":{"s":"BTCUSDT","b":[["64978","0.747914"]],"a":[],"u":184066029,"seq":112464941513},"cts":1786191752451}
{"topic":"orderbook.50.BTCUSDT","ts":1786191752476,"type":"delta","data":{"s":"BTCUSDT","b":[["64978","0.749434"]],"a":[],"u":184066030,"seq":112464941516},"cts":1786191752466}
{"topic":"orderbook.50.BTCUSDT","ts":1786191752496,"type":"delta","data":{"s":"BTCUSDT","b":[["64978","0.743354"]],"a":[],"u":184066031,"seq":112464941527},"cts":1786191752492}
{"topic":"orderbook.50.BTCUSDT","ts":1786191752516,"type":"delta","data":{"s":"BTCUSDT","b":[],"a":[["64978.1","0.869741"]],"u":184066032,"seq":112464941532},"cts":1786191752500}
{"topic":"orderbook.50.BTCUSDT","ts":1786191752555,"type":"delta","data":{"s":"BTCUSDT","b":[],"a":[["64981","0.865581"]],"u":184066033,"seq":112464941538},"cts":1786191752551}
{"topic":"orderbook.50.BTCUSDT","ts":1786191752576,"type":"delta","data":{"s":"BTCUSDT","b":[["64978","0.746394"]],"a":[],"u":184066034,"seq":112464941550},"cts":1786191752570}
{"topic":"orderbook.50.BTCUSDT","ts":1786191752596,"type":"delta","data":{"s":"BTCUSDT","b":[["64978","0.748674"]],"a":[],"u":184066035,"seq":112464941554},"cts":1786191752594}
{"topic":"orderbook.50.BTCUSDT","ts":1786191752636,"type":"delta","data":{"s":"BTCUSDT","b":[["64978","0.746394"]],"a":[["64978.2","0.000561"],["64990.8","0"]],"u":184066036,"seq":112464941559},"cts":1786191752631}
{"topic":"orderbook.50.BTCUSDT","ts":1786191752656,"type":"delta","data":{"s":"BTCUSDT","b":[["64978","0.742594"]],"a":[],"u":184066037,"seq":112464941566},"cts":1786191752650}
{"topic":"orderbook.50.BTCUSDT","ts":1786191752716,"type":"delta","data":{"s":"BTCUSDT","b":[["64968.4","0.099702"],["64967.8","0"]],"a":[],"u":184066038,"seq":112464941570},"cts":1786191752708}
{"topic":"orderbook.50.BTCUSDT","ts":1786191752756,"type":"delta","data":{"s":"BTCUSDT","b":[["64978","0.736094"],["64968.4","0"],["64967.8","0.099703"]],"a":[],"u":184066039,"seq":112464941574},"cts":1786191752754}
{"topic":"orderbook.50.BTCUSDT","ts":1786191752776,"type":"delta","data":{"s":"BTCUSDT","b":[["64978","0.75276"]],"a":[],"u":184066040,"seq":112464941583},"cts":1786191752774}
{"topic":"orderbook.50.BTCUSDT","ts":1786191752816,"type":"delta","data":{"s":"BTCUSDT","b":[["64978","0.752"]],"a":[],"u":184066041,"seq":112464941585},"cts":1786191752806}
{"topic":"orderbook.50.BTCUSDT","ts":1786191752976,"type":"delta","data":{"s":"BTCUSDT","b":[["64974","0.003054"],["64965.9","0.001077"],["64963.4","0"]],"a":[],"u":184066042,"seq":112464941615},"cts":1786191752973}
{"topic":"orderbook.50.BTCUSDT","ts":1786191753316,"type":"delta","data":{"s":"BTCUSDT","b":[],"a":[["64978.2","0"],["64990.8","0.034776"]],"u":184066043,"seq":112464941630},"cts":1786191753306}
{"topic":"orderbook.50.BTCUSDT","ts":1786191753356,"type":"delta","data":{"s":"BTCUSDT","b":[["64976.4","0.0025"],["64963.5","0"]],"a":[["64979.6","0.0025"],["64984.3","0"]],"u":184066044,"seq":112464941633},"cts":1786191753340}
{"topic":"orderbook.50.BTCUSDT","ts":1786191753396,"type":"delta","data":{"s":"BTCUSDT","b":[],"a":[["64978.2","0.000561"],["64990.8","0"]],"u":184066045,"seq":112464941639},"cts":1786191753394}
{"topic":"orderbook.50.BTCUSDT","ts":1786191753419,"type":"delta","data":{"s":"BTCUSDT","b":[["64978","0.735334"]],"a":[["64978.1","0.886458"]],"u":184066046,"seq":112464941643},"cts":1786191753406}
{"topic":"orderbook.50.BTCUSDT","ts":1786191753436,"type":"delta","data":{"s":"BTCUSDT","b":[],"a":[["64978.1","0.902981"],["64978.4","0.000186"],["64979","0.86085"],["64979.9","0.000093"],["64990.4","0"]],"u":184066047,"seq":112464941649},"cts":1786191753423}
{"topic":"orderbook.50.BTCUSDT","ts":1786191753456,"type":"delta","data":{"s":"BTCUSDT","b":[["64978","0.736411"]],"a":[["64978.1","0.91978"]],"u":184066048,"seq":112464941651},"cts":1786191753450}
{"topic":"orderbook.50.BTCUSDT","ts":1786191753476,"type":"delta","data":{"s":"BTCUSDT","b":[],"a":[["64978.1","0.902981"]],"u":184066049,"seq":112464941654},"cts":1786191753469}
{"topic":"orderbook.50.BTCUSDT","ts":1786191753516,"type":"delta","data":{"s":"BTCUSDT","b":[["64978","0.753581"]],"a":[],"u":184066050,"seq":112464941663},"cts":1786191753511}
{"topic":"orderbook.50.BTCUSDT","ts":1786191753536,"type":"delta","data":{"s":"BTCUSDT","b":[["64978","0.769681"]],"a":[["64978.1","0.886458"]],"u":184066051,"seq":112464941671},"cts":1786191753524}
{"topic":"orderbook.50.BTCUSDT","ts":1786191753596,"type":"delta","data":{"s":"BTCUSDT","b":[["64978","0.746681"]],"a":[],"u":184066052,"seq":112464941682},"cts":1786191753592}
{"topic":"orderbook.50.BTCUSDT","ts":1786191753616,"type":"delta","data":{"s":"BTCUSDT","b":[["64978","0.737481"]],"a":[],"u":184066053,"seq":112464941690},"cts":1786191753609}
{"topic":"orderbook.50.BTCUSDT","ts":1786191753696,"type":"delta","data":{"s":"BTCUSDT","b":[["64978","0.739761"],["64974","0.002868"]],"a":[],"u":184066054,"seq":112464941699},"cts":1786191753678}
{"topic":"orderbook.50.BTCUSDT","ts":1786191753716,"type":"delta","data":{"s":"BTCUSDT","b":[],"a":[["64978.1","0.869741"]],"u":184066055,"seq":112464941701},"cts":1786191753711}
{"topic":"orderbook.50.BTCUSDT","ts":1786191753736,"type":"delta","data":{"s":"BTCUSDT","b":[["64978","0.7581"]],"a":[],"u":184066056,"seq":112464941702},"cts":1786191753720}
{"topic":"orderbook.50.BTCUSDT","ts":1786191753756,"type":"delta","data":{"s":"BTCUSDT","b":[["64978","0.75658"]],"a":[],"u":184066057,"seq":112464941707},"cts":1786191753753}
{"topic":"orderbook.50.BTCUSDT","ts":1786191753776,"type":"delta","data":{"s":"BTCUSDT","b":[["64978","0.76342"]],"a":[],"u":184066058,"seq":112464941719},"cts":1786191753766}
{"topic":"orderbook.50.BTCUSDT","ts":1786191753836,"type":"delta","data":{"s":"BTCUSDT","b":[["64978","0.75734"]],"a":[],"u":184066059,"seq":112464941729},"cts":1786191753832}
{"topic":"orderbook.50.BTCUSDT","ts":1786191753856,"type":"delta","data":{"s":"BTCUSDT","b":[["64978","0.75582"],["64968.4","0.099702"],["64967.8","0"]],"a":[],"u":184066060,"seq":112464941737},"cts":1786191753854}
{"topic":"orderbook.50.BTCUSDT","ts":1786191753916,"type":"delta","data":{"s":"BTCUSDT","b":[["64968.4","0"],["64967.4","0.099703"]],"a":[],"u":184066061,"seq":112464941750},"cts":1786191753914}
{"topic":"orderbook.50.BTCUSDT","ts":1786191753936,"type":"delta","data":{"s":"BTCUSDT","b":[["64978","0.75886"],["64967.8","0.099703"],["64967.4","0"]],"a":[],"u":184066062,"seq":112464941759},"cts":1786191753934}
{"topic":"orderbook.50.BTCUSDT","ts":1786191754016,"type":"delta","data":{"s":"BTCUSDT","b":[["64978","0.76114"]],"a":[],"u":184066063,"seq":112464941778},"cts":1786191754015}
{"topic":"orderbook.50.BTCUSDT","ts":1786191754036,"type":"delta","data":{"s":"BTCUSDT","b":[["64978","0.76342"]],"a":[],"u":184066064,"seq":112464941784},"cts":1786191754033}
{"topic":"orderbook.50.BTCUSDT","ts":1786191754056,"type":"delta","data":{"s":"BTCUSDT","b":[],"a":[["64978.1","0.884961"]],"u":184066065,"seq":112464941785},"cts":1786191754040}
{"topic":"orderbook.50.BTCUSDT","ts":1786191754076,"type":"delta","data":{"s":"BTCUSDT","b":[["64978","0.745081"]],"a":[],"u":184066066,"seq":112464941789},"cts":1786191754070}
{"topic":"orderbook.50.BTCUSDT","ts":1786191754096,"type":"delta","data":{"s":"BTCUSDT","b":[["64978","0.738241"]],"a":[],"u":184066067,"seq":112464941801},"cts":1786191754091}
{"topic":"orderbook.50.BTCUSDT","ts":1786191754116,"type":"delta","data":{"s":"BTCUSDT","b":[["64978","0.737481"]],"a":[],"u":184066068,"seq":112464941802},"cts":1786191754100}
{"topic":"orderbook.50.BTCUSDT","ts":1786191754136,"type":"delta","data":{"s":"BTCUSDT","b":[["64978","0.740521"],["64967.8","0"],["64966.9","0.099704"]],"a":[],"u":184066069,"seq":112464941809},"cts":1786191754122}
{"topic":"orderbook.50.BTCUSDT","ts":1786191754156,"type":"delta","data":{"s":"BTCUSDT","b":[["64978","0.757286"],["64967.8","0.099703"],["64966.9","0"]],"a":[["64978.1","0.869741"]],"u":184066070,"seq":112464941815},"cts":1786191754146}
{"topic":"orderbook.50.BTCUSDT","ts":1786191754176,"type":"delta","data":{"s":"BTCUSDT","b":[["64978","0.761846"]],"a":[],"u":184066071,"seq":112464941828},"cts":1786191754174}
{"topic":"orderbook.50.BTCUSDT","ts":1786191754196,"type":"delta","data":{"s":"BTCUSDT","b":[["64967.8","0"],["64966.9","0.099704"]],"a":[],"u":184066072,"seq":112464941835},"cts":1786191754180}
{"topic":"orderbook.50.BTCUSDT","ts":1786191754219,"type":"delta","data":{"s":"BTCUSDT","b":[["64978","0.758806"],["64967.8","0.099702"],["64966.9","0"]],"a":[],"u":184066073,"seq":112464941841},"cts":1786191754213}
{"topic":"orderbook.50.BTCUSDT","ts":1786191754237,"type":"delta","data":{"s":"BTCUSDT","b":[["64978","0.757286"],["64976.7","0.000093"],["64973.7","0.038673"],["64963.6","0"]],"a":[],"u":184066074,"seq":112464941848},"cts":1786191754230}
{"topic":"orderbook.50.BTCUSDT","ts":1786191754256,"type":"delta","data":{"s":"BTCUSDT","b":[["64978","0.755006"],["64967.9","0.099702"],["64967.8","0"]],"a":[],"u":184066075,"seq":112464941855},"cts":1786191754251}
{"topic":"orderbook.50.BTCUSDT","ts":1786191754276,"type":"delta","data":{"s":"BTCUSDT","b":[["64967.9","0"],["64967.8","0.099702"]],"a":[],"u":184066076,"seq":112464941858},"cts":1786191754273}
{"topic":"orderbook.50.BTCUSDT","ts":1786191754316,"type":"delta","data":{"s":"BTCUSDT","b":[["64978","0.757286"]],"a":[],"u":184066077,"seq":112464941862},"cts":1786191754314}
{"topic":"orderbook.50.BTCUSDT","ts":1786191754336,"type":"delta","data":{"s":"BTCUSDT","b":[["64978","0.756526"],["64967.8","0.099703"]],"a":[],"u":184066078,"seq":112464941868},"cts":1786191754332}
{"topic":"orderbook.50.BTCUSDT","ts":1786191754396,"type":"delta","data":{"s":"BTCUSDT","b":[["64978","0.754246"]],"a":[],"u":184066079,"seq":112464941876},"cts":1786191754394}
{"topic":"orderbook.50.BTCUSDT","ts":1786191754416,"type":"delta","data":{"s":"BTCUSDT","b":[["64978","0.758806"]],"a":[],"u":184066080,"seq":112464941883},"cts":1786191754411}
{"topic":"orderbook.50.BTCUSDT","ts":1786191754436,"type":"delta","data":{"s":"BTCUSDT","b":[["64978","0.761846"]],"a":[],"u":184066081,"seq":112464941890},"cts":1786191754427}
{"topic":"orderbook.50.BTCUSDT","ts":1786191754476,"type":"delta","data":{"s":"BTCUSDT","b":[["64978","0.763366"]],"a":[],"u":184066082,"seq":112464941893},"cts":1786191754471}
{"topic":"orderbook.50.BTCUSDT","ts":1786191754496,"type":"delta","data":{"s":"BTCUSDT","b":[["64978","0.804846"],["64977.8","0"],["64976.7","0"],["64973.7","0.038487"],["64963.6","0.000029"],["64963.5","0.13544"]],"a":[],"u":184066083,"seq":112464941906},"cts":1786191754493}
{"topic":"orderbook.50.BTCUSDT","ts":1786191754515,"type":"delta","data":{"s":"BTCUSDT","b":[["64978","0.802566"]],"a":[],"u":184066084,"seq":112464941909},"cts":1786191754502}
{"topic":"orderbook.50.BTCUSDT","ts":1786191754536,"type":"delta","data":{"s":"BTCUSDT","b":[["64978","0.803326"]],"a":[],"u":184066085,"seq":112464941912},"cts":1786191754523}
{"topic":"orderbook.50.BTCUSDT","ts":1786191754556,"type":"delta","data":{"s":"BTCUSDT","b":[["64978","0.801806"]],"a":[],"u":184066086,"seq":112464941914},"cts":1786191754550}
{"topic":"orderbook.50.BTCUSDT","ts":1786191754576,"type":"delta","data":{"s":"BTCUSDT","b":[["64978","0.806366"]],"a":[],"u":184066087,"seq":112464941921},"cts":1786191754573}
{"topic":"orderbook.50.BTCUSDT","ts":1786191754596,"type":"delta","data":{"s":"BTCUSDT","b":[["64978","0.805606"]],"a":[],"u":184066088,"seq":112464941923},"cts":1786191754590}
{"topic":"orderbook.50.BTCUSDT","ts":1786191754616,"type":"delta","data":{"s":"BTCUSDT","b":[["64978","0.807886"]],"a":[],"u":184066089,"seq":112464941926},"cts":1786191754610}
{"topic":"orderbook.50.BTCUSDT","ts":1786191754636,"type":"delta","data":{"s":"BTCUSDT","b":[["64978","0.806366"]],"a":[],"u":184066090,"seq":112464941929},"cts":1786191754631}
{"topic":"orderbook.50.BTCUSDT","ts":1786191754656,"type":"delta","data":{"s":"BTCUSDT","b":[["64978","0.803326"]],"a":[["64978.8","0.049105"]],"u":184066091,"seq":112464941934},"cts":1786191754651}
{"topic":"orderbook.50.BTCUSDT","ts":1786191754676,"type":"delta","data":{"s":"BTCUSDT","b":[["64978","0.804846"]],"a":[],"u":184066092,"seq":112464941938},"cts":1786191754674}
{"topic":"orderbook.50.BTCUSDT","ts":1786191754696,"type":"delta","data":{"s":"BTCUSDT","b":[["64978","0.633191"],["64973.6","1.369474"]],"a":[],"u":184066093,"seq":112464941949},"cts":1786191754694}
{"topic":"orderbook.50.BTCUSDT","ts":1786191754716,"type":"delta","data":{"s":"BTCUSDT","b":[["64978","0.805763"],["64973.7","0.557664"],["64973.6","0.021436"]],"a":[],"u":184066094,"seq":112464941965},"cts":1786191754714}
{"topic":"orderbook.50.BTCUSDT","ts":1786191754736,"type":"delta","data":{"s":"BTCUSDT","b":[["64978","0.807283"],["64973.7","0.206543"]],"a":[],"u":184066095,"seq":112464941973},"cts":1786191754733}
{"topic":"orderbook.50.BTCUSDT","ts":1786191754756,"type":"delta","data":{"s":"BTCUSDT","b":[["64978","0.805763"]],"a":[],"u":184066096,"seq":112464941975},"cts":1786191754753}
{"topic":"orderbook.50.BTCUSDT","ts":1786191754776,"type":"delta","data":{"s":"BTCUSDT","b":[],"a":[["64978.1","0.868972"]],"u":184066097,"seq":112464941977},"cts":1786191754774}
{"topic":"orderbook.50.BTCUSDT","ts":1786191754796,"type":"delta","data":{"s":"BTCUSDT","b":[["64978","0.884123"]],"a":[],"u":184066098,"seq":112464941991},"cts":1786191754789}
{"topic":"orderbook.50.BTCUSDT","ts":1786191754816,"type":"delta","data":{"s":"BTCUSDT","b":[["64978","0.887163"]],"a":[],"u":184066099,"seq":112464941995},"cts":1786191754810}
{"topic":"orderbook.50.BTCUSDT","ts":1786191754856,"type":"delta","data":{"s":"BTCUSDT","b":[["64978","0.887923"]],"a":[],"u":184066100,"seq":112464941999},"cts":1786191754846}
{"topic":"orderbook.50.BTCUSDT","ts":1786191754876,"type":"delta","data":{"s":"BTCUSDT","b":[],"a":[["64979","0.743369"]],"u":184066101,"seq":112464942003},"cts":1786191754871}
{"topic":"orderbook.50.BTCUSDT","ts":1786191754896,"type":"delta","data":{"s":"BTCUSDT","b":[["64978","0"],["64977.3","0.269755"],["64963.4","0.123013"]],"a":[["64977.4","1.135194"],["64977.9","0.209431"],["64978","0.421034"],["64978.1","0.504364"],["64989.8","0"],["64990","0"],["64990.3","0"]],"u":184066102,"seq":112464942038},"cts":1786191754894}
{"topic":"orderbook.50.BTCUSDT","ts":1786191754916,"type":"delta","data":{"s":"BTCUSDT","b":[["64977.3","0.767445"],["64977","0.000093"],["64975.5","0"],["64974.8","0.000135"],["64974.6","0.000186"],["64971.5","0"],["64970.8","0.01135"],["64966.8","0"],["64965.9","0"],["64963.5","0.07544"]],"a":[["64977.4","1.265225"],["64977.9","0"],["64978","0.370984"],["64978.1","0.13313"],["64978.8","0.002305"],["64983.9","0.043575"],["64984.6","0.0025"],["64989.8","0.0025"]],"u":184066103,"seq":112464942178},"cts":1786191754915}
{"topic":"orderbook.50.BTCUSDT","ts":1786191754936,"type":"delta","data":{"s":"BTCUSDT","b":[["64963.5","0.323291"]],"a":[["64977.4","1.266936"]],"u":184066104,"seq":112464942190},"cts":1786191754930}
{"topic":"orderbook.50.BTCUSDT","ts":1786191754976,"type":"delta","data":{"s":"BTCUSDT","b":[["64963.5","0.07544"]],"a":[],"u":184066105,"seq":112464942210},"cts":1786191754975}
{"topic":"orderbook.50.BTCUSDT","ts":1786191754996,"type":"delta","data":{"s":"BTCUSDT","b":[["64977.3","0.654845"]],"a":[],"u":184066106,"seq":112464942216},"cts":1786191754995}
{"topic":"orderbook.50.BTCUSDT","ts":1786191755019,"type":"delta","data":{"s":"BTCUSDT","b":[["64977.3","0.663242"],["64967.8","0"],["64967.4","0.099704"]],"a":[],"u":184066107,"seq":112464942231},"cts":1786191755015}
{"topic":"orderbook.50.BTCUSDT","ts":1786191755036,"type":"delta","data":{"s":"BTCUSDT","b":[["64977.3","0.664002"]],"a":[["64977.4","1.265225"]],"u":184066108,"seq":112464942240},"cts":1786191755030}
{"topic":"orderbook.50.BTCUSDT","ts":1786191755056,"type":"delta","data":{"s":"BTCUSDT","b":[],"a":[["64978.1","0.00493"]],"u":184066109,"seq":112464942245},"cts":1786191755053}
{"topic":"orderbook.50.BTCUSDT","ts":1786191755076,"type":"delta","data":{"s":"BTCUSDT","b":[["64977.3","0.665522"]],"a":[["64977.4","1.266936"]],"u":184066110,"seq":112464942249},"cts":1786191755075}
{"topic":"orderbook.50.BTCUSDT","ts":1786191755096,"type":"delta","data":{"s":"BTCUSDT","b":[["64977.3","0.661722"]],"a":[],"u":184066111,"seq":112464942262},"cts":1786191755092}
{"topic":"orderbook.50.BTCUSDT","ts":1786191755156,"type":"delta","data":{"s":"BTCUSDT","b":[["64977.3","0.657922"]],"a":[],"u":184066112,"seq":112464942269},"cts":1786191755151}
{"topic":"orderbook.50.BTCUSDT","ts":1786191755176,"type":"delta","data":{"s":"BTCUSDT","b":[["64977.3","0.662482"],["64974.6","0.000093"]],"a":[],"u":184066113,"seq":112464942278},"cts":1786191755172}
{"topic":"orderbook.50.BTCUSDT","ts":1786191755196,"type":"delta","data":{"s":"BTCUSDT","b":[["64967.8","0.099703"],["64967.4","0"]],"a":[],"u":184066114,"seq":112464942280},"cts":1786191755187}
{"topic":"orderbook.50.BTCUSDT","ts":1786191755236,"type":"delta","data":{"s":"BTCUSDT","b":[["64977.3","0.659442"],["64975.2","0.142233"],["64975.1","0"],["64967.8","0"],["64966.4","0.099705"],["64963.3","0.037082"]],"a":[["64978.9","0.000093"]],"u":184066115,"seq":112464942298},"cts":1786191755234}
{"topic":"orderbook.50.BTCUSDT","ts":1786191755256,"type":"delta","data":{"s":"BTCUSDT","b":[["64977.3","0.655605"],["64976.9","0.160899"],["64975.9","0"],["64975.5","0.003078"],["64975.2","0.01922"],["64974.5","0.123013"],["64971.3","0.123013"],["64971.2","0"],["64970.9","0"],["64967.7","0"],["64966.5","0.507459"],["64966.4","0"],["64966.2","0"],["64965.3","0.099705"],["64965.1","0"],["64962.3","0.015713"],["64962","0.000116"]],"a":[["64977.8","0.022892"],["64989.8","0"]],"u":184066116,"seq":112464942334},"cts":1786191755253}
{"topic":"orderbook.50.BTCUSDT","ts":1786191755276,"type":"delta","data":{"s":"BTCUSDT","b":[["64977.3","0.644308"],["64973.7","0.098184"],["64970.4","0.384446"],["64966.4","0.099704"],["64966.3","0"],["64965.3","0"]],"a":[["64980.9","0.743652"]],"u":184066117,"seq":112464942355},"cts":1786191755273}
{"topic":"orderbook.50.BTCUSDT","ts":1786191755295,"type":"delta","data":{"s":"BTCUSDT","b":[["64976.9","0.116057"],["64966.4","0"],["64966.3","0.099705"]],"a":[],"u":184066118,"seq":112464942371},"cts":1786191755294}
{"topic":"orderbook.50.BTCUSDT","ts":1786191755316,"type":"delta","data":{"s":"BTCUSDT","b":[["64977.3","0.642808"],["64974.5","0.507459"],["64973.7","0.205309"],["64971.7","0.0015"],["64966.5","0.607163"],["64966.3","0"]],"a":[["64980.9","0.008298"]],"u":184066119,"seq":112464942398},"cts":1786191755313}
{"topic":"orderbook.50.BTCUSDT","ts":1786191755335,"type":"delta","data":{"s":"BTCUSDT","b":[["64977.3","0.646608"],["64976.9","0.215977"],["64966.6","0.312592"],["64966.5","0.507459"]],"a":[],"u":184066120,"seq":112464942420},"cts":1786191755334}
{"topic":"orderbook.50.BTCUSDT","ts":1786191755355,"type":"delta","data":{"s":"BTCUSDT","b":[["64977.3","0.647368"],["64975.1","0.000077"],["64962","0"]],"a":[],"u":184066121,"seq":112464942429},"cts":1786191755354}
{"topic":"orderbook.50.BTCUSDT","ts":1786191755376,"type":"delta","data":{"s":"BTCUSDT","b":[["64977.3","0.648888"]],"a":[],"u":184066122,"seq":112464942437},"cts":1786191755373}
{"topic":"orderbook.50.BTCUSDT","ts":1786191755395,"type":"delta","data":{"s":"BTCUSDT","b":[["64975.5","0"],["64974","0.005946"],["64962","0.000116"]],"a":[],"u":184066123,"seq":112464942441},"cts":1786191755394}
{"topic":"orderbook.50.BTCUSDT","ts":1786191755416,"type":"delta","data":{"s":"BTCUSDT","b":[["64977.3","0.647368"],["64976.4","0.014791"],["64965.6","0.199124"],["64962","0"]],"a":[["64977.4","1.283933"]],"u":184066124,"seq":112464942449},"cts":1786191755408}
{"topic":"orderbook.50.BTCUSDT","ts":1786191755436,"type":"delta","data":{"s":"BTCUSDT","b":[["64977.3","0.643568"],["64966.7","0.099704"],["64966.6","0.212888"],["64962.3","0"]],"a":[["64977.4","1.299565"],["64988.7","0.005603"],["64989.7","0"]],"u":184066125,"seq":112464942460},"cts":1786191755431}
{"topic":"orderbook.50.BTCUSDT","ts":1786191755456,"type":"delta","data":{"s":"BTCUSDT","b":[],"a":[["64977.4","1.31701"]],"u":184066126,"seq":112464942468},"cts":1786191755447}
{"topic":"orderbook.50.BTCUSDT","ts":1786191755476,"type":"delta","data":{"s":"BTCUSDT","b":[["64974.2","0.128045"],["64967.4","0.099704"],["64966.7","0"],["64963.3","0"]],"a":[["64977.4","1.33355"]],"u":184066127,"seq":112464942473},"cts":1786191755473}
{"topic":"orderbook.50.BTCUSDT","ts":1786191755496,"type":"delta","data":{"s":"BTCUSDT","b":[["64977.3","0.642808"]],"a":[["64977.4","1.396197"]],"u":184066128,"seq":112464942477},"cts":1786191755492}
{"topic":"orderbook.50.BTCUSDT","ts":1786191755516,"type":"delta","data":{"s":"BTCUSDT","b":[["64977.3","0.648128"]],"a":[],"u":184066129,"seq":112464942486},"cts":1786191755514}
{"topic":"orderbook.50.BTCUSDT","ts":1786191755536,"type":"delta","data":{"s":"BTCUSDT","b":[["64977.3","0.651168"]],"a":[],"u":184066130,"seq":112464942492},"cts":1786191755526}
{"topic":"orderbook.50.BTCUSDT","ts":1786191755576,"type":"delta","data":{"s":"BTCUSDT","b":[["64977.3","0.650408"]],"a":[["64977.4","1.396658"],["64983","0.068385"]],"u":184066131,"seq":112464942495},"cts":1786191755571}
{"topic":"orderbook.50.BTCUSDT","ts":1786191755596,"type":"delta","data":{"s":"BTCUSDT","b":[["64977.3","0.645088"]],"a":[],"u":184066132,"seq":112464942507},"cts":1786191755594}
{"topic":"orderbook.50.BTCUSDT","ts":1786191755617,"type":"delta","data":{"s":"BTCUSDT","b":[["64977.3","0.643568"]],"a":[],"u":184066133,"seq":112464942512},"cts":1786191755605}
{"topic":"orderbook.50.BTCUSDT","ts":1786191755636,"type":"delta","data":{"s":"BTCUSDT","b":[["64976.4","0.0025"],["64963.5","0.307785"]],"a":[],"u":184066134,"seq":112464942516},"cts":1786191755627}
{"topic":"orderbook.50.BTCUSDT","ts":1786191755656,"type":"delta","data":{"s":"BTCUSDT","b":[["64977.3","0.644328"]],"a":[],"u":184066135,"seq":112464942520},"cts":1786191755654}
{"topic":"orderbook.50.BTCUSDT","ts":1786191755676,"type":"delta","data":{"s":"BTCUSDT","b":[["64977.3","0.648888"]],"a":[],"u":184066136,"seq":112464942528},"cts":1786191755673}
{"topic":"orderbook.50.BTCUSDT","ts":1786191755736,"type":"delta","data":{"s":"BTCUSDT","b":[["64977.3","0.651208"],["64968.4","0.099702"],["64967.4","0"],["64963.5","0.07544"]],"a":[],"u":184066137,"seq":112464942540},"cts":1786191755731}
{"topic":"orderbook.50.BTCUSDT","ts":1786191755756,"type":"delta","data":{"s":"BTCUSDT","b":[["64977.3","0.648168"],["64968.4","0"],["64967.4","0.099703"]],"a":[],"u":184066138,"seq":112464942546},"cts":1786191755750}
{"topic":"orderbook.50.BTCUSDT","ts":1786191755776,"type":"delta","data":{"s":"BTCUSDT","b":[["64977.3","0.655068"]],"a":[],"u":184066139,"seq":112464942550},"cts":1786191755763}
{"topic":"orderbook.50.BTCUSDT","ts":1786191755796,"type":"delta","data":{"s":"BTCUSDT","b":[["64967.5","0.099703"],["64967.4","0"]],"a":[],"u":184066140,"seq":112464942551},"cts":1786191755793}
{"topic":"orderbook.50.BTCUSDT","ts":1786191755818,"type":"delta","data":{"s":"BTCUSDT","b":[["64977.3","0.659668"],["64967.5","0"],["64967.4","0.099703"]],"a":[],"u":184066141,"seq":112464942557},"cts":1786191755816}
{"topic":"orderbook.50.BTCUSDT","ts":1786191755836,"type":"delta","data":{"s":"BTCUSDT","b":[["64963.5","0.307785"]],"a":[],"u":184066142,"seq":112464942560},"cts":1786191755827}
{"topic":"orderbook.50.BTCUSDT","ts":1786191755856,"type":"delta","data":{"s":"BTCUSDT","b":[["64977.3","0.662728"]],"a":[],"u":184066143,"seq":112464942565},"cts":1786191755855}
{"topic":"orderbook.50.BTCUSDT","ts":1786191755876,"type":"delta","data":{"s":"BTCUSDT","b":[["64977.3","0.655828"]],"a":[["64977.4","1.349858"]],"u":184066144,"seq":112464942575},"cts":1786191755875}
{"topic":"orderbook.50.BTCUSDT","ts":1786191755896,"type":"delta","data":{"s":"BTCUSDT","b":[["64977.3","0.646628"]],"a":[],"u":184066145,"seq":112464942581},"cts":1786191755892}
{"topic":"orderbook.50.BTCUSDT","ts":1786191755916,"type":"delta","data":{"s":"BTCUSDT","b":[["64977.3","0.647388"]],"a":[],"u":184066146,"seq":112464942583},"cts":1786191755911}
{"topic":"orderbook.50.BTCUSDT","ts":1786191755936,"type":"delta","data":{"s":"BTCUSDT","b":[["64977.3","0.643568"],["64963.5","0.07544"]],"a":[],"u":184066147,"seq":112464942593},"cts":1786191755931}
{"topic":"orderbook.50.BTCUSDT","ts":1786191755956,"type":"delta","data":{"s":"BTCUSDT","b":[["64977.3","0.642808"],["64967.5","0.099703"],["64967.4","0"]],"a":[["64988.7","0"],["64989.7","0.03"]],"u":184066148,"seq":112464942599},"cts":1786191755954}
{"topic":"orderbook.50.BTCUSDT","ts":1786191755976,"type":"delta","data":{"s":"BTCUSDT","b":[["64977.3","0.648888"],["64967.5","0"],["64967.4","0.099703"]],"a":[],"u":184066149,"seq":112464942613},"cts":1786191755974}
{"topic":"orderbook.50.BTCUSDT","ts":1786191756016,"type":"delta","data":{"s":"BTCUSDT","b":[["64977.3","0.649648"]],"a":[],"u":184066150,"seq":112464942619},"cts":1786191756007}
{"topic":"orderbook.50.BTCUSDT","ts":1786191756036,"type":"delta","data":{"s":"BTCUSDT","b":[["64977.3","0.648888"],["64967.6","0.099703"],["64967.4","0"]],"a":[],"u":184066151,"seq":112464942621},"cts":1786191756033}
{"topic":"orderbook.50.BTCUSDT","ts":1786191756056,"type":"delta","data":{"s":"BTCUSDT","b":[["64977.3","0.643568"],["64967.6","0"],["64967.4","0.099703"]],"a":[],"u":184066152,"seq":112464942633},"cts":1786191756051}
{"topic":"orderbook.50.BTCUSDT","ts":1786191756076,"type":"delta","data":{"s":"BTCUSDT","b":[["64977.3","0.645088"]],"a":[],"u":184066153,"seq":112464942638},"cts":1786191756074}
{"topic":"orderbook.50.BTCUSDT","ts":1786191756096,"type":"delta","data":{"s":"BTCUSDT","b":[["64977.3","0.644328"]],"a":[],"u":184066154,"seq":112464942639},"cts":1786191756082}
{"topic":"orderbook.50.BTCUSDT","ts":1786191756136,"type":"delta","data":{"s":"BTCUSDT","b":[["64977.3","0.647368"],["64963.5","0.307785"]],"a":[],"u":184066155,"seq":112464942653},"cts":1786191756130}
{"topic":"orderbook.50.BTCUSDT","ts":1786191756156,"type":"delta","data":{"s":"BTCUSDT","b":[["64977.3","0.646608"],["64963.5","0.07544"]],"a":[],"u":184066156,"seq":112464942657},"cts":1786191756154}
{"topic":"orderbook.50.BTCUSDT","ts":1786191756176,"type":"delta","data":{"s":"BTCUSDT","b":[["64977.3","0.649648"]],"a":[],"u":184066157,"seq":112464942663},"cts":1786191756174}
{"topic":"orderbook.50.BTCUSDT","ts":1786191756196,"type":"delta","data":{"s":"BTCUSDT","b":[["64977.3","0.647368"]],"a":[],"u":184066158,"seq":112464942666},"cts":1786191756191}
{"topic":"orderbook.50.BTCUSDT","ts":1786191756216,"type":"delta","data":{"s":"BTCUSDT","b":[["64977.3","0.645088"]],"a":[],"u":184066159,"seq":112464942671},"cts":1786191756203}
{"topic":"orderbook.50.BTCUSDT","ts":1786191756236,"type":"delta","data":{"s":"BTCUSDT","b":[["64977.3","0.642808"]],"a":[],"u":184066160,"seq":112464942674},"cts":1786191756231}
{"topic":"orderbook.50.BTCUSDT","ts":1786191756256,"type":"delta","data":{"s":"BTCUSDT","b":[["64976.1","0.012137"],["64963.4","0"]],"a":[],"u":184066161,"seq":112464942678},"cts":1786191756254}
{"topic":"orderbook.50.BTCUSDT","ts":1786191756276,"type":"delta","data":{"s":"BTCUSDT","b":[["64977.3","0.647368"]],"a":[],"u":184066162,"seq":112464942688},"cts":1786191756274}
{"topic":"orderbook.50.BTCUSDT","ts":1786191756296,"type":"delta","data":{"s":"BTCUSDT","b":[["64977.3","0.648888"],["64975","0.00331"],["64974","0.002868"],["64968.7","0.099701"],["64967.4","0"]],"a":[],"u":184066163,"seq":112464942693},"cts":1786191756294}
{"topic":"orderbook.50.BTCUSDT","ts":1786191756316,"type":"delta","data":{"s":"BTCUSDT","b":[["64977.3","0.649648"],["64968.7","0"],["64967.4","0.099703"]],"a":[],"u":184066164,"seq":112464942698},"cts":1786191756311}
{"topic":"orderbook.50.BTCUSDT","ts":1786191756336,"type":"delta","data":{"s":"BTCUSDT","b":[["64977.3","0.647368"],["64963.5","0.307785"]],"a":[],"u":184066165,"seq":112464942706},"cts":1786191756332}
{"topic":"orderbook.50.BTCUSDT","ts":1786191756356,"type":"delta","data":{"s":"BTCUSDT","b":[["64977.3","0.644328"],["64963.5","0.07544"]],"a":[],"u":184066166,"seq":112464942715},"cts":1786191756354}
{"topic":"orderbook.50.BTCUSDT","ts":1786191756376,"type":"delta","data":{"s":"BTCUSDT","b":[["64977.3","0.645088"]],"a":[],"u":184066167,"seq":112464942718},"cts":1786191756370}
{"topic":"orderbook.50.BTCUSDT","ts":1786191756416,"type":"delta","data":{"s":"BTCUSDT","b":[["64977.3","0.646608"],["64968.4","0.099702"],["64967.4","0"]],"a":[],"u":184066168,"seq":112464942727},"cts":1786191756414}
{"topic":"orderbook.50.BTCUSDT","ts":1786191756456,"type":"delta","data":{"s":"BTCUSDT","b":[["64977.3","0.645088"],["64968.4","0"],["64967.4","0.099703"]],"a":[],"u":184066169,"seq":112464942736},"cts":1786191756453}
{"topic":"orderbook.50.BTCUSDT","ts":1786191756476,"type":"delta","data":{"s":"BTCUSDT","b":[["64977.3","0.647368"]],"a":[],"u":184066170,"seq":112464942743},"cts":1786191756474}
{"topic":"orderbook.50.BTCUSDT","ts":1786191756496,"type":"delta","data":{"s":"BTCUSDT","b":[["64977.3","0.646608"]],"a":[],"u":184066171,"seq":112464942750},"cts":1786191756491}
{"topic":"orderbook.50.BTCUSDT","ts":1786191756516,"type":"delta","data":{"s":"BTCUSDT","b":[["64977.3","0.647368"]],"a":[],"u":184066172,"seq":112464942752},"cts":1786191756508}
{"topic":"orderbook.50.BTCUSDT","ts":1786191756536,"type":"delta","data":{"s":"BTCUSDT","b":[["64977.3","0.645848"],["64963.5","0.307785"]],"a":[],"u":184066173,"seq":112464942756},"cts":1786191756532}
{"topic":"orderbook.50.BTCUSDT","ts":1786191756556,"type":"delta","data":{"s":"BTCUSDT","b":[["64977.3","0.643568"]],"a":[],"u":184066174,"seq":112464942765},"cts":1786191756554}
{"topic":"orderbook.50.BTCUSDT","ts":1786191756576,"type":"delta","data":{"s":"BTCUSDT","b":[["64977.3","0.645848"]],"a":[],"u":184066175,"seq":112464942769},"cts":1786191756568}
{"topic":"orderbook.50.BTCUSDT","ts":1786191756596,"type":"delta","data":{"s":"BTCUSDT","b":[["64977.3","0.668848"]],"a":[],"u":184066176,"seq":112464942774},"cts":1786191756586}
{"topic":"orderbook.50.BTCUSDT","ts":1786191756636,"type":"delta","data":{"s":"BTCUSDT","b":[["64977.3","0.670368"],["64963.5","0.07544"]],"a":[],"u":184066177,"seq":112464942778},"cts":1786191756629}
{"topic":"orderbook.50.BTCUSDT","ts":1786191756656,"type":"delta","data":{"s":"BTCUSDT","b":[["64977.3","0.667328"]],"a":[["64977.4","1.334011"]],"u":184066178,"seq":112464942786},"cts":1786191756651}
{"topic":"orderbook.50.BTCUSDT","ts":1786191756676,"type":"delta","data":{"s":"BTCUSDT","b":[["64977.3","0.671888"]],"a":[["64977.4","1.317471"]],"u":184066179,"seq":112464942795},"cts":1786191756675}
{"topic":"orderbook.50.BTCUSDT","ts":1786191756716,"type":"delta","data":{"s":"BTCUSDT","b":[["64977.3","0.671128"]],"a":[],"u":184066180,"seq":112464942799},"cts":1786191756713}
{"topic":"orderbook.50.BTCUSDT","ts":1786191756736,"type":"delta","data":{"s":"BTCUSDT","b":[["64977.3","0.669608"]],"a":[],"u":184066181,"seq":112464942808},"cts":1786191756731}
{"topic":"orderbook.50.BTCUSDT","ts":1786191756756,"type":"delta","data":{"s":"BTCUSDT","b":[["64977.3","0.668088"]],"a":[],"u":184066182,"seq":112464942811},"cts":1786191756742}
{"topic":"orderbook.50.BTCUSDT","ts":1786191756776,"type":"delta","data":{"s":"BTCUSDT","b":[["64977.3","0.668848"]],"a":[],"u":184066183,"seq":112464942814},"cts":1786191756758}
{"topic":"orderbook.50.BTCUSDT","ts":1786191756796,"type":"delta","data":{"s":"BTCUSDT","b":[["64977.3","0.667328"]],"a":[],"u":184066184,"seq":112464942816},"cts":1786191756790}
{"topic":"orderbook.50.BTCUSDT","ts":1786191756816,"type":"delta","data":{"s":"BTCUSDT","b":[["64977.3","0.669608"]],"a":[],"u":184066185,"seq":112464942828},"cts":1786191756812}
{"topic":"orderbook.50.BTCUSDT","ts":1786191756836,"type":"delta","data":{"s":"BTCUSDT","b":[["64977.3","0.671888"],["64963.5","0.307785"]],"a":[],"u":184066186,"seq":112464942833},"cts":1786191756830}
{"topic":"orderbook.50.BTCUSDT","ts":1786191756856,"type":"delta","data":{"s":"BTCUSDT","b":[["64977.3","0.671128"]],"a":[],"u":184066187,"seq":112464942835},"cts":1786191756841}
{"topic":"orderbook.50.BTCUSDT","ts":1786191756916,"type":"delta","data":{"s":"BTCUSDT","b":[["64977.3","0.678028"]],"a":[],"u":184066188,"seq":112464942841},"cts":1786191756914}
{"topic":"orderbook.50.BTCUSDT","ts":1786191756936,"type":"delta","data":{"s":"BTCUSDT","b":[["64977.3","0.680328"],["64963.5","0.07544"]],"a":[["64977.4","1.300026"]],"u":184066189,"seq":112464942848},"cts":1786191756927}
{"topic":"orderbook.50.BTCUSDT","ts":1786191757016,"type":"delta","data":{"s":"BTCUSDT","b":[["64977.3","0.682628"]],"a":[],"u":184066190,"seq":112464942857},"cts":1786191757015}
{"topic":"orderbook.50.BTCUSDT","ts":1786191757056,"type":"delta","data":{"s":"BTCUSDT","b":[["64964.1","0.000861"],["64963.5","0"]],"a":[],"u":184066191,"seq":112464942859},"cts":1786191757034}
{"topic":"orderbook.50.BTCUSDT","ts":1786191757116,"type":"delta","data":{"s":"BTCUSDT","b":[["64976","0.026852"],["64975","0.000232"]],"a":[],"u":184066192,"seq":112464942865},"cts":1786191757106}
{"topic":"orderbook.50.BTCUSDT","ts":1786191757255,"type":"delta","data":{"s":"BTCUSDT","b":[["64977.3","0.678808"]],"a":[],"u":184066193,"seq":112464942879},"cts":1786191757254}
{"topic":"orderbook.50.BTCUSDT","ts":1786191757276,"type":"delta","data":{"s":"BTCUSDT","b":[["64977.3","0.668868"]],"a":[],"u":184066194,"seq":112464942887},"cts":1786191757269}
{"topic":"orderbook.50.BTCUSDT","ts":1786191757296,"type":"delta","data":{"s":"BTCUSDT","b":[["64977.3","0.665048"]],"a":[],"u":184066195,"seq":112464942891},"cts":1786191757278}
{"topic":"orderbook.50.BTCUSDT","ts":1786191757356,"type":"delta","data":{"s":"BTCUSDT","b":[["64977.3","0.669648"]],"a":[],"u":184066196,"seq":112464942895},"cts":1786191757354}
{"topic":"orderbook.50.BTCUSDT","ts":1786191757376,"type":"delta","data":{"s":"BTCUSDT","b":[["64977.3","0.681148"]],"a":[],"u":184066197,"seq":112464942904},"cts":1786191757366}
{"topic":"orderbook.50.BTCUSDT","ts":1786191757456,"type":"delta","data":{"s":"BTCUSDT","b":[["64968.7","0.099701"],["64967.4","0"]],"a":[],"u":184066198,"seq":112464942906},"cts":1786191757442}
{"topic":"orderbook.50.BTCUSDT","ts":1786191757476,"type":"delta","data":{"s":"BTCUSDT","b":[["64977","0"],["64974.6","0"],["64968.7","0"],["64967.4","0.099703"],["64963.5","0.307785"],["64963.4","0.123013"]],"a":[["64983","0.068292"]],"u":184066199,"seq":112464942914},"cts":1786191757471}
{"topic":"orderbook.50.BTCUSDT","ts":1786191757496,"type":"delta","data":{"s":"BTCUSDT","b":[],"a":[["64977.4","1.284394"]],"u":184066200,"seq":112464942918},"cts":1786191757488}
{"topic":"orderbook.50.BTCUSDT","ts":1786191757536,"type":"delta","data":{"s":"BTCUSDT","b":[["64963.5","0.07544"]],"a":[],"u":184066201,"seq":112464942926},"cts":1786191757529}
{"topic":"orderbook.50.BTCUSDT","ts":1786191757556,"type":"delta","data":{"s":"BTCUSDT","b":[],"a":[["64977.4","1.284487"]],"u":184066202,"seq":112464942927},"cts":1786191757549}
{"topic":"orderbook.50.BTCUSDT","ts":1786191757576,"type":"delta","data":{"s":"BTCUSDT","b":[["64977.3","0.690348"]],"a":[["64977.4","1.300212"]],"u":184066203,"seq":112464942934},"cts":1786191757570}
{"topic":"orderbook.50.BTCUSDT","ts":1786191757596,"type":"delta","data":{"s":"BTCUSDT","b":[["64977.3","0.697248"]],"a":[["64977.4","1.318086"]],"u":184066204,"seq":112464942938},"cts":1786191757580}
{"topic":"orderbook.50.BTCUSDT","ts":1786191757616,"type":"delta","data":{"s":"BTCUSDT","b":[],"a":[["64977.4","1.334289"],["64978.8","0.000768"]],"u":184066205,"seq":112464942940},"cts":1786191757601}
{"topic":"orderbook.50.BTCUSDT","ts":1786191757636,"type":"delta","data":{"s":"BTCUSDT","b":[["64963.5","0.307785"]],"a":[["64977.4","1.351738"]],"u":184066206,"seq":112464942943},"cts":1786191757625}
{"topic":"orderbook.50.BTCUSDT","ts":1786191757735,"type":"delta","data":{"s":"BTCUSDT","b":[["64963.5","0.07544"]],"a":[],"u":184066207,"seq":112464942951},"cts":1786191757726}
{"topic":"orderbook.50.BTCUSDT","ts":1786191757836,"type":"delta","data":{"s":"BTCUSDT","b":[["64977.3","0.698109"],["64968.7","0.099701"],["64967.4","0"],["64964.1","0"],["64963.3","0.037082"]],"a":[],"u":184066208,"seq":112464942962},"cts":1786191757832}
{"topic":"orderbook.50.BTCUSDT","ts":1786191757856,"type":"delta","data":{"s":"BTCUSDT","b":[["64968.7","0"],["64968.4","0.099702"]],"a":[["64977.4","1.334289"]],"u":184066209,"seq":112464942966},"cts":1786191757845}
{"topic":"orderbook.50.BTCUSDT","ts":1786191757876,"type":"delta","data":{"s":"BTCUSDT","b":[["64968.4","0"],["64967.4","0.099703"]],"a":[["64977.4","1.318086"]],"u":184066210,"seq":112464942972},"cts":1786191757874}
{"topic":"orderbook.50.BTCUSDT","ts":1786191757896,"type":"delta","data":{"s":"BTCUSDT","b":[],"a":[["64977.4","1.300212"]],"u":184066211,"seq":112464942974},"cts":1786191757880}
{"topic":"orderbook.50.BTCUSDT","ts":1786191757936,"type":"delta","data":{"s":"BTCUSDT","b":[["64963.5","0.307785"]],"a":[],"u":184066212,"seq":112464942982},"cts":1786191757931}
{"topic":"orderbook.50.BTCUSDT","ts":1786191758136,"type":"delta","data":{"s":"BTCUSDT","b":[["64963.5","0.07544"]],"a":[],"u":184066213,"seq":112464943000},"cts":1786191758133}
{"topic":"orderbook.50.BTCUSDT","ts":1786191758196,"type":"delta","data":{"s":"BTCUSDT","b":[["64977.3","0.694459"]],"a":[["64977.4","1.31534"]],"u":184066214,"seq":112464943021},"cts":1786191758187}
{"topic":"orderbook.50.BTCUSDT","ts":1786191758218,"type":"delta","data":{"s":"BTCUSDT","b":[],"a":[["64977.4","1.331875"]],"u":184066215,"seq":112464943025},"cts":1786191758200}
{"topic":"orderbook.50.BTCUSDT","ts":1786191758236,"type":"delta","data":{"s":"BTCUSDT","b":[["64968.4","0.099702"],["64967.4","0"],["64963.5","0.307785"]],"a":[["64977.4","1.348534"]],"u":184066216,"seq":112464943030},"cts":1786191758234}
{"topic":"orderbook.50.BTCUSDT","ts":1786191758256,"type":"delta","data":{"s":"BTCUSDT","b":[["64968.4","0"],["64967.4","0.099703"],["64965.2","0"],["64962.3","0.000324"]],"a":[],"u":184066217,"seq":112464943041},"cts":1786191758253}
{"topic":"orderbook.50.BTCUSDT","ts":1786191758296,"type":"delta","data":{"s":"BTCUSDT","b":[["64967.5","0.099703"],["64967.4","0"]],"a":[],"u":184066218,"seq":112464943046},"cts":1786191758292}
{"topic":"orderbook.50.BTCUSDT","ts":1786191758316,"type":"delta","data":{"s":"BTCUSDT","b":[["64967.5","0"],["64967.4","0.099703"]],"a":[],"u":184066219,"seq":112464943048},"cts":1786191758306}
{"topic":"orderbook.50.BTCUSDT","ts":1786191758336,"type":"delta","data":{"s":"BTCUSDT","b":[["64963.5","0.07544"]],"a":[],"u":184066220,"seq":112464943050},"cts":1786191758321}
{"topic":"orderbook.50.BTCUSDT","ts":1786191758536,"type":"delta","data":{"s":"BTCUSDT","b":[["64976","0.027038"],["64973","0.000186"],["64963.5","0.307785"],["64962.3","0"]],"a":[],"u":184066221,"seq":112464943072},"cts":1786191758525}
{"topic":"orderbook.50.BTCUSDT","ts":1786191758656,"type":"delta","data":{"s":"BTCUSDT","b":[["64968.4","0.099702"],["64967.4","0"]],"a":[["64977.4","1.415199"]],"u":184066222,"seq":112464943083},"cts":1786191758652}
{"topic":"orderbook.50.BTCUSDT","ts":1786191758696,"type":"delta","data":{"s":"BTCUSDT","b":[["64968.4","0"],["64967.4","0.099703"]],"a":[],"u":184066223,"seq":112464943088},"cts":1786191758687}
{"topic":"orderbook.50.BTCUSDT","ts":1786191758716,"type":"delta","data":{"s":"BTCUSDT","b":[],"a":[["64977.4","1.348534"]],"u":184066224,"seq":112464943089},"cts":1786191758698}
{"topic":"orderbook.50.BTCUSDT","ts":1786191758736,"type":"delta","data":{"s":"BTCUSDT","b":[["64963.5","0.07544"]],"a":[],"u":184066225,"seq":112464943093},"cts":1786191758733}
{"topic":"orderbook.50.BTCUSDT","ts":1786191758776,"type":"delta","data":{"s":"BTCUSDT","b":[["64976","0.026852"],["64973","0"],["64962.3","0.000324"]],"a":[],"u":184066226,"seq":112464943100},"cts":1786191758755}
{"topic":"orderbook.50.BTCUSDT","ts":1786191758816,"type":"delta","data":{"s":"BTCUSDT","b":[],"a":[["64980.9","0.002686"],["64981.7","0.000029"]],"u":184066227,"seq":112464943103},"cts":1786191758815}
{"topic":"orderbook.50.BTCUSDT","ts":1786191758896,"type":"delta","data":{"s":"BTCUSDT","b":[["64968.4","0.099702"],["64967.4","0"]],"a":[],"u":184066228,"seq":112464943112},"cts":1786191758894}
{"topic":"orderbook.50.BTCUSDT","ts":1786191758917,"type":"delta","data":{"s":"BTCUSDT","b":[["64970.4","0.484145"],["64968.4","0"],["64962","0.000116"]],"a":[],"u":184066229,"seq":112464943126},"cts":1786191758911}
{"topic":"orderbook.50.BTCUSDT","ts":1786191758935,"type":"delta","data":{"s":"BTCUSDT","b":[["64970.4","0.384446"],["64969","0.0997"],["64963.5","0.307785"],["64962","0"]],"a":[["64977.4","1.331875"]],"u":184066230,"seq":112464943136},"cts":1786191758933}
{"topic":"orderbook.50.BTCUSDT","ts":1786191758956,"type":"delta","data":{"s":"BTCUSDT","b":[],"a":[["64977.4","1.313629"]],"u":184066231,"seq":112464943141},"cts":1786191758945}
{"topic":"orderbook.50.BTCUSDT","ts":1786191758976,"type":"delta","data":{"s":"BTCUSDT","b":[],"a":[["64977.4","1.298501"]],"u":184066232,"seq":112464943142},"cts":1786191758960}
{"topic":"orderbook.50.BTCUSDT","ts":1786191758996,"type":"delta","data":{"s":"BTCUSDT","b":[["64969","0"],["64968.7","0.099701"]],"a":[["64989","1.143755"]],"u":184066233,"seq":112464943151},"cts":1786191758991}
{"topic":"orderbook.50.BTCUSDT","ts":1786191759036,"type":"delta","data":{"s":"BTCUSDT","b":[["64963.5","0.07544"]],"a":[],"u":184066234,"seq":112464943157},"cts":1786191759028}
{"topic":"orderbook.50.BTCUSDT","ts":1786191759056,"type":"delta","data":{"s":"BTCUSDT","b":[["64969","0.0997"],["64968.7","0"]],"a":[],"u":184066235,"seq":112464943162},"cts":1786191759054}
{"topic":"orderbook.50.BTCUSDT","ts":1786191759076,"type":"delta","data":{"s":"BTCUSDT","b":[["64969","0"],["64968.4","0.099702"]],"a":[],"u":184066236,"seq":112464943164},"cts":1786191759062}
{"topic":"orderbook.50.BTCUSDT","ts":1786191759096,"type":"delta","data":{"s":"BTCUSDT","b":[["64969","0.099701"],["64968.4","0"]],"a":[],"u":184066237,"seq":112464943169},"cts":1786191759093}
{"topic":"orderbook.50.BTCUSDT","ts":1786191759116,"type":"delta","data":{"s":"BTCUSDT","b":[["64969","0"],["64967.4","0.099702"]],"a":[],"u":184066238,"seq":112464943171},"cts":1786191759114}
{"topic":"orderbook.50.BTCUSDT","ts":1786191759156,"type":"delta","data":{"s":"BTCUSDT","b":[["64967.4","0.099703"],["64963.5","0.307784"]],"a":[["64977.4","1.298594"]],"u":184066239,"seq":112464943181},"cts":1786191759154}
{"topic":"orderbook.50.BTCUSDT","ts":1786191759176,"type":"delta","data":{"s":"BTCUSDT","b":[["64968.4","0.099702"],["64967.4","0"]],"a":[],"u":184066240,"seq":112464943185},"cts":1786191759174}
{"topic":"orderbook.50.BTCUSDT","ts":1786191759216,"type":"delta","data":{"s":"BTCUSDT","b":[["64968.4","0"],["64967.4","0.099702"]],"a":[],"u":184066241,"seq":112464943190},"cts":1786191759212}
{"topic":"orderbook.50.BTCUSDT","ts":1786191759356,"type":"delta","data":{"s":"BTCUSDT","b":[["64963.5","0.07544"]],"a":[],"u":184066242,"seq":112464943199},"cts":1786191759354}
{"topic":"orderbook.50.BTCUSDT","ts":1786191759416,"type":"delta","data":{"s":"BTCUSDT","b":[["64968.7","0.099701"],["64967.4","0"]],"a":[],"u":184066243,"seq":112464943205},"cts":1786191759407}
{"topic":"orderbook.50.BTCUSDT","ts":1786191759436,"type":"delta","data":{"s":"BTCUSDT","b":[["64968.7","0"],["64967.4","0.099703"]],"a":[],"u":184066244,"seq":112464943208},"cts":1786191759429}
{"topic":"orderbook.50.BTCUSDT","ts":1786191759516,"type":"delta","data":{"s":"BTCUSDT","b":[["64968.7","0.099701"],["64967.4","0"]],"a":[],"u":184066245,"seq":112464943216},"cts":1786191759509}
{"topic":"orderbook.50.BTCUSDT","ts":1786191759536,"type":"delta","data":{"s":"BTCUSDT","b":[["64963.5","0.307784"]],"a":[["64977.4","1.282869"]],"u":184066246,"seq":112464943220},"cts":1786191759524}
{"topic":"orderbook.50.BTCUSDT","ts":1786191759556,"type":"delta","data":{"s":"BTCUSDT","b":[["64976.9","0.21607"],["64974.5","0.507552"],["64972.7","0.002244"],["64968.7","0"],["64967.5","0.099703"]],"a":[],"u":184066247,"seq":112464943231},"cts":1786191759554}
{"topic":"orderbook.50.BTCUSDT","ts":1786191759576,"type":"delta","data":{"s":"BTCUSDT","b":[["64967.5","0"],["64967.4","0.099703"],["64963.5","0.07544"]],"a":[],"u":184066248,"seq":112464943234},"cts":1786191759560}
{"topic":"orderbook.50.BTCUSDT","ts":1786191759596,"type":"delta","data":{"s":"BTCUSDT","b":[],"a":[["64978","20.370984"]],"u":184066249,"seq":112464943237},"cts":1786191759584}
{"topic":"orderbook.50.BTCUSDT","ts":1786191759636,"type":"delta","data":{"s":"BTCUSDT","b":[["64967.6","0.099703"],["64967.4","0"]],"a":[],"u":184066250,"seq":112464943245},"cts":1786191759633}
{"topic":"orderbook.50.BTCUSDT","ts":1786191759656,"type":"delta","data":{"s":"BTCUSDT","b":[["64967.6","0"],["64967.4","0.099703"]],"a":[],"u":184066251,"seq":112464943249},"cts":1786191759647}
{"topic":"orderbook.50.BTCUSDT","ts":1786191759716,"type":"delta","data":{"s":"BTCUSDT","b":[["64967.4","0"],["64966.7","0.099704"]],"a":[],"u":184066252,"seq":112464943256},"cts":1786191759713}
{"topic":"orderbook.50.BTCUSDT","ts":1786191759736,"type":"delta","data":{"s":"BTCUSDT","b":[["64963.5","0.307784"]],"a":[],"u":184066253,"seq":112464943259},"cts":1786191759725}
{"topic":"orderbook.50.BTCUSDT","ts":1786191759776,"type":"delta","data":{"s":"BTCUSDT","b":[["64977.3","0.69402"]],"a":[],"u":184066254,"seq":112464943265},"cts":1786191759774}
{"topic":"orderbook.50.BTCUSDT","ts":1786191759796,"type":"delta","data":{"s":"BTCUSDT","b":[["64974.5","0.507459"],["64972.7","0.002151"],["64966.7","0"],["64966.6","0.312593"],["64962","0.000116"]],"a":[["64977.4","1.315042"]],"u":184066255,"seq":112464943273},"cts":1786191759794}
{"topic":"orderbook.50.BTCUSDT","ts":1786191759819,"type":"delta","data":{"s":"BTCUSDT","b":[["64966.6","0.212888"],["64966.2","0.099705"],["64962","0"]],"a":[["64977.4","1.333016"]],"u":184066256,"seq":112464943280},"cts":1786191759808}
{"topic":"orderbook.50.BTCUSDT","ts":1786191759836,"type":"delta","data":{"s":"BTCUSDT","b":[["64963.5","0.07544"]],"a":[["64977.4","1.348239"]],"u":184066257,"seq":112464943285},"cts":1786191759823}
{"topic":"orderbook.50.BTCUSDT","ts":1786191759976,"type":"delta","data":{"s":"BTCUSDT","b":[["64966.2","0"],["64965.7","0.099705"]],"a":[],"u":184066258,"seq":112464943309},"cts":1786191759960}
{"topic":"orderbook.50.BTCUSDT","ts":1786191760016,"type":"delta","data":{"s":"BTCUSDT","b":[],"a":[["64978.8","0"],["64989.8","0.0025"]],"u":184066259,"seq":112464943312},"cts":1786191760015}
{"topic":"orderbook.50.BTCUSDT","ts":1786191760035,"type":"delta","data":{"s":"BTCUSDT","b":[["64977.3","0.693252"]],"a":[],"u":184066260,"seq":112464943315},"cts":1786191760021}
{"topic":"orderbook.50.BTCUSDT","ts":1786191760156,"type":"delta","data":{"s":"BTCUSDT","b":[["64966.6","0.312593"],["64965.7","0"],["64962","0.000116"]],"a":[],"u":184066261,"seq":112464943325},"cts":1786191760154}
{"topic":"orderbook.50.BTCUSDT","ts":1786191760176,"type":"delta","data":{"s":"BTCUSDT","b":[["64966.6","0.212888"],["64965.7","0.099706"],["64962","0"]],"a":[["64978","20.253504"]],"u":184066262,"seq":112464943328},"cts":1786191760167}
{"topic":"orderbook.50.BTCUSDT","ts":1786191760196,"type":"delta","data":{"s":"BTCUSDT","b":[["64976.8","0.000093"],["64972.2","0.000093"],["64963.3","0"],["64962.3","0"]],"a":[],"u":184066263,"seq":112464943330},"cts":1786191760175}
{"topic":"orderbook.50.BTCUSDT","ts":1786191760376,"type":"delta","data":{"s":"BTCUSDT","b":[["64963.5","0.318716"]],"a":[],"u":184066264,"seq":112464943341},"cts":1786191760369}
{"topic":"orderbook.50.BTCUSDT","ts":1786191760496,"type":"delta","data":{"s":"BTCUSDT","b":[["64977.3","0.714978"]],"a":[["64977.4","1.347239"],["64983.9","0.042575"]],"u":184066265,"seq":112464943354},"cts":1786191760492}
{"topic":"orderbook.50.BTCUSDT","ts":1786191760516,"type":"delta","data":{"s":"BTCUSDT","b":[["64977.3","0.730637"]],"a":[["64977.4","1.332016"]],"u":184066266,"seq":112464943356},"cts":1786191760500}
{"topic":"orderbook.50.BTCUSDT","ts":1786191760536,"type":"delta","data":{"s":"BTCUSDT","b":[["64963.5","0.07544"]],"a":[["64977.4","1.314042"]],"u":184066267,"seq":112464943361},"cts":1786191760523}
{"topic":"orderbook.50.BTCUSDT","ts":1786191760756,"type":"delta","data":{"s":"BTCUSDT","b":[["64963.5","0.318716"]],"a":[],"u":184066268,"seq":112464943381},"cts":1786191760754}
{"topic":"orderbook.50.BTCUSDT","ts":1786191760776,"type":"delta","data":{"s":"BTCUSDT","b":[["64977.3","0.714978"]],"a":[],"u":184066269,"seq":112464943384},"cts":1786191760773}
{"topic":"orderbook.50.BTCUSDT","ts":1786191760796,"type":"delta","data":{"s":"BTCUSDT","b":[],"a":[["64977.4","1.298713"]],"u":184066270,"seq":112464943387},"cts":1786191760788}
{"topic":"orderbook.50.BTCUSDT","ts":1786191760936,"type":"delta","data":{"s":"BTCUSDT","b":[["64963.5","0.07544"]],"a":[],"u":184066271,"seq":112464943401},"cts":1786191760927}
{"topic":"orderbook.50.BTCUSDT","ts":1786191761256,"type":"delta","data":{"s":"BTCUSDT","b":[],"a":[["64977.4","1.301963"]],"u":184066272,"seq":112464943428},"cts":1786191761254}
{"topic":"orderbook.50.BTCUSDT","ts":1786191761276,"type":"delta","data":{"s":"BTCUSDT","b":[["64977.3","0.718228"],["64971.7","0"],["64970.8","0.0146"],["64970.7","0.0015"]],"a":[["64977.4","1.317473"],["64983.9","0.045825"]],"u":184066273,"seq":112464943447},"cts":1786191761266}
{"topic":"orderbook.50.BTCUSDT","ts":1786191761296,"type":"delta","data":{"s":"BTCUSDT","b":[],"a":[["64977.4","1.334093"]],"u":184066274,"seq":112464943452},"cts":1786191761289}
{"topic":"orderbook.50.BTCUSDT","ts":1786191761316,"type":"delta","data":{"s":"BTCUSDT","b":[["64975.1","0"],["64963.3","0.037082"]],"a":[["64977.4","1.351149"]],"u":184066275,"seq":112464943456},"cts":1786191761307}
{"topic":"orderbook.50.BTCUSDT","ts":1786191761336,"type":"delta","data":{"s":"BTCUSDT","b":[["64963.5","0.318716"]],"a":[],"u":184066276,"seq":112464943460},"cts":1786191761327}
{"topic":"orderbook.50.BTCUSDT","ts":1786191761356,"type":"delta","data":{"s":"BTCUSDT","b":[["64975.7","0.000078"],["64963.3","0"]],"a":[],"u":184066277,"seq":112464943464},"cts":1786191761354}
{"topic":"orderbook.50.BTCUSDT","ts":1786191761536,"type":"delta","data":{"s":"BTCUSDT","b":[["64963.5","0.07544"]],"a":[],"u":184066278,"seq":112464943488},"cts":1786191761530}
{"topic":"orderbook.50.BTCUSDT","ts":1786191761736,"type":"delta","data":{"s":"BTCUSDT","b":[["64963.5","0.318716"]],"a":[],"u":184066279,"seq":112464943509},"cts":1786191761733}
{"topic":"orderbook.50.BTCUSDT","ts":1786191761936,"type":"delta","data":{"s":"BTCUSDT","b":[["64963.5","0.07544"]],"a":[],"u":184066280,"seq":112464943522},"cts":1786191761927}
{"topic":"orderbook.50.BTCUSDT","ts":1786191761956,"type":"delta","data":{"s":"BTCUSDT","b":[],"a":[["64977.4","1.301963"]],"u":184066281,"seq":112464943527},"cts":1786191761946}
{"topic":"orderbook.50.BTCUSDT","ts":1786191762036,"type":"delta","data":{"s":"BTCUSDT","b":[["64963.5","0.318716"]],"a":[],"u":184066282,"seq":112464943539},"cts":1786191762018}
{"topic":"orderbook.50.BTCUSDT","ts":1786191762056,"type":"delta","data":{"s":"BTCUSDT","b":[["64966.7","0.099704"],["64965.7","0"]],"a":[],"u":184066283,"seq":112464943542},"cts":1786191762053}
{"topic":"orderbook.50.BTCUSDT","ts":1786191762096,"type":"delta","data":{"s":"BTCUSDT","b":[["64966.7","0"],["64965.7","0.099706"]],"a":[],"u":184066284,"seq":112464943548},"cts":1786191762093}
{"topic":"orderbook.50.BTCUSDT","ts":1786191762236,"type":"delta","data":{"s":"BTCUSDT","b":[["64963.5","0.07544"]],"a":[],"u":184066285,"seq":112464943563},"cts":1786191762223}
{"topic":"orderbook.50.BTCUSDT","ts":1786191762256,"type":"delta","data":{"s":"BTCUSDT","b":[["64975.2","0.000324"]],"a":[],"u":184066286,"seq":112464943566},"cts":1786191762251}
{"topic":"orderbook.50.BTCUSDT","ts":1786191762316,"type":"delta","data":{"s":"BTCUSDT","b":[],"a":[["64977.4","1.302116"]],"u":184066287,"seq":112464943570},"cts":1786191762297}
{"topic":"orderbook.50.BTCUSDT","ts":1786191762336,"type":"delta","data":{"s":"BTCUSDT","b":[["64977.3","0.726027"]],"a":[["64977.4","1.317686"]],"u":184066288,"seq":112464943575},"cts":1786191762332}
{"topic":"orderbook.50.BTCUSDT","ts":1786191762356,"type":"delta","data":{"s":"BTCUSDT","b":[["64977.3","0.718228"],["64963.5","0.318716"]],"a":[["64977.4","1.332954"]],"u":184066289,"seq":112464943581},"cts":1786191762354}
{"topic":"orderbook.50.BTCUSDT","ts":1786191762376,"type":"delta","data":{"s":"BTCUSDT","b":[],"a":[["64977.4","1.349754"]],"u":184066290,"seq":112464943584},"cts":1786191762366}
{"topic":"orderbook.50.BTCUSDT","ts":1786191762436,"type":"delta","data":{"s":"BTCUSDT","b":[["64963.5","0.07544"]],"a":[],"u":184066291,"seq":112464943591},"cts":1786191762425}
{"topic":"orderbook.50.BTCUSDT","ts":1786191762496,"type":"delta","data":{"s":"BTCUSDT","b":[["64977.3","0"],["64976.9","0"],["64976.8","0"],["64976.6","0"],["64976.4","0"],["64974.6","0.261742"],["64966.7","0.099704"],["64965.7","0"],["64963.3","0.037082"],["64962.3","0.000324"],["64962","0.000116"],["64961.6","0.004984"]],"a":[["64976.2","0.40911"],["64976.5","0.7859"],["64977.8","0"],["64989.8","0"]],"u":184066292,"seq":112464943613},"cts":1786191762494}
{"topic":"orderbook.50.BTCUSDT","ts":1786191762516,"type":"delta","data":{"s":"BTCUSDT","b":[["64976.1","0.525517"],["64974.8","0"],["64973.5","0.036701"],["64970.8","0"],["64970.7","0"],["64970.6","0.0015"],["64969.6","0.013"],["64966.7","0"],["64965.7","0.099706"],["64961.6","0"],["64960.8","0.769695"],["64960.6","0.164822"]],"a":[["64976.2","1.210937"],["64976.5","0"],["64977.3","0.11748"],["64977.4","0.236073"],["64982.7","0.013186"],["64983.8","0.007799"],["64983.9","0.023426"],["64989.2","0.006"],["64989.6","0"],["64989.7","0"]],"u":184066293,"seq":112464943826},"cts":1786191762513}
{"topic":"orderbook.50.BTCUSDT","ts":1786191762536,"type":"delta","data":{"s":"BTCUSDT","b":[["64973.6","0.021599"],["64963.5","0.317228"]],"a":[["64976.2","1.213937"],["64982.7","0.020985"],["64983.8","0"],["64989.6","0.150033"]],"u":184066294,"seq":112464943834},"cts":1786191762528}
{"topic":"orderbook.50.BTCUSDT","ts":1786191762556,"type":"delta","data":{"s":"BTCUSDT","b":[["64963.5","0.07544"],["64960.8","0"],["64960.5","0.617969"]],"a":[["64989.6","0.296653"]],"u":184066295,"seq":112464943838},"cts":1786191762554}
{"topic":"orderbook.50.BTCUSDT","ts":1786191762576,"type":"delta","data":{"s":"BTCUSDT","b":[["64976.1","0.51338"],["64974.5","0.123013"]],"a":[],"u":184066296,"seq":112464943849},"cts":1786191762572}
{"topic":"orderbook.50.BTCUSDT","ts":1786191762596,"type":"delta","data":{"s":"BTCUSDT","b":[["64974.6","0.531431"]],"a":[],"u":184066297,"seq":112464943856},"cts":1786191762588}
{"topic":"orderbook.50.BTCUSDT","ts":1786191762636,"type":"delta","data":{"s":"BTCUSDT","b":[["64965.8","0.099706"],["64965.7","0"]],"a":[["64978.1","0"],["64989.7","0.03"]],"u":184066298,"seq":112464943870},"cts":1786191762629}
{"topic":"orderbook.50.BTCUSDT","ts":1786191762656,"type":"delta","data":{"s":"BTCUSDT","b":[["64965.8","0"],["64965.7","0.099706"]],"a":[["64977.4","0.107873"]],"u":184066299,"seq":112464943873},"cts":1786191762650}
{"topic":"orderbook.50.BTCUSDT","ts":1786191762676,"type":"delta","data":{"s":"BTCUSDT","b":[],"a":[["64982.7","0.149185"]],"u":184066300,"seq":112464943876},"cts":1786191762671}
{"topic":"orderbook.50.BTCUSDT","ts":1786191762716,"type":"delta","data":{"s":"BTCUSDT","b":[],"a":[["64979.4","0"],["64989.8","0.0025"]],"u":184066301,"seq":112464943884},"cts":1786191762702}
{"topic":"orderbook.50.BTCUSDT","ts":1786191762796,"type":"delta","data":{"s":"BTCUSDT","b":[],"a":[["64980.7","0"],["64990","0.895423"]],"u":184066302,"seq":112464943888},"cts":1786191762777}
{"topic":"orderbook.50.BTCUSDT","ts":1786191762816,"type":"delta","data":{"s":"BTCUSDT","b":[["64966.2","0.099705"],["64965.7","0"]],"a":[],"u":184066303,"seq":112464943891},"cts":1786191762804}
{"topic":"orderbook.50.BTCUSDT","ts":1786191762835,"type":"delta","data":{"s":"BTCUSDT","b":[["64966.2","0"],["64965.7","0.099706"]],"a":[],"u":184066304,"seq":112464943892},"cts":1786191762830}
{"topic":"orderbook.50.BTCUSDT","ts":1786191762856,"type":"delta","data":{"s":"BTCUSDT","b":[],"a":[["64988.5","0"],["64990.9","1.330965"]],"u":184066305,"seq":112464943893},"cts":1786191762844}
{"topic":"orderbook.50.BTCUSDT","ts":1786191762876,"type":"delta","data":{"s":"BTCUSDT","b":[],"a":[["64982","1.419551"]],"u":184066306,"seq":112464943894},"cts":1786191762858}
{"topic":"orderbook.50.BTCUSDT","ts":1786191762936,"type":"delta","data":{"s":"BTCUSDT","b":[["64974.7","0.267742"],["64974.6","0.384446"]],"a":[["64983.3","0"],["64991","3"]],"u":184066307,"seq":112464943904},"cts":1786191762930}
{"topic":"orderbook.50.BTCUSDT","ts":1786191762956,"type":"delta","data":{"s":"BTCUSDT","b":[],"a":[["64976.2","1.280602"],["64983.4","0.027833"],["64991","0"]],"u":184066308,"seq":112464943909},"cts":1786191762942}
{"topic":"orderbook.50.BTCUSDT","ts":1786191762976,"type":"delta","data":{"s":"BTCUSDT","b":[],"a":[["64983.4","0"],["64991","3"]],"u":184066309,"seq":112464943912},"cts":1786191762972}
{"topic":"orderbook.50.BTCUSDT","ts":1786191763019,"type":"delta","data":{"s":"BTCUSDT","b":[["64975.3","0"],["64960.4","0.507459"]],"a":[],"u":184066310,"seq":112464943917},"cts":1786191763016}
{"topic":"orderbook.50.BTCUSDT","ts":1786191763036,"type":"delta","data":{"s":"BTCUSDT","b":[["64976.1","0.51566"]],"a":[],"u":184066311,"seq":112464943921},"cts":1786191763026}
{"topic":"orderbook.50.BTCUSDT","ts":1786191763056,"type":"delta","data":{"s":"BTCUSDT","b":[["64976.1","0.533358"]],"a":[["64977.3","0.119017"]],"u":184066312,"seq":112464943926},"cts":1786191763054}
{"topic":"orderbook.50.BTCUSDT","ts":1786191763076,"type":"delta","data":{"s":"BTCUSDT","b":[["64976.1","0.550367"]],"a":[],"u":184066313,"seq":112464943927},"cts":1786191763060}
{"topic":"orderbook.50.BTCUSDT","ts":1786191763096,"type":"delta","data":{"s":"BTCUSDT","b":[["64976.1","0.568586"]],"a":[["64977.4","0.026394"]],"u":184066314,"seq":112464943934},"cts":1786191763093}
{"topic":"orderbook.50.BTCUSDT","ts":1786191763116,"type":"delta","data":{"s":"BTCUSDT","b":[["64976.1","0.631286"],["64974","0.0627"]],"a":[["64976.2","1.297071"]],"u":184066315,"seq":112464943948},"cts":1786191763111}
{"topic":"orderbook.50.BTCUSDT","ts":1786191763136,"type":"delta","data":{"s":"BTCUSDT","b":[["64976.1","0.632046"]],"a":[["64976.2","1.314452"]],"u":184066316,"seq":112464943957},"cts":1786191763132}
{"topic":"orderbook.50.BTCUSDT","ts":1786191763176,"type":"delta","data":{"s":"BTCUSDT","b":[["64976.1","0.638886"]],"a":[],"u":184066317,"seq":112464943972},"cts":1786191763173}
{"topic":"orderbook.50.BTCUSDT","ts":1786191763196,"type":"delta","data":{"s":"BTCUSDT","b":[["64976.1","0.635846"],["64972.7","0"],["64959.9","0.004984"]],"a":[],"u":184066318,"seq":112464943977},"cts":1786191763192}
{"topic":"orderbook.50.BTCUSDT","ts":1786191763236,"type":"delta","data":{"s":"BTCUSDT","b":[["64976.1","0.631286"]],"a":[],"u":184066319,"seq":112464943988},"cts":1786191763233}
{"topic":"orderbook.50.BTCUSDT","ts":1786191763256,"type":"delta","data":{"s":"BTCUSDT","b":[["64976.1","0.629006"],["64971.4","0"],["64959.7","0.043444"]],"a":[["64976.2","1.297071"]],"u":184066320,"seq":112464943994},"cts":1786191763251}
{"topic":"orderbook.50.BTCUSDT","ts":1786191763356,"type":"delta","data":{"s":"BTCUSDT","b":[["64976.1","0.629766"]],"a":[],"u":184066321,"seq":112464944000},"cts":1786191763351}
{"topic":"orderbook.50.BTCUSDT","ts":1786191763376,"type":"delta","data":{"s":"BTCUSDT","b":[],"a":[["64976.2","1.280602"]],"u":184066322,"seq":112464944002},"cts":1786191763360}
{"topic":"orderbook.50.BTCUSDT","ts":1786191763436,"type":"delta","data":{"s":"BTCUSDT","b":[["64976.1","0.629006"],["64974.6","0.388717"]],"a":[["64976.2","1.213937"]],"u":184066323,"seq":112464944010},"cts":1786191763431}
{"topic":"orderbook.50.BTCUSDT","ts":1786191763456,"type":"delta","data":{"s":"BTCUSDT","b":[["64976.1","0.632046"]],"a":[],"u":184066324,"seq":112464944014},"cts":1786191763454}
{"topic":"orderbook.50.BTCUSDT","ts":1786191763476,"type":"delta","data":{"s":"BTCUSDT","b":[["64976.1","0.634326"]],"a":[],"u":184066325,"seq":112464944021},"cts":1786191763461}
{"topic":"orderbook.50.BTCUSDT","ts":1786191763516,"type":"delta","data":{"s":"BTCUSDT","b":[["64973.4","0.003559"],["64959.7","0"]],"a":[],"u":184066326,"seq":112464944026},"cts":1786191763515}
{"topic":"orderbook.50.BTCUSDT","ts":1786191763536,"type":"delta","data":{"s":"BTCUSDT","b":[["64976.1","0.629006"]],"a":[],"u":184066327,"seq":112464944033},"cts":1786191763531}
{"topic":"orderbook.50.BTCUSDT","ts":1786191763556,"type":"delta","data":{"s":"BTCUSDT","b":[["64976.1","0.652006"]],"a":[["64976.2","1.232102"],["64978.2","0"],["64991.4","0.247739"]],"u":184066328,"seq":112464944036},"cts":1786191763545}
{"topic":"orderbook.50.BTCUSDT","ts":1786191763576,"type":"delta","data":{"s":"BTCUSDT","b":[["64976.1","0.654286"],["64972.1","0.002847"],["64959.9","0"]],"a":[],"u":184066329,"seq":112464944045},"cts":1786191763574}
{"topic":"orderbook.50.BTCUSDT","ts":1786191763616,"type":"delta","data":{"s":"BTCUSDT","b":[["64976.1","0.655046"]],"a":[],"u":184066330,"seq":112464944046},"cts":1786191763609}
{"topic":"orderbook.50.BTCUSDT","ts":1786191763636,"type":"delta","data":{"s":"BTCUSDT","b":[["64976.1","0.658086"]],"a":[],"u":184066331,"seq":112464944053},"cts":1786191763628}
{"topic":"orderbook.50.BTCUSDT","ts":1786191763656,"type":"delta","data":{"s":"BTCUSDT","b":[["64970.8","0.002135"],["64960.4","0"]],"a":[],"u":184066332,"seq":112464944063},"cts":1786191763654}
{"topic":"orderbook.50.BTCUSDT","ts":1786191763676,"type":"delta","data":{"s":"BTCUSDT","b":[["64976.1","0.661126"]],"a":[],"u":184066333,"seq":112464944071},"cts":1786191763670}
{"topic":"orderbook.50.BTCUSDT","ts":1786191763695,"type":"delta","data":{"s":"BTCUSDT","b":[["64976.1","0.660366"]],"a":[],"u":184066334,"seq":112464944072},"cts":1786191763689}
{"topic":"orderbook.50.BTCUSDT","ts":1786191763715,"type":"delta","data":{"s":"BTCUSDT","b":[["64976.1","0.657326"]],"a":[],"u":184066335,"seq":112464944077},"cts":1786191763701}
{"topic":"orderbook.50.BTCUSDT","ts":1786191763736,"type":"delta","data":{"s":"BTCUSDT","b":[["64976.1","0.655046"],["64969.5","0.001423"],["64960.5","0"]],"a":[],"u":184066336,"seq":112464944090},"cts":1786191763732}
{"topic":"orderbook.50.BTCUSDT","ts":1786191763756,"type":"delta","data":{"s":"BTCUSDT","b":[["64976.1","0.654286"]],"a":[],"u":184066337,"seq":112464944091},"cts":1786191763742}
{"topic":"orderbook.50.BTCUSDT","ts":1786191763776,"type":"delta","data":{"s":"BTCUSDT","b":[["64976.1","0.655046"]],"a":[],"u":184066338,"seq":112464944096},"cts":1786191763774}
{"topic":"orderbook.50.BTCUSDT","ts":1786191763796,"type":"delta","data":{"s":"BTCUSDT","b":[["64976.1","0.654286"]],"a":[["64976.2","1.237064"]],"u":184066339,"seq":112464944101},"cts":1786191763792}
{"topic":"orderbook.50.BTCUSDT","ts":1786191763818,"type":"delta","data":{"s":"BTCUSDT","b":[["64976.1","0.658086"]],"a":[["64976.2","1.249726"]],"u":184066340,"seq":112464944109},"cts":1786191763815}
{"topic":"orderbook.50.BTCUSDT","ts":1786191763836,"type":"delta","data":{"s":"BTCUSDT","b":[["64976.1","0.837392"]],"a":[],"u":184066341,"seq":112464944117},"cts":1786191763825}
{"topic":"orderbook.50.BTCUSDT","ts":1786191763856,"type":"delta","data":{"s":"BTCUSDT","b":[["64976.1","0.835872"]],"a":[],"u":184066342,"seq":112464944119},"cts":1786191763851}
{"topic":"orderbook.50.BTCUSDT","ts":1786191763876,"type":"delta","data":{"s":"BTCUSDT","b":[["64976.1","0.838152"]],"a":[["64977.5","0.004135"],["64991.4","0"]],"u":184066343,"seq":112464944124},"cts":1786191763866}
{"topic":"orderbook.50.BTCUSDT","ts":1786191763896,"type":"delta","data":{"s":"BTCUSDT","b":[["64976.1","0.832832"]],"a":[],"u":184066344,"seq":112464944131},"cts":1786191763892}
{"topic":"orderbook.50.BTCUSDT","ts":1786191763916,"type":"delta","data":{"s":"BTCUSDT","b":[["64976.1","0.833592"]],"a":[],"u":184066345,"seq":112464944135},"cts":1786191763914}
{"topic":"orderbook.50.BTCUSDT","ts":1786191763936,"type":"delta","data":{"s":"BTCUSDT","b":[["64976.1","0.832832"]],"a":[["64976.2","1.231561"]],"u":184066346,"seq":112464944142},"cts":1786191763931}
{"topic":"orderbook.50.BTCUSDT","ts":1786191763956,"type":"delta","data":{"s":"BTCUSDT","b":[["64976.1","0.831312"]],"a":[["64978.8","0.003308"],["64991","0"]],"u":184066347,"seq":112464944147},"cts":1786191763942}
{"topic":"orderbook.50.BTCUSDT","ts":1786191763976,"type":"delta","data":{"s":"BTCUSDT","b":[["64976.1","0.832832"]],"a":[["64976.2","1.230761"]],"u":184066348,"seq":112464944153},"cts":1786191763973}
{"topic":"orderbook.50.BTCUSDT","ts":1786191763996,"type":"delta","data":{"s":"BTCUSDT","b":[["64976.1","0.832072"]],"a":[["64976.2","1.245866"]],"u":184066349,"seq":112464944159},"cts":1786191763988}
{"topic":"orderbook.50.BTCUSDT","ts":1786191764016,"type":"delta","data":{"s":"BTCUSDT","b":[["64976.1","0.834352"]],"a":[["64980.1","0.002574"]],"u":184066350,"seq":112464944163},"cts":1786191764012}
{"topic":"orderbook.50.BTCUSDT","ts":1786191764036,"type":"delta","data":{"s":"BTCUSDT","b":[["64976.1","0.835112"]],"a":[],"u":184066351,"seq":112464944172},"cts":1786191764030}
{"topic":"orderbook.50.BTCUSDT","ts":1786191764056,"type":"delta","data":{"s":"BTCUSDT","b":[["64962.5","0.000861"],["64960.6","0"]],"a":[],"u":184066352,"seq":112464944173},"cts":1786191764040}
{"topic":"orderbook.50.BTCUSDT","ts":1786191764096,"type":"delta","data":{"s":"BTCUSDT","b":[["64976.1","0.832072"]],"a":[["64981.4","0.001654"],["64990.9","0"]],"u":184066353,"seq":112464944181},"cts":1786191764092}
{"topic":"orderbook.50.BTCUSDT","ts":1786191764116,"type":"delta","data":{"s":"BTCUSDT","b":[["64976.1","0.834352"]],"a":[],"u":184066354,"seq":112464944193},"cts":1786191764115}
{"topic":"orderbook.50.BTCUSDT","ts":1786191764136,"type":"delta","data":{"s":"BTCUSDT","b":[["64976.1","0.835872"]],"a":[],"u":184066355,"seq":112464944199},"cts":1786191764133}
{"topic":"orderbook.50.BTCUSDT","ts":1786191764156,"type":"delta","data":{"s":"BTCUSDT","b":[["64976.1","0.817653"]],"a":[],"u":184066356,"seq":112464944200},"cts":1786191764140}
{"topic":"orderbook.50.BTCUSDT","ts":1786191764176,"type":"delta","data":{"s":"BTCUSDT","b":[["64977.9","1.519128"],["64977.6","0.1282"],["64977.4","0.123013"],["64976.2","0.534942"],["64976.1","0.076348"],["64974.7","0.006"],["64974","0"],["64971.4","0.00975"],["64970.7","0.0015"],["64970.6","0"],["64969.6","0"],["64967.3","0"],["64965.7","0"],["64964.1","0.099707"],["64962.3","0"],["64962","0"]],"a":[["64976.2","0"],["64977.3","0"],["64977.4","0"],["64977.5","0"],["64978","20.297803"],["64982.7","0.128386"],["64984.5","0.017549"],["64990.9","1.330965"],["64991","3"],["64991.4","0.247739"]],"u":184066357,"seq":112464944366},"cts":1786191764173}
{"topic":"orderbook.50.BTCUSDT","ts":1786191764196,"type":"delta","data":{"s":"BTCUSDT","b":[["64976.2","0.294947"],["64976.1","0.070268"],["64975.4","0.00012"],["64973.6","0.021436"],["64970.2","0"],["64970.1","0.088"],["64962.5","0"]],"a":[["64978","20.301053"]],"u":184066358,"seq":112464944392},"cts":1786191764195}
{"topic":"orderbook.50.BTCUSDT","ts":1786191764216,"type":"delta","data":{"s":"BTCUSDT","b":[["64977.9","1.369128"],["64976.1","0.072548"],["64965.7","0.099706"],["64964.1","0"]],"a":[],"u":184066359,"seq":112464944414},"cts":1786191764214}
{"topic":"orderbook.50.BTCUSDT","ts":1786191764236,"type":"delta","data":{"s":"BTCUSDT","b":[["64977.9","1.566628"],["64976.1","0.073308"],["64966.7","0.099704"],["64965.7","0"]],"a":[],"u":184066360,"seq":112464944429},"cts":1786191764234}
{"topic":"orderbook.50.BTCUSDT","ts":1786191764256,"type":"delta","data":{"s":"BTCUSDT","b":[["64977.9","1.567388"],["64976.1","0.071788"],["64976","0.039053"]],"a":[],"u":184066361,"seq":112464944440},"cts":1786191764254}
{"topic":"orderbook.50.BTCUSDT","ts":1786191764275,"type":"delta","data":{"s":"BTCUSDT","b":[["64977.9","1.57318"],["64976.1","0.071028"]],"a":[],"u":184066362,"seq":112464944460},"cts":1786191764275}
{"topic":"orderbook.50.BTCUSDT","ts":1786191764296,"type":"delta","data":{"s":"BTCUSDT","b":[["64977.9","1.576172"],["64976.1","0.070268"]],"a":[],"u":184066363,"seq":112464944470},"cts":1786191764292}
{"topic":"orderbook.50.BTCUSDT","ts":1786191764316,"type":"delta","data":{"s":"BTCUSDT","b":[["64977.9","1.577692"],["64976.1","0.067988"],["64966.7","0"],["64966.2","0.099705"]],"a":[],"u":184066364,"seq":112464944484},"cts":1786191764314}
{"topic":"orderbook.50.BTCUSDT","ts":1786191764336,"type":"delta","data":{"s":"BTCUSDT","b":[["64977.9","1.575412"],["64977.6","0"],["64962.5","0.000861"]],"a":[["64978.8","0"],["64991.5","0.000324"]],"u":184066365,"seq":112464944496},"cts":1786191764330}
{"topic":"orderbook.50.BTCUSDT","ts":1786191764356,"type":"delta","data":{"s":"BTCUSDT","b":[["64977.9","1.573132"]],"a":[],"u":184066366,"seq":112464944499},"cts":1786191764341}
{"topic":"orderbook.50.BTCUSDT","ts":1786191764376,"type":"delta","data":{"s":"BTCUSDT","b":[["64977.9","1.575412"]],"a":[],"u":184066367,"seq":112464944506},"cts":1786191764374}
{"topic":"orderbook.50.BTCUSDT","ts":1786191764396,"type":"delta","data":{"s":"BTCUSDT","b":[["64977.9","1.574652"]],"a":[],"u":184066368,"seq":112464944512},"cts":1786191764391}
{"topic":"orderbook.50.BTCUSDT","ts":1786191764416,"type":"delta","data":{"s":"BTCUSDT","b":[],"a":[["64980.1","0.000093"]],"u":184066369,"seq":112464944516},"cts":1786191764412}
{"topic":"orderbook.50.BTCUSDT","ts":1786191764436,"type":"delta","data":{"s":"BTCUSDT","b":[["64977.9","1.575412"]],"a":[],"u":184066370,"seq":112464944520},"cts":1786191764429}
{"topic":"orderbook.50.BTCUSDT","ts":1786191764456,"type":"delta","data":{"s":"BTCUSDT","b":[["64977.9","1.572372"]],"a":[],"u":184066371,"seq":112464944526},"cts":1786191764452}
{"topic":"orderbook.50.BTCUSDT","ts":1786191764476,"type":"delta","data":{"s":"BTCUSDT","b":[["64977.9","1.579972"]],"a":[["64981.4","0"],["64991.9","0.02143"]],"u":184066372,"seq":112464944538},"cts":1786191764471}
{"topic":"orderbook.50.BTCUSDT","ts":1786191764496,"type":"delta","data":{"s":"BTCUSDT","b":[["64966.2","0"],["64965.7","0.099705"]],"a":[["64978","20.321471"]],"u":184066373,"seq":112464944542},"cts":1786191764493}
{"topic":"orderbook.50.BTCUSDT","ts":1786191764516,"type":"delta","data":{"s":"BTCUSDT","b":[["64977.9","1.579212"]],"a":[],"u":184066374,"seq":112464944545},"cts":1786191764500}
{"topic":"orderbook.50.BTCUSDT","ts":1786191764536,"type":"delta","data":{"s":"BTCUSDT","b":[["64977.9","1.377152"],["64976.2","0.298025"],["64976","0.035975"]],"a":[],"u":184066375,"seq":112464944560},"cts":1786191764534}
{"topic":"orderbook.50.BTCUSDT","ts":1786191764556,"type":"delta","data":{"s":"BTCUSDT","b":[["64977.9","1.374112"],["64974.6","0.384446"]],"a":[],"u":184066376,"seq":112464944572},"cts":1786191764544}
{"topic":"orderbook.50.BTCUSDT","ts":1786191764576,"type":"delta","data":{"s":"BTCUSDT","b":[["64977.9","1.374872"]],"a":[],"u":184066377,"seq":112464944574},"cts":1786191764574}
{"topic":"orderbook.50.BTCUSDT","ts":1786191764596,"type":"delta","data":{"s":"BTCUSDT","b":[["64977.9","1.377152"]],"a":[],"u":184066378,"seq":112464944584},"cts":1786191764592}
{"topic":"orderbook.50.BTCUSDT","ts":1786191764636,"type":"delta","data":{"s":"BTCUSDT","b":[["64973.4","0"],["64962.3","0.000324"]],"a":[["64987.2","0.000678"],["64991.9","0"]],"u":184066379,"seq":112464944588},"cts":1786191764632}
{"topic":"orderbook.50.BTCUSDT","ts":1786191764676,"type":"delta","data":{"s":"BTCUSDT","b":[["64977.9","1.381712"]],"a":[],"u":184066380,"seq":112464944606},"cts":1786191764673}
{"topic":"orderbook.50.BTCUSDT","ts":1786191764696,"type":"delta","data":{"s":"BTCUSDT","b":[["64977.9","1.39932"],["64972.1","0"],["64962","0.000116"]],"a":[["64978.1","0.000561"],["64991.5","0"]],"u":184066381,"seq":112464944612},"cts":1786191764692}
{"topic":"orderbook.50.BTCUSDT","ts":1786191764756,"type":"delta","data":{"s":"BTCUSDT","b":[["64977.9","1.39248"]],"a":[],"u":184066382,"seq":112464944630},"cts":1786191764753}
{"topic":"orderbook.50.BTCUSDT","ts":1786191764776,"type":"delta","data":{"s":"BTCUSDT","b":[["64977.9","1.39324"],["64973.5","0.055"],["64970.8","0"],["64961.9","0.015389"]],"a":[["64988.6","0.018295"],["64991.4","0"]],"u":184066383,"seq":112464944634},"cts":1786191764771}
{"topic":"orderbook.50.BTCUSDT","ts":1786191764796,"type":"delta","data":{"s":"BTCUSDT","b":[["64977.9","1.39552"]],"a":[],"u":184066384,"seq":112464944639},"cts":1786191764780}
{"topic":"orderbook.50.BTCUSDT","ts":1786191764856,"type":"delta","data":{"s":"BTCUSDT","b":[["64969.5","0"],["64961.7","0.004984"]],"a":[],"u":184066385,"seq":112464944657},"cts":1786191764855}
{"topic":"orderbook.50.BTCUSDT","ts":1786191764876,"type":"delta","data":{"s":"BTCUSDT","b":[["64977.9","1.39932"]],"a":[],"u":184066386,"seq":112464944662},"cts":1786191764862}
{"topic":"orderbook.50.BTCUSDT","ts":1786191764916,"type":"delta","data":{"s":"BTCUSDT","b":[["64977.9","1.39856"]],"a":[],"u":184066387,"seq":112464944666},"cts":1786191764900}
{"topic":"orderbook.50.BTCUSDT","ts":1786191764936,"type":"delta","data":{"s":"BTCUSDT","b":[["64977.9","1.39324"],["64976.6","0.004339"],["64961.7","0"]],"a":[],"u":184066388,"seq":112464944681},"cts":1786191764932}
{"topic":"orderbook.50.BTCUSDT","ts":1786191764956,"type":"delta","data":{"s":"BTCUSDT","b":[["64977.9","1.39172"]],"a":[],"u":184066389,"seq":112464944686},"cts":1786191764939}
{"topic":"orderbook.50.BTCUSDT","ts":1786191765017,"type":"delta","data":{"s":"BTCUSDT","b":[["64977.9","1.39324"],["64975.3","0.003616"],["64961.9","0"]],"a":[],"u":184066390,"seq":112464944694},"cts":1786191765012}
{"topic":"orderbook.50.BTCUSDT","ts":1786191765036,"type":"delta","data":{"s":"BTCUSDT","b":[["64977.9","1.39932"]],"a":[],"u":184066391,"seq":112464944706},"cts":1786191765028}
{"topic":"orderbook.50.BTCUSDT","ts":1786191765055,"type":"delta","data":{"s":"BTCUSDT","b":[["64966.6","0.312593"],["64965.7","0"],["64961.9","0.015389"]],"a":[],"u":184066392,"seq":112464944708},"cts":1786191765052}
{"topic":"orderbook.50.BTCUSDT","ts":1786191765076,"type":"delta","data":{"s":"BTCUSDT","b":[["64974","0.002892"],["64961.9","0"]],"a":[],"u":184066393,"seq":112464944714},"cts":1786191765075}
{"topic":"orderbook.50.BTCUSDT","ts":1786191765096,"type":"delta","data":{"s":"BTCUSDT","b":[["64977.9","1.397141"],["64966.6","0.212888"],["64965.7","0.099706"],["64962","0"]],"a":[],"u":184066394,"seq":112464944723},"cts":1786191765091}
{"topic":"orderbook.50.BTCUSDT","ts":1786191765117,"type":"delta","data":{"s":"BTCUSDT","b":[["64977.9","1.396691"]],"a":[],"u":184066395,"seq":112464944738},"cts":1786191765107}
{"topic":"orderbook.50.BTCUSDT","ts":1786191765156,"type":"delta","data":{"s":"BTCUSDT","b":[["64972.7","0.002169"],["64962.3","0"]],"a":[],"u":184066396,"seq":112464944743},"cts":1786191765153}
{"topic":"orderbook.50.BTCUSDT","ts":1786191765176,"type":"delta","data":{"s":"BTCUSDT","b":[["64977","0.003078"],["64976.2","0.294947"],["64962.5","0"]],"a":[],"u":184066397,"seq":112464944746},"cts":1786191765171}
{"topic":"orderbook.50.BTCUSDT","ts":1786191765196,"type":"delta","data":{"s":"BTCUSDT","b":[["64977.9","1.395931"]],"a":[],"u":184066398,"seq":112464944758},"cts":1786191765187}
{"topic":"orderbook.50.BTCUSDT","ts":1786191765236,"type":"delta","data":{"s":"BTCUSDT","b":[["64971.4","0.011196"]],"a":[],"u":184066399,"seq":112464944762},"cts":1786191765227}
{"topic":"orderbook.50.BTCUSDT","ts":1786191765256,"type":"delta","data":{"s":"BTCUSDT","b":[["64977.9","1.393651"]],"a":[],"u":184066400,"seq":112464944766},"cts":1786191765251}
{"topic":"orderbook.50.BTCUSDT","ts":1786191765316,"type":"delta","data":{"s":"BTCUSDT","b":[],"a":[["64978.1","0.005455"]],"u":184066401,"seq":112464944770},"cts":1786191765298}
{"topic":"orderbook.50.BTCUSDT","ts":1786191765376,"type":"delta","data":{"s":"BTCUSDT","b":[["64976.1","0.033281"]],"a":[["64979.4","0.004078"],["64991","0"]],"u":184066402,"seq":112464944778},"cts":1786191765370}
{"topic":"orderbook.50.BTCUSDT","ts":1786191765456,"type":"delta","data":{"s":"BTCUSDT","b":[],"a":[["64980.7","0.003263"],["64990.9","0"]],"u":184066403,"seq":112464944787},"cts":1786191765444}
{"topic":"orderbook.50.BTCUSDT","ts":1786191765536,"type":"delta","data":{"s":"BTCUSDT","b":[["64977.9","1.265451"]],"a":[["64982","1.421998"]],"u":184066404,"seq":112464944799},"cts":1786191765523}
{"topic":"orderbook.50.BTCUSDT","ts":1786191765556,"type":"delta","data":{"s":"BTCUSDT","b":[],"a":[["64978","20.388136"]],"u":184066405,"seq":112464944803},"cts":1786191765546}
{"topic":"orderbook.50.BTCUSDT","ts":1786191765576,"type":"delta","data":{"s":"BTCUSDT","b":[["64977.9","1.247843"]],"a":[["64978","20.387905"]],"u":184066406,"seq":112464944813},"cts":1786191765572}
{"topic":"orderbook.50.BTCUSDT","ts":1786191765596,"type":"delta","data":{"s":"BTCUSDT","b":[],"a":[["64983.3","0.001631"],["64990","0"]],"u":184066407,"seq":112464944817},"cts":1786191765592}
{"topic":"orderbook.50.BTCUSDT","ts":1786191765615,"type":"delta","data":{"s":"BTCUSDT","b":[["64977.9","1.253163"]],"a":[],"u":184066408,"seq":112464944826},"cts":1786191765610}
{"topic":"orderbook.50.BTCUSDT","ts":1786191765636,"type":"delta","data":{"s":"BTCUSDT","b":[["64977.9","1.27478"]],"a":[],"u":184066409,"seq":112464944838},"cts":1786191765627}
{"topic":"orderbook.50.BTCUSDT","ts":1786191765696,"type":"delta","data":{"s":"BTCUSDT","b":[["64977.9","1.26718"]],"a":[],"u":184066410,"seq":112464944852},"cts":1786191765694}
{"topic":"orderbook.50.BTCUSDT","ts":1786191765716,"type":"delta","data":{"s":"BTCUSDT","b":[["64977.9","1.26414"]],"a":[],"u":184066411,"seq":112464944861},"cts":1786191765703}
{"topic":"orderbook.50.BTCUSDT","ts":1786191765776,"type":"delta","data":{"s":"BTCUSDT","b":[["64977.9","1.26642"]],"a":[],"u":184066412,"seq":112464944868},"cts":1786191765769}
{"topic":"orderbook.50.BTCUSDT","ts":1786191765856,"type":"delta","data":{"s":"BTCUSDT","b":[["64977.9","1.26414"]],"a":[],"u":184066413,"seq":112464944875},"cts":1786191765851}
{"topic":"orderbook.50.BTCUSDT","ts":1786191765876,"type":"delta","data":{"s":"BTCUSDT","b":[["64977.9","1.26946"]],"a":[],"u":184066414,"seq":112464944883},"cts":1786191765861}
{"topic":"orderbook.50.BTCUSDT","ts":1786191765936,"type":"delta","data":{"s":"BTCUSDT","b":[["64977.9","1.26642"]],"a":[],"u":184066415,"seq":112464944889},"cts":1786191765931}
{"topic":"orderbook.50.BTCUSDT","ts":1786191765956,"type":"delta","data":{"s":"BTCUSDT","b":[["64977.9","1.26414"]],"a":[],"u":184066416,"seq":112464944894},"cts":1786191765954}
{"topic":"orderbook.50.BTCUSDT","ts":1786191766316,"type":"delta","data":{"s":"BTCUSDT","b":[["64977.9","1.26307"]],"a":[],"u":184066417,"seq":112464944928},"cts":1786191766306}
{"topic":"orderbook.50.BTCUSDT","ts":1786191766336,"type":"delta","data":{"s":"BTCUSDT","b":[["64977.9","1.246773"]],"a":[],"u":184066418,"seq":112464944933},"cts":1786191766327}
{"topic":"orderbook.50.BTCUSDT","ts":1786191766416,"type":"delta","data":{"s":"BTCUSDT","b":[["64977.9","1.249363"]],"a":[],"u":184066419,"seq":112464944947},"cts":1786191766414}
{"topic":"orderbook.50.BTCUSDT","ts":1786191766436,"type":"delta","data":{"s":"BTCUSDT","b":[["64977.9","1.254683"]],"a":[],"u":184066420,"seq":112464944958},"cts":1786191766425}
{"topic":"orderbook.50.BTCUSDT","ts":1786191766497,"type":"delta","data":{"s":"BTCUSDT","b":[["64977.9","1.249813"]],"a":[],"u":184066421,"seq":112464944965},"cts":1786191766490}
{"topic":"orderbook.50.BTCUSDT","ts":1786191766516,"type":"delta","data":{"s":"BTCUSDT","b":[["64977.9","1.247533"]],"a":[],"u":184066422,"seq":112464944972},"cts":1786191766506}
{"topic":"orderbook.50.BTCUSDT","ts":1786191766576,"type":"delta","data":{"s":"BTCUSDT","b":[["64977.9","1.249813"]],"a":[],"u":184066423,"seq":112464944980},"cts":1786191766567}
{"topic":"orderbook.50.BTCUSDT","ts":1786191766596,"type":"delta","data":{"s":"BTCUSDT","b":[["64977.9","1.249053"]],"a":[],"u":184066424,"seq":112464944981},"cts":1786191766585}
{"topic":"orderbook.50.BTCUSDT","ts":1786191766656,"type":"delta","data":{"s":"BTCUSDT","b":[["64977.9","1.246773"]],"a":[],"u":184066425,"seq":112464944987},"cts":1786191766641}
{"topic":"orderbook.50.BTCUSDT","ts":1786191766756,"type":"delta","data":{"s":"BTCUSDT","b":[["64977.9","1.015796"]],"a":[],"u":184066426,"seq":112464945004},"cts":1786191766753}
{"topic":"orderbook.50.BTCUSDT","ts":1786191766776,"type":"delta","data":{"s":"BTCUSDT","b":[["64977.9","0.870631"]],"a":[],"u":184066427,"seq":112464945012},"cts":1786191766766}
{"topic":"orderbook.50.BTCUSDT","ts":1786191766856,"type":"delta","data":{"s":"BTCUSDT","b":[["64977.9","0.87129"],["64971.3","0.123874"]],"a":[],"u":184066428,"seq":112464945033},"cts":1786191766854}
{"topic":"orderbook.50.BTCUSDT","ts":1786191766876,"type":"delta","data":{"s":"BTCUSDT","b":[["64977.9","0.87616"]],"a":[],"u":184066429,"seq":112464945040},"cts":1786191766866}
{"topic":"orderbook.50.BTCUSDT","ts":1786191766936,"type":"delta","data":{"s":"BTCUSDT","b":[["64977.9","0.87464"]],"a":[],"u":184066430,"seq":112464945058},"cts":1786191766931}
{"topic":"orderbook.50.BTCUSDT","ts":1786191766956,"type":"delta","data":{"s":"BTCUSDT","b":[["64977.9","0.87388"]],"a":[],"u":184066431,"seq":112464945061},"cts":1786191766954}
{"topic":"orderbook.50.BTCUSDT","ts":1786191767018,"type":"delta","data":{"s":"BTCUSDT","b":[["64977.9","0.87616"]],"a":[],"u":184066432,"seq":112464945076},"cts":1786191767014}
{"topic":"orderbook.50.BTCUSDT","ts":1786191767096,"type":"delta","data":{"s":"BTCUSDT","b":[["64977.9","0.87084"]],"a":[],"u":184066433,"seq":112464945092},"cts":1786191767092}
{"topic":"orderbook.50.BTCUSDT","ts":1786191767116,"type":"delta","data":{"s":"BTCUSDT","b":[["64977.9","0.85487"]],"a":[],"u":184066434,"seq":112464945095},"cts":1786191767107}
{"topic":"orderbook.50.BTCUSDT","ts":1786191767176,"type":"delta","data":{"s":"BTCUSDT","b":[["64977.9","0.85717"]],"a":[],"u":184066435,"seq":112464945102},"cts":1786191767173}
{"topic":"orderbook.50.BTCUSDT","ts":1786191767196,"type":"delta","data":{"s":"BTCUSDT","b":[["64977.9","0.86407"]],"a":[],"u":184066436,"seq":112464945105},"cts":1786191767177}
{"topic":"orderbook.50.BTCUSDT","ts":1786191767256,"type":"delta","data":{"s":"BTCUSDT","b":[["64977.9","0.86637"]],"a":[],"u":184066437,"seq":112464945113},"cts":1786191767252}
{"topic":"orderbook.50.BTCUSDT","ts":1786191767276,"type":"delta","data":{"s":"BTCUSDT","b":[["64977.9","0.88477"]],"a":[],"u":184066438,"seq":112464945122},"cts":1786191767272}
{"topic":"orderbook.50.BTCUSDT","ts":1786191767336,"type":"delta","data":{"s":"BTCUSDT","b":[["64977.9","0.87557"],["64965.7","0"],["64964.1","0.099707"]],"a":[],"u":184066439,"seq":112464945137},"cts":1786191767333}
{"topic":"orderbook.50.BTCUSDT","ts":1786191767356,"type":"delta","data":{"s":"BTCUSDT","b":[["64977.9","0.86637"]],"a":[],"u":184066440,"seq":112464945141},"cts":1786191767354}
{"topic":"orderbook.50.BTCUSDT","ts":1786191767376,"type":"delta","data":{"s":"BTCUSDT","b":[["64977.9","0.85487"],["64965.7","0.099706"],["64964.1","0"]],"a":[],"u":184066441,"seq":112464945148},"cts":1786191767374}
{"topic":"orderbook.50.BTCUSDT","ts":1786191767436,"type":"delta","data":{"s":"BTCUSDT","b":[["64977.9","0.85791"]],"a":[],"u":184066442,"seq":112464945165},"cts":1786191767427}
{"topic":"orderbook.50.BTCUSDT","ts":1786191767456,"type":"delta","data":{"s":"BTCUSDT","b":[["64972.2","0"],["64962.5","0.000861"]],"a":[],"u":184066443,"seq":112464945167},"cts":1786191767450}
{"topic":"orderbook.50.BTCUSDT","ts":1786191767476,"type":"delta","data":{"s":"BTCUSDT","b":[["64977.9","0.86475"]],"a":[],"u":184066444,"seq":112464945177},"cts":1786191767473}
{"topic":"orderbook.50.BTCUSDT","ts":1786191767819,"type":"delta","data":{"s":"BTCUSDT","b":[],"a":[["64978.1","0.005641"],["64978.3","0.000093"],["64989.8","0"]],"u":184066445,"seq":112464945206},"cts":1786191767795}
{"topic":"orderbook.50.BTCUSDT","ts":1786191767876,"type":"delta","data":{"s":"BTCUSDT","b":[["64977.9","1.06225"]],"a":[],"u":184066446,"seq":112464945235},"cts":1786191767874}
{"topic":"orderbook.50.BTCUSDT","ts":1786191767916,"type":"delta","data":{"s":"BTCUSDT","b":[["64977.9","0.86475"]],"a":[["64978","20.32124"]],"u":184066447,"seq":112464945246},"cts":1786191767914}
{"topic":"orderbook.50.BTCUSDT","ts":1786191768016,"type":"delta","data":{"s":"BTCUSDT","b":[["64977.9","0"],["64977.4","0.560201"],["64971.4","0.001446"],["64971.3","0.123013"],["64970.9","0.00975"],["64962.5","0"],["64962.3","0.000324"]],"a":[["64977.5","0.727735"],["64977.9","0.0472"],["64978","20.28149"],["64982.7","0.000186"],["64984","0.00975"],["64984.5","0.007799"],["64989.4","0"],["64989.6","0"],["64989.7","0"]],"u":184066448,"seq":112464945362},"cts":1786191768015}
{"topic":"orderbook.50.BTCUSDT","ts":1786191768035,"type":"delta","data":{"s":"BTCUSDT","b":[["64977.4","0.596851"]],"a":[["64977.5","0.750715"],["64978","20.273691"],["64984","0.017549"],["64984.5","0"],["64989.4","0.0025"]],"u":184066449,"seq":112464945387},"cts":1786191768034}
{"topic":"orderbook.50.BTCUSDT","ts":1786191768056,"type":"delta","data":{"s":"BTCUSDT","b":[["64977.4","0.614054"]],"a":[["64977.5","0.766976"]],"u":184066450,"seq":112464945393},"cts":1786191768049}
{"topic":"orderbook.50.BTCUSDT","ts":1786191768076,"type":"delta","data":{"s":"BTCUSDT","b":[["64977.4","0.648188"],["64966.7","0.099705"],["64965.7","0"]],"a":[["64977.5","0.785233"]],"u":184066451,"seq":112464945408},"cts":1786191768074}
{"topic":"orderbook.50.BTCUSDT","ts":1786191768096,"type":"delta","data":{"s":"BTCUSDT","b":[["64966.7","0"],["64966.2","0.099705"]],"a":[["64977.5","0.802509"]],"u":184066452,"seq":112464945420},"cts":1786191768087}
{"topic":"orderbook.50.BTCUSDT","ts":1786191768116,"type":"delta","data":{"s":"BTCUSDT","b":[["64977.4","0.632477"],["64966.2","0"],["64965.7","0.099706"]],"a":[["64977.5","0.82013"]],"u":184066453,"seq":112464945427},"cts":1786191768112}
{"topic":"orderbook.50.BTCUSDT","ts":1786191768136,"type":"delta","data":{"s":"BTCUSDT","b":[["64963.5","0.323309"]],"a":[["64977.5","0.82313"]],"u":184066454,"seq":112464945437},"cts":1786191768134}
{"topic":"orderbook.50.BTCUSDT","ts":1786191768156,"type":"delta","data":{"s":"BTCUSDT","b":[["64963.5","0.07544"]],"a":[],"u":184066455,"seq":112464945443},"cts":1786191768154}
{"topic":"orderbook.50.BTCUSDT","ts":1786191768196,"type":"delta","data":{"s":"BTCUSDT","b":[],"a":[["64982","1.421812"],["64982.7","0.000093"]],"u":184066456,"seq":112464945451},"cts":1786191768186}
{"topic":"orderbook.50.BTCUSDT","ts":1786191768296,"type":"delta","data":{"s":"BTCUSDT","b":[],"a":[["64978","20.273784"],["64978.1","0.005734"],["64978.3","0.000186"]],"u":184066457,"seq":112464945464},"cts":1786191768290}
{"topic":"orderbook.50.BTCUSDT","ts":1786191768376,"type":"delta","data":{"s":"BTCUSDT","b":[["64963.5","0.323309"]],"a":[],"u":184066458,"seq":112464945468},"cts":1786191768355}
{"topic":"orderbook.50.BTCUSDT","ts":1786191768496,"type":"delta","data":{"s":"BTCUSDT","b":[["64977.4","0.654864"]],"a":[],"u":184066459,"seq":112464945478},"cts":1786191768491}
{"topic":"orderbook.50.BTCUSDT","ts":1786191768516,"type":"delta","data":{"s":"BTCUSDT","b":[["64977.4","0.67005"]],"a":[["64977.5","0.825122"]],"u":184066460,"seq":112464945484},"cts":1786191768508}
{"topic":"orderbook.50.BTCUSDT","ts":1786191768536,"type":"delta","data":{"s":"BTCUSDT","b":[["64963.5","0.07544"]],"a":[],"u":184066461,"seq":112464945487},"cts":1786191768534}
{"topic":"orderbook.50.BTCUSDT","ts":1786191768556,"type":"delta","data":{"s":"BTCUSDT","b":[["64966.6","0.312593"],["64965.7","0"],["64962","0.000116"]],"a":[],"u":184066462,"seq":112464945491},"cts":1786191768552}
{"topic":"orderbook.50.BTCUSDT","ts":1786191768575,"type":"delta","data":{"s":"BTCUSDT","b":[["64977.4","0.67235"],["64966.6","0.212888"],["64966.2","0.099705"],["64962","0"]],"a":[],"u":184066463,"seq":112464945495},"cts":1786191768574}
{"topic":"orderbook.50.BTCUSDT","ts":1786191768596,"type":"delta","data":{"s":"BTCUSDT","b":[["64977.4","0.67925"],["64966.2","0"],["64965.7","0.099706"]],"a":[],"u":184066464,"seq":112464945504},"cts":1786191768593}
{"topic":"orderbook.50.BTCUSDT","ts":1786191768618,"type":"delta","data":{"s":"BTCUSDT","b":[["64977.4","0.68155"]],"a":[],"u":184066465,"seq":112464945507},"cts":1786191768615}
{"topic":"orderbook.50.BTCUSDT","ts":1786191768636,"type":"delta","data":{"s":"BTCUSDT","b":[["64963.5","0.323309"]],"a":[],"u":184066466,"seq":112464945512},"cts":1786191768633}
{"topic":"orderbook.50.BTCUSDT","ts":1786191768676,"type":"delta","data":{"s":"BTCUSDT","b":[["64977.4","0.70332"]],"a":[],"u":184066467,"seq":112464945528},"cts":1786191768663}
{"topic":"orderbook.50.BTCUSDT","ts":1786191768736,"type":"delta","data":{"s":"BTCUSDT","b":[["64963.5","0.07544"]],"a":[],"u":184066468,"seq":112464945536},"cts":1786191768718}
{"topic":"orderbook.50.BTCUSDT","ts":1786191769116,"type":"delta","data":{"s":"BTCUSDT","b":[["64977.4","0.563382"]],"a":[],"u":184066469,"seq":112464945581},"cts":1786191769108}
{"topic":"orderbook.50.BTCUSDT","ts":1786191769196,"type":"delta","data":{"s":"BTCUSDT","b":[["64965.7","0"],["64964.1","0.099707"]],"a":[],"u":184066470,"seq":112464945589},"cts":1786191769179}
{"topic":"orderbook.50.BTCUSDT","ts":1786191769216,"type":"delta","data":{"s":"BTCUSDT","b":[["64977.4","0.548196"],["64965.7","0.099706"],["64964.1","0"]],"a":[],"u":184066471,"seq":112464945600},"cts":1786191769215}
{"topic":"orderbook.50.BTCUSDT","ts":1786191769236,"type":"delta","data":{"s":"BTCUSDT","b":[["64965.7","0"],["64964.1","0.099707"]],"a":[],"u":184066472,"seq":112464945612},"cts":1786191769224}
{"topic":"orderbook.50.BTCUSDT","ts":1786191769256,"type":"delta","data":{"s":"BTCUSDT","b":[["64973.6","0"],["64962","0.000116"]],"a":[],"u":184066473,"seq":112464945619},"cts":1786191769252}
{"topic":"orderbook.50.BTCUSDT","ts":1786191769336,"type":"delta","data":{"s":"BTCUSDT","b":[["64963.5","0.323309"]],"a":[],"u":184066474,"seq":112464945638},"cts":1786191769330}
{"topic":"orderbook.50.BTCUSDT","ts":1786191769356,"type":"delta","data":{"s":"BTCUSDT","b":[["64965.7","0.099706"],["64964.1","0"]],"a":[],"u":184066475,"seq":112464945646},"cts":1786191769350}
{"topic":"orderbook.50.BTCUSDT","ts":1786191769376,"type":"delta","data":{"s":"BTCUSDT","b":[["64965.7","0"],["64964.1","0.099707"]],"a":[],"u":184066476,"seq":112464945648},"cts":1786191769366}
{"topic":"orderbook.50.BTCUSDT","ts":1786191769456,"type":"delta","data":{"s":"BTCUSDT","b":[["64965.7","0.099706"],["64964.1","0"]],"a":[],"u":184066477,"seq":112464945665},"cts":1786191769452}
{"topic":"orderbook.50.BTCUSDT","ts":1786191769496,"type":"delta","data":{"s":"BTCUSDT","b":[],"a":[["64977.5","0.891787"]],"u":184066478,"seq":112464945669},"cts":1786191769489}
{"topic":"orderbook.50.BTCUSDT","ts":1786191769516,"type":"delta","data":{"s":"BTCUSDT","b":[["64977.4","0.515843"]],"a":[],"u":184066479,"seq":112464945679},"cts":1786191769510}
{"topic":"orderbook.50.BTCUSDT","ts":1786191769536,"type":"delta","data":{"s":"BTCUSDT","b":[["64977.4","0.51892"],["64977","0"],["64963.5","0.07544"],["64961.9","0.015389"]],"a":[],"u":184066480,"seq":112464945688},"cts":1786191769533}
{"topic":"orderbook.50.BTCUSDT","ts":1786191769556,"type":"delta","data":{"s":"BTCUSDT","b":[["64977.4","0.535482"]],"a":[],"u":184066481,"seq":112464945696},"cts":1786191769553}
{"topic":"orderbook.50.BTCUSDT","ts":1786191769576,"type":"delta","data":{"s":"BTCUSDT","b":[["64977.4","0.550577"]],"a":[],"u":184066482,"seq":112464945698},"cts":1786191769560}
{"topic":"orderbook.50.BTCUSDT","ts":1786191769596,"type":"delta","data":{"s":"BTCUSDT","b":[["64977.4","0.566778"],["64966.7","0.099704"],["64965.7","0"]],"a":[],"u":184066483,"seq":112464945713},"cts":1786191769591}
{"topic":"orderbook.50.BTCUSDT","ts":1786191769636,"type":"delta","data":{"s":"BTCUSDT","b":[["64963.5","0.323309"]],"a":[],"u":184066484,"seq":112464945724},"cts":1786191769629}
{"topic":"orderbook.50.BTCUSDT","ts":1786191769676,"type":"delta","data":{"s":"BTCUSDT","b":[["64966.7","0"],["64966.6","0.312593"],["64961.7","0.004984"]],"a":[["64977.5","0.825122"]],"u":184066485,"seq":112464945734},"cts":1786191769671}
{"topic":"orderbook.50.BTCUSDT","ts":1786191769696,"type":"delta","data":{"s":"BTCUSDT","b":[["64966.6","0.212888"],["64966.2","0.099705"],["64961.7","0"]],"a":[],"u":184066486,"seq":112464945740},"cts":1786191769694}
{"topic":"orderbook.50.BTCUSDT","ts":1786191769716,"type":"delta","data":{"s":"BTCUSDT","b":[],"a":[["64977.5","0.790225"]],"u":184066487,"seq":112464945745},"cts":1786191769711}
{"topic":"orderbook.50.BTCUSDT","ts":1786191769736,"type":"delta","data":{"s":"BTCUSDT","b":[["64963.5","0.07544"]],"a":[["64977.5","0.771968"]],"u":184066488,"seq":112464945751},"cts":1786191769733}
{"topic":"orderbook.50.BTCUSDT","ts":1786191769756,"type":"delta","data":{"s":"BTCUSDT","b":[["64977.4","0.564478"]],"a":[],"u":184066489,"seq":112464945755},"cts":1786191769753}
{"topic":"orderbook.50.BTCUSDT","ts":1786191769776,"type":"delta","data":{"s":"BTCUSDT","b":[["64977.4","0.543778"],["64971.7","0.020131"],["64961.9","0"]],"a":[],"u":184066490,"seq":112464945768},"cts":1786191769769}
{"topic":"orderbook.50.BTCUSDT","ts":1786191769796,"type":"delta","data":{"s":"BTCUSDT","b":[["64977.4","0.534578"]],"a":[],"u":184066491,"seq":112464945774},"cts":1786191769793}
{"topic":"orderbook.50.BTCUSDT","ts":1786191769836,"type":"delta","data":{"s":"BTCUSDT","b":[["64963.5","0.323309"]],"a":[],"u":184066492,"seq":112464945784},"cts":1786191769830}
{"topic":"orderbook.50.BTCUSDT","ts":1786191769856,"type":"delta","data":{"s":"BTCUSDT","b":[["64977.4","0.535338"],["64966.2","0"],["64965.7","0.099706"],["64963.3","0.037943"]],"a":[],"u":184066493,"seq":112464945789},"cts":1786191769851}
{"topic":"orderbook.50.BTCUSDT","ts":1786191769876,"type":"delta","data":{"s":"BTCUSDT","b":[["64977.4","0.542938"]],"a":[["64977.5","0.789165"]],"u":184066494,"seq":112464945802},"cts":1786191769872}
{"topic":"orderbook.50.BTCUSDT","ts":1786191769896,"type":"delta","data":{"s":"BTCUSDT","b":[["64977.4","0.545218"]],"a":[["64977.5","0.805111"]],"u":184066495,"seq":112464945806},"cts":1786191769880}
{"topic":"orderbook.50.BTCUSDT","ts":1786191769916,"type":"delta","data":{"s":"BTCUSDT","b":[["64977.4","0.529017"]],"a":[],"u":184066496,"seq":112464945812},"cts":1786191769913}
{"topic":"orderbook.50.BTCUSDT","ts":1786191769936,"type":"delta","data":{"s":"BTCUSDT","b":[["64977.4","0.525217"],["64963.5","0.07544"]],"a":[],"u":184066497,"seq":112464945820},"cts":1786191769932}
{"topic":"orderbook.50.BTCUSDT","ts":1786191769956,"type":"delta","data":{"s":"BTCUSDT","b":[["64977.4","0.518377"]],"a":[],"u":184066498,"seq":112464945830},"cts":1786191769952}
{"topic":"orderbook.50.BTCUSDT","ts":1786191770016,"type":"delta","data":{"s":"BTCUSDT","b":[["64977.4","0.519137"]],"a":[],"u":184066499,"seq":112464945838},"cts":1786191770014}
{"topic":"orderbook.50.BTCUSDT","ts":1786191770036,"type":"delta","data":{"s":"BTCUSDT","b":[],"a":[["64977.5","0.789165"]],"u":184066500,"seq":112464945842},"cts":1786191770031}
{"topic":"orderbook.50.BTCUSDT","ts":1786191770056,"type":"delta","data":{"s":"BTCUSDT","b":[["64977.4","0.519897"],["64965.8","0.015388"],["64962","0"]],"a":[],"u":184066501,"seq":112464945848},"cts":1786191770051}
{"topic":"orderbook.50.BTCUSDT","ts":1786191770076,"type":"delta","data":{"s":"BTCUSDT","b":[],"a":[["64977.5","0.771968"]],"u":184066502,"seq":112464945850},"cts":1786191770061}
{"topic":"orderbook.50.BTCUSDT","ts":1786191770096,"type":"delta","data":{"s":"BTCUSDT","b":[["64977.4","0.519137"]],"a":[],"u":184066503,"seq":112464945851},"cts":1786191770080}
{"topic":"orderbook.50.BTCUSDT","ts":1786191770117,"type":"delta","data":{"s":"BTCUSDT","b":[["64977.4","0.523697"]],"a":[],"u":184066504,"seq":112464945863},"cts":1786191770115}
{"topic":"orderbook.50.BTCUSDT","ts":1786191770136,"type":"delta","data":{"s":"BTCUSDT","b":[["64977.4","0.524457"],["64965.9","0.099706"],["64965.7","0"]],"a":[],"u":184066505,"seq":112464945870},"cts":1786191770131}
{"topic":"orderbook.50.BTCUSDT","ts":1786191770156,"type":"delta","data":{"s":"BTCUSDT","b":[],"a":[["64977.5","0.772968"],["64984","0.018549"]],"u":184066506,"seq":112464945874},"cts":1786191770151}
{"topic":"orderbook.50.BTCUSDT","ts":1786191770176,"type":"delta","data":{"s":"BTCUSDT","b":[["64977.4","0.526427"]],"a":[["64977.5","0.789279"]],"u":184066507,"seq":112464945881},"cts":1786191770174}
{"topic":"orderbook.50.BTCUSDT","ts":1786191770196,"type":"delta","data":{"s":"BTCUSDT","b":[["64977.4","0.521107"]],"a":[],"u":184066508,"seq":112464945890},"cts":1786191770190}
{"topic":"orderbook.50.BTCUSDT","ts":1786191770236,"type":"delta","data":{"s":"BTCUSDT","b":[["64977.4","0.520347"]],"a":[],"u":184066509,"seq":112464945894},"cts":1786191770232}
{"topic":"orderbook.50.BTCUSDT","ts":1786191770276,"type":"delta","data":{"s":"BTCUSDT","b":[["64977.4","0.528007"]],"a":[],"u":184066510,"seq":112464945908},"cts":1786191770270}
{"topic":"orderbook.50.BTCUSDT","ts":1786191770296,"type":"delta","data":{"s":"BTCUSDT","b":[["64966.7","0.099705"],["64965.9","0"]],"a":[],"u":184066511,"seq":112464945910},"cts":1786191770287}
{"topic":"orderbook.50.BTCUSDT","ts":1786191770317,"type":"delta","data":{"s":"BTCUSDT","b":[["64974.2","0"],["64966.7","0"],["64966.6","0.312593"],["64962","0.000116"],["64961.7","0.004984"]],"a":[],"u":184066512,"seq":112464945916},"cts":1786191770312}
{"topic":"orderbook.50.BTCUSDT","ts":1786191770336,"type":"delta","data":{"s":"BTCUSDT","b":[["64966.6","0.212888"],["64965.7","0.099706"],["64961.7","0"]],"a":[],"u":184066513,"seq":112464945922},"cts":1786191770330}
{"topic":"orderbook.50.BTCUSDT","ts":1786191770356,"type":"delta","data":{"s":"BTCUSDT","b":[["64977.4","0.527247"],["64963.5","0.318974"]],"a":[],"u":184066514,"seq":112464945926},"cts":1786191770354}
{"topic":"orderbook.50.BTCUSDT","ts":1786191770376,"type":"delta","data":{"s":"BTCUSDT","b":[["64977.4","0.521107"]],"a":[],"u":184066515,"seq":112464945940},"cts":1786191770373}
{"topic":"orderbook.50.BTCUSDT","ts":1786191770436,"type":"delta","data":{"s":"BTCUSDT","b":[["64977.4","0.519587"],["64965.9","0.099706"],["64965.7","0"]],"a":[],"u":184066516,"seq":112464945951},"cts":1786191770433}
{"topic":"orderbook.50.BTCUSDT","ts":1786191770456,"type":"delta","data":{"s":"BTCUSDT","b":[["64977.4","0.518067"]],"a":[],"u":184066517,"seq":112464945955},"cts":1786191770451}
{"topic":"orderbook.50.BTCUSDT","ts":1786191770476,"type":"delta","data":{"s":"BTCUSDT","b":[["64973.9","0.254696"],["64962","0"]],"a":[],"u":184066518,"seq":112464945957},"cts":1786191770467}
{"topic":"orderbook.50.BTCUSDT","ts":1786191770556,"type":"delta","data":{"s":"BTCUSDT","b":[["64970.8","0.000861"],["64963.5","0.07544"],["64962.3","0"]],"a":[],"u":184066519,"seq":112464945972},"cts":1786191770554}
{"topic":"orderbook.50.BTCUSDT","ts":1786191770616,"type":"delta","data":{"s":"BTCUSDT","b":[["64977","0.000093"],["64972.9","0.000093"],["64963.4","0"],["64963.3","0"]],"a":[],"u":184066520,"seq":112464945977},"cts":1786191770604}
{"topic":"orderbook.50.BTCUSDT","ts":1786191770716,"type":"delta","data":{"s":"BTCUSDT","b":[["64977.4","0.518928"],["64970.8","0"],["64963.4","0.123013"]],"a":[],"u":184066521,"seq":112464945984},"cts":1786191770713}
{"topic":"orderbook.50.BTCUSDT","ts":1786191770856,"type":"delta","data":{"s":"BTCUSDT","b":[["64966.7","0.099705"],["64965.9","0"]],"a":[],"u":184066522,"seq":112464946004},"cts":1786191770854}
{"topic":"orderbook.50.BTCUSDT","ts":1786191770876,"type":"delta","data":{"s":"BTCUSDT","b":[["64966.7","0"],["64966.2","0.099705"]],"a":[],"u":184066523,"seq":112464946007},"cts":1786191770873}
{"topic":"orderbook.50.BTCUSDT","ts":1786191770896,"type":"delta","data":{"s":"BTCUSDT","b":[["64966.2","0"],["64965.7","0.099706"]],"a":[],"u":184066524,"seq":112464946009},"cts":1786191770881}
{"topic":"orderbook.50.BTCUSDT","ts":1786191770996,"type":"delta","data":{"s":"BTCUSDT","b":[["64977.4","0"],["64977","0"],["64976.6","0"],["64976.2","0"],["64976.1","0"],["64976","0"],["64975.7","0.127389"],["64974.7","0.305555"],["64970.9","0.0065"],["64969.3","0.00325"],["64963.4","0.146456"],["64963.3","0.037082"],["64962.3","0.000324"],["64962","0.000116"],["64961.7","0.004984"],["64960.6","0.164822"]],"a":[["64975.8","1.127601"],["64975.9","0.0472"],["64976","6.54293"],["64977.5","0.196244"],["64977.9","0"],["64982.4","0.00325"],["64983.8","0.001"],["64984","0.014299"],["64988.6","0"],["64989","0"],["64989.2","0"],["64989.4","0"]],"u":184066525,"seq":112464946092},"cts":1786191770995}
{"topic":"orderbook.50.BTCUSDT","ts":1786191771018,"type":"delta","data":{"s":"BTCUSDT","b":[["64975.7","0.446119"],["64975.4","0"],["64973.2","0.002097"],["64970.9","0"],["64970.7","0"],["64970.6","0.0015"],["64969.3","0"],["64969.2","0.00975"],["64965.9","0.099706"],["64965.7","0"],["64961.7","0"],["64960.5","0.617969"],["64960.4","0.507459"],["64959.9","0.036464"]],"a":[["64975.8","1.177892"],["64975.9","0"],["64977.5","0.209575"],["64982.3","0.018549"],["64982.4","0"],["64983.8","0"],["64984","0"],["64988.6","0.018295"],["64988.8","0.006"],["64989","1.143755"]],"u":184066526,"seq":112464946188},"cts":1786191771015}
{"topic":"orderbook.50.BTCUSDT","ts":1786191771036,"type":"delta","data":{"s":"BTCUSDT","b":[["64972.9","0"],["64968.9","0"],["64959.7","0.043444"],["64959.5","0.004984"]],"a":[],"u":184066527,"seq":112464946204},"cts":1786191771030}
{"topic":"orderbook.50.BTCUSDT","ts":1786191771076,"type":"delta","data":{"s":"BTCUSDT","b":[["64965.9","0"],["64965.7","0.099706"]],"a":[],"u":184066528,"seq":112464946216},"cts":1786191771071}
{"topic":"orderbook.50.BTCUSDT","ts":1786191771136,"type":"delta","data":{"s":"BTCUSDT","b":[["64959.9","0"],["64959","0.000324"]],"a":[["64978.1","0.00084"]],"u":184066529,"seq":112464946233},"cts":1786191771131}
{"topic":"orderbook.50.BTCUSDT","ts":1786191771156,"type":"delta","data":{"s":"BTCUSDT","b":[],"a":[["64977.5","0.081375"],["64982.3","0.146749"]],"u":184066530,"seq":112464946235},"cts":1786191771150}
{"topic":"orderbook.50.BTCUSDT","ts":1786191771216,"type":"delta","data":{"s":"BTCUSDT","b":[["64965.7","0"],["64964.1","0.099706"]],"a":[["64979.4","0"],["64989.4","0.0025"]],"u":184066531,"seq":112464946240},"cts":1786191771210}
{"topic":"orderbook.50.BTCUSDT","ts":1786191771276,"type":"delta","data":{"s":"BTCUSDT","b":[],"a":[["64980.7","0"],["64989.6","0.296653"]],"u":184066532,"seq":112464946247},"cts":1786191771274}
{"topic":"orderbook.50.BTCUSDT","ts":1786191771356,"type":"delta","data":{"s":"BTCUSDT","b":[],"a":[["64982","1.419365"]],"u":184066533,"seq":112464946255},"cts":1786191771348}
{"topic":"orderbook.50.BTCUSDT","ts":1786191771436,"type":"delta","data":{"s":"BTCUSDT","b":[],"a":[["64983.3","0"],["64989.7","0.03"]],"u":184066534,"seq":112464946258},"cts":1786191771426}
{"topic":"orderbook.50.BTCUSDT","ts":1786191771456,"type":"delta","data":{"s":"BTCUSDT","b":[],"a":[["64975.8","1.244557"]],"u":184066535,"seq":112464946260},"cts":1786191771440}
{"topic":"orderbook.50.BTCUSDT","ts":1786191771496,"type":"delta","data":{"s":"BTCUSDT","b":[["64975.7","0.468415"]],"a":[],"u":184066536,"seq":112464946262},"cts":1786191771490}
{"topic":"orderbook.50.BTCUSDT","ts":1786191771516,"type":"delta","data":{"s":"BTCUSDT","b":[["64975.7","0.486627"],["64975.3","0"],["64958.4","0.014771"]],"a":[],"u":184066537,"seq":112464946265},"cts":1786191771500}
{"topic":"orderbook.50.BTCUSDT","ts":1786191771536,"type":"delta","data":{"s":"BTCUSDT","b":[["64975.7","0.503349"]],"a":[],"u":184066538,"seq":112464946267},"cts":1786191771520}
{"topic":"orderbook.50.BTCUSDT","ts":1786191771556,"type":"delta","data":{"s":"BTCUSDT","b":[["64975.7","0.518566"]],"a":[],"u":184066539,"seq":112464946269},"cts":1786191771540}
{"topic":"orderbook.50.BTCUSDT","ts":1786191771575,"type":"delta","data":{"s":"BTCUSDT","b":[["64975.7","0.533871"],["64974","0"],["64957.3","0.123013"]],"a":[],"u":184066540,"seq":112464946271},"cts":1786191771574}
{"topic":"orderbook.50.BTCUSDT","ts":1786191771596,"type":"delta","data":{"s":"BTCUSDT","b":[["64975.7","0.612359"],["64974","0.0627"],["64957.3","0"]],"a":[],"u":184066541,"seq":112464946279},"cts":1786191771595}
{"topic":"orderbook.50.BTCUSDT","ts":1786191771636,"type":"delta","data":{"s":"BTCUSDT","b":[["64975.2","0.000417"],["64970.4","0.384632"],["64959.8","0.036377"],["64958.4","0"]],"a":[["64976.2","0.000279"],["64976.9","0.000093"],["64989.6","0"],["64989.7","0"]],"u":184066542,"seq":112464946290},"cts":1786191771633}
{"topic":"orderbook.50.BTCUSDT","ts":1786191771656,"type":"delta","data":{"s":"BTCUSDT","b":[["64972.7","0"],["64958.4","0.014771"]],"a":[],"u":184066543,"seq":112464946292},"cts":1786191771647}
{"topic":"orderbook.50.BTCUSDT","ts":1786191771696,"type":"delta","data":{"s":"BTCUSDT","b":[["64975.7","0.518849"],["64975","0.548101"]],"a":[],"u":184066544,"seq":112464946302},"cts":1786191771692}
{"topic":"orderbook.50.BTCUSDT","ts":1786191771717,"type":"delta","data":{"s":"BTCUSDT","b":[["64975.1","0.482807"],["64974.7","0.006"],["64958.4","0"]],"a":[["64975.8","1.197357"]],"u":184066545,"seq":112464946307},"cts":1786191771715}
{"topic":"orderbook.50.BTCUSDT","ts":1786191771736,"type":"delta","data":{"s":"BTCUSDT","b":[["64975.2","0.548285"],["64975","0.000232"],["64971.4","0"],["64958.4","0.014771"]],"a":[],"u":184066546,"seq":112464946309},"cts":1786191771720}
{"topic":"orderbook.50.BTCUSDT","ts":1786191771756,"type":"delta","data":{"s":"BTCUSDT","b":[["64975.3","0.482931"],["64975.1","0"]],"a":[],"u":184066547,"seq":112464946312},"cts":1786191771741}
{"topic":"orderbook.50.BTCUSDT","ts":1786191771776,"type":"delta","data":{"s":"BTCUSDT","b":[["64975.7","0.521889"],["64975.2","0.000417"]],"a":[],"u":184066548,"seq":112464946317},"cts":1786191771773}
{"topic":"orderbook.50.BTCUSDT","ts":1786191771796,"type":"delta","data":{"s":"BTCUSDT","b":[["64975.3","0.319392"]],"a":[],"u":184066549,"seq":112464946320},"cts":1786191771787}
{"topic":"orderbook.50.BTCUSDT","ts":1786191771818,"type":"delta","data":{"s":"BTCUSDT","b":[["64975.7","0.522649"]],"a":[],"u":184066550,"seq":112464946321},"cts":1786191771799}
{"topic":"orderbook.50.BTCUSDT","ts":1786191771836,"type":"delta","data":{"s":"BTCUSDT","b":[],"a":[["64975.8","1.202284"]],"u":184066551,"seq":112464946323},"cts":1786191771829}
{"topic":"orderbook.50.BTCUSDT","ts":1786191771916,"type":"delta","data":{"s":"BTCUSDT","b":[["64975.7","0.524169"]],"a":[["64977.1","0.004106"],["64989.4","0"]],"u":184066552,"seq":112464946332},"cts":1786191771912}
{"topic":"orderbook.50.BTCUSDT","ts":1786191771936,"type":"delta","data":{"s":"BTCUSDT","b":[["64975.7","0.524929"]],"a":[],"u":184066553,"seq":112464946337},"cts":1786191771927}
{"topic":"orderbook.50.BTCUSDT","ts":1786191771976,"type":"delta","data":{"s":"BTCUSDT","b":[],"a":[["64978.4","0.00347"]],"u":184066554,"seq":112464946339},"cts":1786191771974}
{"topic":"orderbook.50.BTCUSDT","ts":1786191772016,"type":"delta","data":{"s":"BTCUSDT","b":[["64975.7","0.530559"]],"a":[],"u":184066555,"seq":112464946347},"cts":1786191772010}
{"topic":"orderbook.50.BTCUSDT","ts":1786191772056,"type":"delta","data":{"s":"BTCUSDT","b":[],"a":[["64979.7","0.002463"],["64989","0"]],"u":184066556,"seq":112464946351},"cts":1786191772047}
{"topic":"orderbook.50.BTCUSDT","ts":1786191772117,"type":"delta","data":{"s":"BTCUSDT","b":[["64975.2","0.000324"]],"a":[["64975.8","1.135619"],["64980.9","0.0025"],["64981.3","0"],["64982","1.419179"],["64982.7","0"],["64989","1.143755"],["64989.4","0.0025"]],"u":184066557,"seq":112464946366},"cts":1786191772109}
{"topic":"orderbook.50.BTCUSDT","ts":1786191772136,"type":"delta","data":{"s":"BTCUSDT","b":[],"a":[["64981","0.867223"]],"u":184066558,"seq":112464946375},"cts":1786191772130}
{"topic":"orderbook.50.BTCUSDT","ts":1786191772196,"type":"delta","data":{"s":"BTCUSDT","b":[["64974.3","0.004306"],["64958.4","0"]],"a":[],"u":184066559,"seq":112464946390},"cts":1786191772193}
{"topic":"orderbook.50.BTCUSDT","ts":1786191772216,"type":"delta","data":{"s":"BTCUSDT","b":[["64975.7","0.522959"]],"a":[["64975.8","1.151157"],["64977.5","0.0025"]],"u":184066560,"seq":112464946407},"cts":1786191772215}
{"topic":"orderbook.50.BTCUSDT","ts":1786191772236,"type":"delta","data":{"s":"BTCUSDT","b":[["64975.7","0.488826"]],"a":[["64975.8","1.167148"]],"u":184066561,"seq":112464946419},"cts":1786191772225}
{"topic":"orderbook.50.BTCUSDT","ts":1786191772256,"type":"delta","data":{"s":"BTCUSDT","b":[["64975.7","0.473609"]],"a":[["64975.8","1.183836"]],"u":184066562,"seq":112464946422},"cts":1786191772248}
{"topic":"orderbook.50.BTCUSDT","ts":1786191772276,"type":"delta","data":{"s":"BTCUSDT","b":[["64975.7","0.456887"],["64973","0.003589"],["64959","0"]],"a":[["64975.8","1.200218"]],"u":184066563,"seq":112464946429},"cts":1786191772274}
{"topic":"orderbook.50.BTCUSDT","ts":1786191772296,"type":"delta","data":{"s":"BTCUSDT","b":[["64975.7","0.504087"]],"a":[["64975.8","1.217042"]],"u":184066564,"seq":112464946433},"cts":1786191772295}
{"topic":"orderbook.50.BTCUSDT","ts":1786191772316,"type":"delta","data":{"s":"BTCUSDT","b":[["64975.7","0.511687"],["64966.2","0.099705"],["64964.1","0"]],"a":[["64975.8","1.217195"]],"u":184066565,"seq":112464946447},"cts":1786191772311}
{"topic":"orderbook.50.BTCUSDT","ts":1786191772336,"type":"delta","data":{"s":"BTCUSDT","b":[["64975.7","0.512447"],["64966.2","0"],["64964.1","0.099707"]],"a":[],"u":184066566,"seq":112464946452},"cts":1786191772333}
{"topic":"orderbook.50.BTCUSDT","ts":1786191772356,"type":"delta","data":{"s":"BTCUSDT","b":[["64971.7","0.023002"]],"a":[],"u":184066567,"seq":112464946454},"cts":1786191772350}
{"topic":"orderbook.50.BTCUSDT","ts":1786191772376,"type":"delta","data":{"s":"BTCUSDT","b":[["64975.7","0.538536"],["64970.4","0.384539"],["64969.2","0.017549"]],"a":[],"u":184066568,"seq":112464946460},"cts":1786191772372}
{"topic":"orderbook.50.BTCUSDT","ts":1786191772396,"type":"delta","data":{"s":"BTCUSDT","b":[["64975.7","0.546104"]],"a":[["64975.8","1.15131"]],"u":184066569,"seq":112464946477},"cts":1786191772391}
{"topic":"orderbook.50.BTCUSDT","ts":1786191772416,"type":"delta","data":{"s":"BTCUSDT","b":[["64975.7","0.5631"]],"a":[],"u":184066570,"seq":112464946480},"cts":1786191772405}
{"topic":"orderbook.50.BTCUSDT","ts":1786191772436,"type":"delta","data":{"s":"BTCUSDT","b":[["64975.7","0.578444"],["64970.4","0.386692"]],"a":[],"u":184066571,"seq":112464946486},"cts":1786191772431}
{"topic":"orderbook.50.BTCUSDT","ts":1786191772496,"type":"delta","data":{"s":"BTCUSDT","b":[["64969.1","0.001435"],["64959.5","0"]],"a":[],"u":184066572,"seq":112464946491},"cts":1786191772493}
{"topic":"orderbook.50.BTCUSDT","ts":1786191772536,"type":"delta","data":{"s":"BTCUSDT","b":[["64975.7","0.583084"],["64969.2","0.019149"]],"a":[["64975.8","1.15291"],["64982.3","0.148349"]],"u":184066573,"seq":112464946503},"cts":1786191772529}
{"topic":"orderbook.50.BTCUSDT","ts":1786191772576,"type":"delta","data":{"s":"BTCUSDT","b":[["64975.4","0.012109"],["64959.7","0"]],"a":[],"u":184066574,"seq":112464946505},"cts":1786191772565}
{"topic":"orderbook.50.BTCUSDT","ts":1786191772596,"type":"delta","data":{"s":"BTCUSDT","b":[["64975.7","0.680044"]],"a":[],"u":184066575,"seq":112464946511},"cts":1786191772591}
{"topic":"orderbook.50.BTCUSDT","ts":1786191772619,"type":"delta","data":{"s":"BTCUSDT","b":[["64970.4","0.386599"]],"a":[],"u":184066576,"seq":112464946514},"cts":1786191772617}
{"topic":"orderbook.50.BTCUSDT","ts":1786191772656,"type":"delta","data":{"s":"BTCUSDT","b":[["64975.7","0.680804"]],"a":[],"u":184066577,"seq":112464946521},"cts":1786191772655}
{"topic":"orderbook.50.BTCUSDT","ts":1786191772676,"type":"delta","data":{"s":"BTCUSDT","b":[["64975.7","0.688424"]],"a":[],"u":184066578,"seq":112464946531},"cts":1786191772674}
{"topic":"orderbook.50.BTCUSDT","ts":1786191772696,"type":"delta","data":{"s":"BTCUSDT","b":[["64975.7","0.689944"]],"a":[],"u":184066579,"seq":112464946533},"cts":1786191772676}
{"topic":"orderbook.50.BTCUSDT","ts":1786191772736,"type":"delta","data":{"s":"BTCUSDT","b":[["64975.7","0.685364"]],"a":[],"u":184066580,"seq":112464946544},"cts":1786191772731}
{"topic":"orderbook.50.BTCUSDT","ts":1786191772756,"type":"delta","data":{"s":"BTCUSDT","b":[["64975.7","0.680804"]],"a":[["64975.8","1.137372"]],"u":184066581,"seq":112464946553},"cts":1786191772752}
{"topic":"orderbook.50.BTCUSDT","ts":1786191772775,"type":"delta","data":{"s":"BTCUSDT","b":[["64975.7","0.682324"]],"a":[],"u":184066582,"seq":112464946556},"cts":1786191772769}
{"topic":"orderbook.50.BTCUSDT","ts":1786191772796,"type":"delta","data":{"s":"BTCUSDT","b":[],"a":[["64975.8","1.155175"]],"u":184066583,"seq":112464946559},"cts":1786191772779}
{"topic":"orderbook.50.BTCUSDT","ts":1786191772836,"type":"delta","data":{"s":"BTCUSDT","b":[["64975.7","0.683844"]],"a":[],"u":184066584,"seq":112464946567},"cts":1786191772824}
{"topic":"orderbook.50.BTCUSDT","ts":1786191772855,"type":"delta","data":{"s":"BTCUSDT","b":[["64975.7","0.682324"],["64964.2","0.000861"],["64959.8","0"]],"a":[],"u":184066585,"seq":112464946570},"cts":1786191772849}
{"topic":"orderbook.50.BTCUSDT","ts":1786191772876,"type":"delta","data":{"s":"BTCUSDT","b":[],"a":[["64975.8","1.155361"],["64976","6.543209"]],"u":184066586,"seq":112464946578},"cts":1786191772869}
{"topic":"orderbook.50.BTCUSDT","ts":1786191772916,"type":"delta","data":{"s":"BTCUSDT","b":[["64975.7","0.680044"]],"a":[],"u":184066587,"seq":112464946584},"cts":1786191772904}
{"topic":"orderbook.50.BTCUSDT","ts":1786191773016,"type":"delta","data":{"s":"BTCUSDT","b":[["64975.7","0.678974"]],"a":[],"u":184066588,"seq":112464946595},"cts":1786191773006}
{"topic":"orderbook.50.BTCUSDT","ts":1786191773296,"type":"delta","data":{"s":"BTCUSDT","b":[],"a":[["64979.9","0"],["64980.1","0"],["64989.6","0.296653"],["64989.7","0.03"]],"u":184066589,"seq":112464946619},"cts":1786191773279}
{"topic":"orderbook.50.BTCUSDT","ts":1786191773375,"type":"delta","data":{"s":"BTCUSDT","b":[],"a":[["64975.8","1.155454"],["64977.3","0.03387"],["64989.7","0"]],"u":184066590,"seq":112464946627},"cts":1786191773366}
{"topic":"orderbook.50.BTCUSDT","ts":1786191773396,"type":"delta","data":{"s":"BTCUSDT","b":[["64975.7","0.613277"]],"a":[["64975.8","1.172698"]],"u":184066591,"seq":112464946638},"cts":1786191773392}
{"topic":"orderbook.50.BTCUSDT","ts":1786191773418,"type":"delta","data":{"s":"BTCUSDT","b":[],"a":[["64975.8","1.190082"]],"u":184066592,"seq":112464946640},"cts":1786191773412}
{"topic":"orderbook.50.BTCUSDT","ts":1786191773456,"type":"delta","data":{"s":"BTCUSDT","b":[["64974.1","0.0025"],["64960.4","0"]],"a":[["64977.3","0.03637"]],"u":184066593,"seq":112464946644},"cts":1786191773447}
{"topic":"orderbook.50.BTCUSDT","ts":1786191773476,"type":"delta","data":{"s":"BTCUSDT","b":[["64975.7","0.616317"]],"a":[["64975.8","1.207619"]],"u":184066594,"seq":112464946650},"cts":1786191773475}
{"topic":"orderbook.50.BTCUSDT","ts":1786191773496,"type":"delta","data":{"s":"BTCUSDT","b":[["64975.7","2.152275"]],"a":[["64975.8","1.190082"]],"u":184066595,"seq":112464946654},"cts":1786191773493}
{"topic":"orderbook.50.BTCUSDT","ts":1786191773576,"type":"delta","data":{"s":"BTCUSDT","b":[["64975.7","2.157595"]],"a":[],"u":184066596,"seq":112464946679},"cts":1786191773569}
{"topic":"orderbook.50.BTCUSDT","ts":1786191773596,"type":"delta","data":{"s":"BTCUSDT","b":[],"a":[["64975.8","1.155454"]],"u":184066597,"seq":112464946681},"cts":1786191773580}
{"topic":"orderbook.50.BTCUSDT","ts":1786191773636,"type":"delta","data":{"s":"BTCUSDT","b":[["64975.7","2.153795"]],"a":[],"u":184066598,"seq":112464946689},"cts":1786191773634}
{"topic":"orderbook.50.BTCUSDT","ts":1786191773676,"type":"delta","data":{"s":"BTCUSDT","b":[["64975.7","2.160695"]],"a":[],"u":184066599,"seq":112464946696},"cts":1786191773674}
{"topic":"orderbook.50.BTCUSDT","ts":1786191773736,"type":"delta","data":{"s":"BTCUSDT","b":[["64975.7","2.162995"]],"a":[],"u":184066600,"seq":112464946704},"cts":1786191773725}
{"topic":"orderbook.50.BTCUSDT","ts":1786191773756,"type":"delta","data":{"s":"BTCUSDT","b":[],"a":[["64975.8","1.137651"]],"u":184066601,"seq":112464946708},"cts":1786191773749}
{"topic":"orderbook.50.BTCUSDT","ts":1786191773776,"type":"delta","data":{"s":"BTCUSDT","b":[["64975.7","2.170655"]],"a":[],"u":184066602,"seq":112464946713},"cts":1786191773772}
{"topic":"orderbook.50.BTCUSDT","ts":1786191773836,"type":"delta","data":{"s":"BTCUSDT","b":[["64975.7","2.169895"]],"a":[],"u":184066603,"seq":112464946718},"cts":1786191773829}
{"topic":"orderbook.50.BTCUSDT","ts":1786191773976,"type":"delta","data":{"s":"BTCUSDT","b":[["64975.7","2.158415"],["64971","0.000093"],["64960.5","0"]],"a":[],"u":184066604,"seq":112464946741},"cts":1786191773975}
{"topic":"orderbook.50.BTCUSDT","ts":1786191774016,"type":"delta","data":{"s":"BTCUSDT","b":[["64975.7","2.149235"]],"a":[],"u":184066605,"seq":112464946750},"cts":1786191774011}
{"topic":"orderbook.50.BTCUSDT","ts":1786191774056,"type":"delta","data":{"s":"BTCUSDT","b":[["64975.7","2.149995"],["64966.2","0.099706"],["64964.1","0"]],"a":[],"u":184066606,"seq":112464946760},"cts":1786191774049}
{"topic":"orderbook.50.BTCUSDT","ts":1786191774076,"type":"delta","data":{"s":"BTCUSDT","b":[["64975.7","2.153035"],["64966.2","0"],["64964.1","0.099707"]],"a":[],"u":184066607,"seq":112464946766},"cts":1786191774070}
{"topic":"orderbook.50.BTCUSDT","ts":1786191774136,"type":"delta","data":{"s":"BTCUSDT","b":[["64975.7","2.152275"]],"a":[],"u":184066608,"seq":112464946775},"cts":1786191774132}
{"topic":"orderbook.50.BTCUSDT","ts":1786191774156,"type":"delta","data":{"s":"BTCUSDT","b":[["64975.7","2.149235"]],"a":[],"u":184066609,"seq":112464946780},"cts":1786191774155}
{"topic":"orderbook.50.BTCUSDT","ts":1786191774236,"type":"delta","data":{"s":"BTCUSDT","b":[["64975.7","2.154765"],["64969.2","0.022399"]],"a":[["64975.8","1.140901"],["64982.3","0.151599"]],"u":184066610,"seq":112464946800},"cts":1786191774227}
{"topic":"orderbook.50.BTCUSDT","ts":1786191774256,"type":"delta","data":{"s":"BTCUSDT","b":[["64972","0.000324"]],"a":[],"u":184066611,"seq":112464946806},"cts":1786191774251}
{"topic":"orderbook.50.BTCUSDT","ts":1786191774316,"type":"delta","data":{"s":"BTCUSDT","b":[["64975.7","2.161155"]],"a":[],"u":184066612,"seq":112464946834},"cts":1786191774314}
{"topic":"orderbook.50.BTCUSDT","ts":1786191774396,"type":"delta","data":{"s":"BTCUSDT","b":[["64975.7","2.153555"]],"a":[],"u":184066613,"seq":112464946854},"cts":1786191774392}
{"topic":"orderbook.50.BTCUSDT","ts":1786191774476,"type":"delta","data":{"s":"BTCUSDT","b":[["64975.7","2.157355"]],"a":[],"u":184066614,"seq":112464946867},"cts":1786191774474}
{"topic":"orderbook.50.BTCUSDT","ts":1786191774495,"type":"delta","data":{"s":"BTCUSDT","b":[["64975.7","2.158875"]],"a":[],"u":184066615,"seq":112464946870},"cts":1786191774483}
{"topic":"orderbook.50.BTCUSDT","ts":1786191774556,"type":"delta","data":{"s":"BTCUSDT","b":[["64975.7","2.157355"],["64966.2","0.099706"],["64964.1","0"]],"a":[],"u":184066616,"seq":112464946887},"cts":1786191774554}
{"topic":"orderbook.50.BTCUSDT","ts":1786191774576,"type":"delta","data":{"s":"BTCUSDT","b":[["64975.7","2.158875"]],"a":[],"u":184066617,"seq":112464946889},"cts":1786191774558}
{"topic":"orderbook.50.BTCUSDT","ts":1786191774596,"type":"delta","data":{"s":"BTCUSDT","b":[["64971","0"],["64966.2","0"],["64964.1","0.099707"],["64960.5","0.617969"]],"a":[],"u":184066618,"seq":112464946895},"cts":1786191774593}
{"topic":"orderbook.50.BTCUSDT","ts":1786191774617,"type":"delta","data":{"s":"BTCUSDT","b":[],"a":[["64975.8","1.158427"]],"u":184066619,"seq":112464946896},"cts":1786191774600}
{"topic":"orderbook.50.BTCUSDT","ts":1786191774636,"type":"delta","data":{"s":"BTCUSDT","b":[["64975.7","2.154315"]],"a":[],"u":184066620,"seq":112464946903},"cts":1786191774632}
{"topic":"orderbook.50.BTCUSDT","ts":1786191774656,"type":"delta","data":{"s":"BTCUSDT","b":[["64975.7","2.153555"]],"a":[],"u":184066621,"seq":112464946904},"cts":1786191774640}
{"topic":"orderbook.50.BTCUSDT","ts":1786191774716,"type":"delta","data":{"s":"BTCUSDT","b":[["64966.2","0.099706"],["64964.1","0"]],"a":[],"u":184066622,"seq":112464946913},"cts":1786191774715}
{"topic":"orderbook.50.BTCUSDT","ts":1786191774736,"type":"delta","data":{"s":"BTCUSDT","b":[["64975.7","2.156595"],["64966.2","0"],["64965.9","0.099706"]],"a":[],"u":184066623,"seq":112464946922},"cts":1786191774732}
{"topic":"orderbook.50.BTCUSDT","ts":1786191774756,"type":"delta","data":{"s":"BTCUSDT","b":[["64965.9","0"],["64964.1","0.099707"]],"a":[["64975.8","1.140901"]],"u":184066624,"seq":112464946926},"cts":1786191774744}
{"topic":"orderbook.50.BTCUSDT","ts":1786191774776,"type":"delta","data":{"s":"BTCUSDT","b":[["64969.7","0.099124"]],"a":[],"u":184066625,"seq":112464946927},"cts":1786191774767}
{"topic":"orderbook.50.BTCUSDT","ts":1786191774816,"type":"delta","data":{"s":"BTCUSDT","b":[["64975.7","2.158875"]],"a":[],"u":184066626,"seq":112464946941},"cts":1786191774808}
{"topic":"orderbook.50.BTCUSDT","ts":1786191774896,"type":"delta","data":{"s":"BTCUSDT","b":[["64975.7","2.153555"]],"a":[],"u":184066627,"seq":112464946952},"cts":1786191774889}
{"topic":"orderbook.50.BTCUSDT","ts":1786191774976,"type":"delta","data":{"s":"BTCUSDT","b":[["64975.7","2.158115"]],"a":[],"u":184066628,"seq":112464946977},"cts":1786191774974}
{"topic":"orderbook.50.BTCUSDT","ts":1786191774996,"type":"delta","data":{"s":"BTCUSDT","b":[["64975.7","2.158875"]],"a":[["64975.8","1.157287"]],"u":184066629,"seq":112464946980},"cts":1786191774990}
{"topic":"orderbook.50.BTCUSDT","ts":1786191775018,"type":"delta","data":{"s":"BTCUSDT","b":[],"a":[["64975.8","1.172503"]],"u":184066630,"seq":112464946983},"cts":1786191775000}
{"topic":"orderbook.50.BTCUSDT","ts":1786191775055,"type":"delta","data":{"s":"BTCUSDT","b":[["64975.7","2.154315"]],"a":[],"u":184066631,"seq":112464946994},"cts":1786191775051}
{"topic":"orderbook.50.BTCUSDT","ts":1786191775076,"type":"delta","data":{"s":"BTCUSDT","b":[["64975.7","2.158875"]],"a":[],"u":184066632,"seq":112464947000},"cts":1786191775058}
{"topic":"orderbook.50.BTCUSDT","ts":1786191775136,"type":"delta","data":{"s":"BTCUSDT","b":[["64975.7","2.153555"]],"a":[],"u":184066633,"seq":112464947011},"cts":1786191775132}
{"topic":"orderbook.50.BTCUSDT","ts":1786191775155,"type":"delta","data":{"s":"BTCUSDT","b":[],"a":[["64975.8","1.157287"]],"u":184066634,"seq":112464947015},"cts":1786191775149}
{"topic":"orderbook.50.BTCUSDT","ts":1786191775256,"type":"delta","data":{"s":"BTCUSDT","b":[],"a":[["64978.1","0.000279"]],"u":184066635,"seq":112464947027},"cts":1786191775254}
{"topic":"orderbook.50.BTCUSDT","ts":1786191775276,"type":"delta","data":{"s":"BTCUSDT","b":[],"a":[["64975.8","1.174237"]],"u":184066636,"seq":112464947029},"cts":1786191775260}
{"topic":"orderbook.50.BTCUSDT","ts":1786191775296,"type":"delta","data":{"s":"BTCUSDT","b":[],"a":[["64975.8","1.191884"]],"u":184066637,"seq":112464947030},"cts":1786191775280}
{"topic":"orderbook.50.BTCUSDT","ts":1786191775316,"type":"delta","data":{"s":"BTCUSDT","b":[],"a":[["64975.8","1.206972"]],"u":184066638,"seq":112464947036},"cts":1786191775310}
{"topic":"orderbook.50.BTCUSDT","ts":1786191775336,"type":"delta","data":{"s":"BTCUSDT","b":[],"a":[["64975.8","1.224514"],["64975.9","0.000561"],["64989.6","0"]],"u":184066639,"seq":112464947039},"cts":1786191775329}
{"topic":"orderbook.50.BTCUSDT","ts":1786191775356,"type":"delta","data":{"s":"BTCUSDT","b":[["64975.7","2.155835"]],"a":[],"u":184066640,"seq":112464947045},"cts":1786191775354}
{"topic":"orderbook.50.BTCUSDT","ts":1786191775376,"type":"delta","data":{"s":"BTCUSDT","b":[["64975.7","2.164195"]],"a":[],"u":184066641,"seq":112464947056},"cts":1786191775375}
{"topic":"orderbook.50.BTCUSDT","ts":1786191775436,"type":"delta","data":{"s":"BTCUSDT","b":[["64975.7","2.160395"]],"a":[],"u":184066642,"seq":112464947067},"cts":1786191775431}
{"topic":"orderbook.50.BTCUSDT","ts":1786191775456,"type":"delta","data":{"s":"BTCUSDT","b":[["64975.7","2.153555"]],"a":[],"u":184066643,"seq":112464947079},"cts":1786191775452}
{"topic":"orderbook.50.BTCUSDT","ts":1786191775536,"type":"delta","data":{"s":"BTCUSDT","b":[["64975.7","2.155835"]],"a":[],"u":184066644,"seq":112464947084},"cts":1786191775529}
{"topic":"orderbook.50.BTCUSDT","ts":1786191775556,"type":"delta","data":{"s":"BTCUSDT","b":[],"a":[["64975.8","1.174237"]],"u":184066645,"seq":112464947090},"cts":1786191775546}
{"topic":"orderbook.50.BTCUSDT","ts":1786191775595,"type":"delta","data":{"s":"BTCUSDT","b":[],"a":[["64975.9","0"],["64989.6","0.296653"]],"u":184066646,"seq":112464947091},"cts":1786191775577}
{"topic":"orderbook.50.BTCUSDT","ts":1786191775616,"type":"delta","data":{"s":"BTCUSDT","b":[["64975.7","2.159635"]],"a":[],"u":184066647,"seq":112464947108},"cts":1786191775615}
{"topic":"orderbook.50.BTCUSDT","ts":1786191775636,"type":"delta","data":{"s":"BTCUSDT","b":[["64975.7","2.161915"]],"a":[],"u":184066648,"seq":112464947111},"cts":1786191775620}
{"topic":"orderbook.50.BTCUSDT","ts":1786191775676,"type":"delta","data":{"s":"BTCUSDT","b":[],"a":[["64975.9","0.000561"],["64989.6","0"]],"u":184066649,"seq":112464947115},"cts":1786191775662}
{"topic":"orderbook.50.BTCUSDT","ts":1786191775696,"type":"delta","data":{"s":"BTCUSDT","b":[["64975.7","2.153555"]],"a":[],"u":184066650,"seq":112464947126},"cts":1786191775692}
{"topic":"orderbook.50.BTCUSDT","ts":1786191775917,"type":"delta","data":{"s":"BTCUSDT","b":[["64966.6","0.210481"]],"a":[],"u":184066651,"seq":112464947143},"cts":1786191775904}
{"topic":"orderbook.50.BTCUSDT","ts":1786191776376,"type":"delta","data":{"s":"BTCUSDT","b":[["64965.9","0.099706"],["64964.1","0"]],"a":[],"u":184066652,"seq":112464947181},"cts":1786191776368}
{"topic":"orderbook.50.BTCUSDT","ts":1786191776396,"type":"delta","data":{"s":"BTCUSDT","b":[["64965.9","0"],["64964.1","0.099707"]],"a":[],"u":184066653,"seq":112464947186},"cts":1786191776392}
{"topic":"orderbook.50.BTCUSDT","ts":1786191776436,"type":"delta","data":{"s":"BTCUSDT","b":[["64964.2","0.100568"],["64964.1","0"],["64960.4","0.507459"]],"a":[],"u":184066654,"seq":112464947188},"cts":1786191776430}
{"topic":"orderbook.50.BTCUSDT","ts":1786191776456,"type":"delta","data":{"s":"BTCUSDT","b":[["64964.2","0.000861"],["64964.1","0.099707"],["64960.4","0"]],"a":[],"u":184066655,"seq":112464947191},"cts":1786191776453}
{"topic":"orderbook.50.BTCUSDT","ts":1786191777335,"type":"delta","data":{"s":"BTCUSDT","b":[],"a":[["64975.8","1.140901"]],"u":184066656,"seq":112464947241},"cts":1786191777332}
{"topic":"orderbook.50.BTCUSDT","ts":1786191777418,"type":"delta","data":{"s":"BTCUSDT","b":[["64975.7","2.158875"]],"a":[],"u":184066657,"seq":112464947261},"cts":1786191777417}
{"topic":"orderbook.50.BTCUSDT","ts":1786191777436,"type":"delta","data":{"s":"BTCUSDT","b":[["64975.7","2.160395"]],"a":[],"u":184066658,"seq":112464947267},"cts":1786191777430}
{"topic":"orderbook.50.BTCUSDT","ts":1786191777496,"type":"delta","data":{"s":"BTCUSDT","b":[["64975.7","2.154315"]],"a":[],"u":184066659,"seq":112464947283},"cts":1786191777491}
{"topic":"orderbook.50.BTCUSDT","ts":1786191777516,"type":"delta","data":{"s":"BTCUSDT","b":[["64975.7","2.169315"]],"a":[],"u":184066660,"seq":112464947286},"cts":1786191777502}
{"topic":"orderbook.50.BTCUSDT","ts":1786191777536,"type":"delta","data":{"s":"BTCUSDT","b":[["64975.7","2.170075"]],"a":[],"u":184066661,"seq":112464947291},"cts":1786191777529}
{"topic":"orderbook.50.BTCUSDT","ts":1786191777615,"type":"delta","data":{"s":"BTCUSDT","b":[["64975.7","2.168555"]],"a":[["64979.5","0"],["64989.6","0.296653"]],"u":184066662,"seq":112464947297},"cts":1786191777614}
{"topic":"orderbook.50.BTCUSDT","ts":1786191778016,"type":"delta","data":{"s":"BTCUSDT","b":[["64973.9","0"],["64965.6","0"],["64960.4","0.507459"],["64959.8","0.036377"]],"a":[],"u":184066663,"seq":112464947323},"cts":1786191777998}
{"topic":"orderbook.50.BTCUSDT","ts":1786191778176,"type":"delta","data":{"s":"BTCUSDT","b":[["64975.7","2.159555"],["64969.2","0.019149"],["64967.7","0.199856"],["64959.8","0"]],"a":[["64975.8","1.158846"]],"u":184066664,"seq":112464947342},"cts":1786191778174}
{"topic":"orderbook.50.BTCUSDT","ts":1786191778196,"type":"delta","data":{"s":"BTCUSDT","b":[["64970.1","0.145454"]],"a":[["64975.8","1.176762"]],"u":184066665,"seq":112464947347},"cts":1786191778188}
{"topic":"orderbook.50.BTCUSDT","ts":1786191778219,"type":"delta","data":{"s":"BTCUSDT","b":[],"a":[["64975.8","1.194285"]],"u":184066666,"seq":112464947348},"cts":1786191778200}
{"topic":"orderbook.50.BTCUSDT","ts":1786191778236,"type":"delta","data":{"s":"BTCUSDT","b":[],"a":[["64975.8","1.212361"]],"u":184066667,"seq":112464947351},"cts":1786191778225}
{"topic":"orderbook.50.BTCUSDT","ts":1786191778256,"type":"delta","data":{"s":"BTCUSDT","b":[["64975.7","2.161075"],["64973.8","0.284636"],["64960.4","0"]],"a":[["64975.8","1.230359"]],"u":184066668,"seq":112464947356},"cts":1786191778255}
{"topic":"orderbook.50.BTCUSDT","ts":1786191778276,"type":"delta","data":{"s":"BTCUSDT","b":[["64975.7","2.167155"]],"a":[],"u":184066669,"seq":112464947364},"cts":1786191778267}
{"topic":"orderbook.50.BTCUSDT","ts":1786191778356,"type":"delta","data":{"s":"BTCUSDT","b":[["64975.7","2.162595"]],"a":[],"u":184066670,"seq":112464947386},"cts":1786191778342}
{"topic":"orderbook.50.BTCUSDT","ts":1786191778436,"type":"delta","data":{"s":"BTCUSDT","b":[["64975.7","2.164875"]],"a":[],"u":184066671,"seq":112464947409},"cts":1786191778430}
{"topic":"orderbook.50.BTCUSDT","ts":1786191778496,"type":"delta","data":{"s":"BTCUSDT","b":[["64975.7","2.160315"]],"a":[],"u":184066672,"seq":112464947421},"cts":1786191778490}
{"topic":"orderbook.50.BTCUSDT","ts":1786191778516,"type":"delta","data":{"s":"BTCUSDT","b":[],"a":[["64975.8","1.212361"]],"u":184066673,"seq":112464947427},"cts":1786191778503}
{"topic":"orderbook.50.BTCUSDT","ts":1786191778576,"type":"delta","data":{"s":"BTCUSDT","b":[["64975.7","2.163355"]],"a":[],"u":184066674,"seq":112464947437},"cts":1786191778574}
{"topic":"orderbook.50.BTCUSDT","ts":1786191778596,"type":"delta","data":{"s":"BTCUSDT","b":[["64975.7","2.164875"]],"a":[["64975.8","1.176762"]],"u":184066675,"seq":112464947444},"cts":1786191778591}
{"topic":"orderbook.50.BTCUSDT","ts":1786191778616,"type":"delta","data":{"s":"BTCUSDT","b":[["64975.7","2.362375"]],"a":[],"u":184066676,"seq":112464947461},"cts":1786191778614}
{"topic":"orderbook.50.BTCUSDT","ts":1786191778636,"type":"delta","data":{"s":"BTCUSDT","b":[],"a":[["64975.8","1.140901"]],"u":184066677,"seq":112464947469},"cts":1786191778633}
{"topic":"orderbook.50.BTCUSDT","ts":1786191778656,"type":"delta","data":{"s":"BTCUSDT","b":[["64975.7","2.358575"]],"a":[],"u":184066678,"seq":112464947483},"cts":1786191778655}
{"topic":"orderbook.50.BTCUSDT","ts":1786191778676,"type":"delta","data":{"s":"BTCUSDT","b":[["64975.7","2.362375"]],"a":[],"u":184066679,"seq":112464947488},"cts":1786191778661}
{"topic":"orderbook.50.BTCUSDT","ts":1786191778736,"type":"delta","data":{"s":"BTCUSDT","b":[["64975.7","2.364655"]],"a":[],"u":184066680,"seq":112464947503},"cts":1786191778732}
{"topic":"orderbook.50.BTCUSDT","ts":1786191778756,"type":"delta","data":{"s":"BTCUSDT","b":[["64975.7","2.360095"]],"a":[],"u":184066681,"seq":112464947510},"cts":1786191778748}
{"topic":"orderbook.50.BTCUSDT","ts":1786191778776,"type":"delta","data":{"s":"BTCUSDT","b":[["64966.2","0.099705"],["64964.1","0"]],"a":[],"u":184066682,"seq":112464947513},"cts":1786191778774}
{"topic":"orderbook.50.BTCUSDT","ts":1786191778795,"type":"delta","data":{"s":"BTCUSDT","b":[["64966.2","0"],["64964.1","0.099707"]],"a":[],"u":184066683,"seq":112464947518},"cts":1786191778781}
{"topic":"orderbook.50.BTCUSDT","ts":1786191778816,"type":"delta","data":{"s":"BTCUSDT","b":[["64975.7","2.357055"]],"a":[],"u":184066684,"seq":112464947523},"cts":1786191778801}
{"topic":"orderbook.50.BTCUSDT","ts":1786191778836,"type":"delta","data":{"s":"BTCUSDT","b":[["64964.2","0.100568"],["64964.1","0"],["64960.4","0.507459"]],"a":[],"u":184066685,"seq":112464947524},"cts":1786191778832}
{"topic":"orderbook.50.BTCUSDT","ts":1786191778857,"type":"delta","data":{"s":"BTCUSDT","b":[["64964.2","0.000861"],["64964.1","0.099707"],["64960.4","0"]],"a":[],"u":184066686,"seq":112464947526},"cts":1786191778850}
{"topic":"orderbook.50.BTCUSDT","ts":1786191778996,"type":"delta","data":{"s":"BTCUSDT","b":[["64964.2","0.100568"],["64964.1","0"],["64960.4","0.507459"]],"a":[],"u":184066687,"seq":112464947540},"cts":1786191778993}
{"topic":"orderbook.50.BTCUSDT","ts":1786191779019,"type":"delta","data":{"s":"BTCUSDT","b":[["64964.2","0.000861"],["64964.1","0.099707"],["64960.4","0"]],"a":[],"u":184066688,"seq":112464947544},"cts":1786191779013}
{"topic":"orderbook.50.BTCUSDT","ts":1786191779076,"type":"delta","data":{"s":"BTCUSDT","b":[["64964.3","0.099707"],["64964.1","0"]],"a":[],"u":184066689,"seq":112464947547},"cts":1786191779073}
{"topic":"orderbook.50.BTCUSDT","ts":1786191779116,"type":"delta","data":{"s":"BTCUSDT","b":[["64964.3","0"],["64964.1","0.099707"]],"a":[],"u":184066690,"seq":112464947551},"cts":1786191779099}
{"topic":"orderbook.50.BTCUSDT","ts":1786191779156,"type":"delta","data":{"s":"BTCUSDT","b":[["64975.7","2.356599"]],"a":[["64975.8","1.158397"]],"u":184066691,"seq":112464947558},"cts":1786191779155}
{"topic":"orderbook.50.BTCUSDT","ts":1786191779176,"type":"delta","data":{"s":"BTCUSDT","b":[["64964.4","0.099707"],["64964.1","0"]],"a":[["64975.8","1.176607"]],"u":184066692,"seq":112464947560},"cts":1786191779167}
{"topic":"orderbook.50.BTCUSDT","ts":1786191779196,"type":"delta","data":{"s":"BTCUSDT","b":[["64964.4","0"],["64964.1","0.099707"]],"a":[["64975.8","1.192093"]],"u":184066693,"seq":112464947562},"cts":1786191779189}
{"topic":"orderbook.50.BTCUSDT","ts":1786191779216,"type":"delta","data":{"s":"BTCUSDT","b":[],"a":[["64975.8","1.208915"]],"u":184066694,"seq":112464947564},"cts":1786191779201}
{"topic":"orderbook.50.BTCUSDT","ts":1786191779236,"type":"delta","data":{"s":"BTCUSDT","b":[],"a":[["64975.8","1.226064"]],"u":184066695,"seq":112464947569},"cts":1786191779232}
{"topic":"orderbook.50.BTCUSDT","ts":1786191779256,"type":"delta","data":{"s":"BTCUSDT","b":[["64975.7","2.357359"],["64970.7","0.0015"],["64970.6","0"],["64964.1","0.099708"]],"a":[],"u":184066696,"seq":112464947578},"cts":1786191779253}
{"topic":"orderbook.50.BTCUSDT","ts":1786191779276,"type":"delta","data":{"s":"BTCUSDT","b":[["64975.7","2.365719"],["64964.1","0.099707"]],"a":[],"u":184066697,"seq":112464947593},"cts":1786191779275}
{"topic":"orderbook.50.BTCUSDT","ts":1786191779296,"type":"delta","data":{"s":"BTCUSDT","b":[["64975.7","2.367239"]],"a":[],"u":184066698,"seq":112464947599},"cts":1786191779286}
{"topic":"orderbook.50.BTCUSDT","ts":1786191779316,"type":"delta","data":{"s":"BTCUSDT","b":[],"a":[["64975.8","1.192093"]],"u":184066699,"seq":112464947602},"cts":1786191779302}
{"topic":"orderbook.50.BTCUSDT","ts":1786191779336,"type":"delta","data":{"s":"BTCUSDT","b":[["64975.7","2.364199"]],"a":[],"u":184066700,"seq":112464947609},"cts":1786191779333}
{"topic":"orderbook.50.BTCUSDT","ts":1786191779355,"type":"delta","data":{"s":"BTCUSDT","b":[["64975.7","2.356599"]],"a":[],"u":184066701,"seq":112464947630},"cts":1786191779352}
{"topic":"orderbook.50.BTCUSDT","ts":1786191779856,"type":"delta","data":{"s":"BTCUSDT","b":[["64963.7","0"],["64960.4","0.507459"]],"a":[],"u":184066702,"seq":112464947687},"cts":1786191779853}
{"topic":"orderbook.50.BTCUSDT","ts":1786191779876,"type":"delta","data":{"s":"BTCUSDT","b":[],"a":[["64975.8","1.209245"]],"u":184066703,"seq":112464947693},"cts":1786191779873}
{"topic":"orderbook.50.BTCUSDT","ts":1786191779895,"type":"delta","data":{"s":"BTCUSDT","b":[],"a":[["64975.8","1.227307"]],"u":184066704,"seq":112464947703},"cts":1786191779893}
{"topic":"orderbook.50.BTCUSDT","ts":1786191779976,"type":"delta","data":{"s":"BTCUSDT","b":[["64963.7","0.000762"],["64960.4","0"]],"a":[],"u":184066705,"seq":112464947718},"cts":1786191779974}
{"topic":"orderbook.50.BTCUSDT","ts":1786191780076,"type":"delta","data":{"s":"BTCUSDT","b":[["64965.9","0.099706"],["64964.1","0"]],"a":[],"u":184066706,"seq":112464947727},"cts":1786191780074}
{"topic":"orderbook.50.BTCUSDT","ts":1786191780096,"type":"delta","data":{"s":"BTCUSDT","b":[["64975.7","2.338387"]],"a":[["64975.8","1.209245"]],"u":184066707,"seq":112464947729},"cts":1786191780080}
{"topic":"orderbook.50.BTCUSDT","ts":1786191780116,"type":"delta","data":{"s":"BTCUSDT","b":[["64965.9","0"],["64964.1","0.099707"]],"a":[["64975.8","1.192093"]],"u":184066708,"seq":112464947731},"cts":1786191780103}
{"topic":"orderbook.50.BTCUSDT","ts":1786191780176,"type":"delta","data":{"s":"BTCUSDT","b":[["64975.7","2.339387"]],"a":[["64975.8","1.176607"]],"u":184066709,"seq":112464947740},"cts":1786191780171}
{"topic":"orderbook.50.BTCUSDT","ts":1786191780196,"type":"delta","data":{"s":"BTCUSDT","b":[["64975.7","2.338387"]],"a":[["64975.8","1.140901"]],"u":184066710,"seq":112464947745},"cts":1786191780193}
{"topic":"orderbook.50.BTCUSDT","ts":1786191780216,"type":"delta","data":{"s":"BTCUSDT","b":[["64965.9","0.099706"],["64964.1","0"]],"a":[],"u":184066711,"seq":112464947746},"cts":1786191780199}
{"topic":"orderbook.50.BTCUSDT","ts":1786191780236,"type":"delta","data":{"s":"BTCUSDT","b":[["64965.9","0"],["64964.1","0.099707"]],"a":[],"u":184066712,"seq":112464947748},"cts":1786191780228}
{"topic":"orderbook.50.BTCUSDT","ts":1786191780256,"type":"delta","data":{"s":"BTCUSDT","b":[["64975.7","2.339147"]],"a":[],"u":184066713,"seq":112464947751},"cts":1786191780250}
{"topic":"orderbook.50.BTCUSDT","ts":1786191780276,"type":"delta","data":{"s":"BTCUSDT","b":[["64975.7","2.349027"],["64964.2","0.100568"],["64964.1","0"],["64960.4","0.507459"]],"a":[],"u":184066714,"seq":112464947766},"cts":1786191780274}
{"topic":"orderbook.50.BTCUSDT","ts":1786191780296,"type":"delta","data":{"s":"BTCUSDT","b":[["64964.2","0.000861"],["64964.1","0.099707"],["64960.4","0"]],"a":[],"u":184066715,"seq":112464947776},"cts":1786191780294}
{"topic":"orderbook.50.BTCUSDT","ts":1786191780316,"type":"delta","data":{"s":"BTCUSDT","b":[["64975.9","0.325336"],["64975.8","0.948702"],["64975.7","2.149673"],["64969.3","0.01135"],["64969.2","0.007799"],["64962","0"],["64960.6","0"],["64960.5","0"]],"a":[["64975.8","0"],["64975.9","0"],["64976","4.176585"],["64978","20.223366"],["64981.3","0.023492"],["64982.3","0.135999"],["64982.4","0.0156"],["64985.9","0"],["64986.9","0"],["64989","1.138152"],["64989.7","0.03"],["64989.8","0.0025"]],"u":184066716,"seq":112464947982},"cts":1786191780314}
{"topic":"orderbook.50.BTCUSDT","ts":1786191780335,"type":"delta","data":{"s":"BTCUSDT","b":[["64975.9","2.143764"],["64975.8","3.042337"],["64975.7","0.101492"],["64975.3","0"],["64972.1","0.038669"],["64969.4","0.012649"],["64969.3","0"],["64969.2","0"],["64966.7","0.099704"],["64964.1","0"],["64962","0.000116"]],"a":[["64976","2.92495"],["64981.3","0"],["64982.3","0.1282"],["64982.4","0"],["64982.5","0.015899"],["64983.9","0"],["64985.1","0"],["64990","0.915549"],["64990.9","1.330965"],["64991","3"]],"u":184066717,"seq":112464948303},"cts":1786191780334}
{"topic":"orderbook.50.BTCUSDT","ts":1786191780355,"type":"delta","data":{"s":"BTCUSDT","b":[["64975.9","2.158764"],["64975.8","2.392044"],["64975.7","0.095412"],["64966.7","0"],["64966.6","0.310186"],["64960.6","0.164822"]],"a":[["64976","1.862252"]],"u":184066718,"seq":112464948364},"cts":1786191780354}
{"topic":"orderbook.50.BTCUSDT","ts":1786191780376,"type":"delta","data":{"s":"BTCUSDT","b":[["64975.9","2.37472"],["64975.8","2.166681"],["64970.7","0.016887"],["64965.8","0"],["64963","0.00154"]],"a":[["64986.9","0.501115"],["64991","0"]],"u":184066719,"seq":112464948393},"cts":1786191780373}
{"topic":"orderbook.50.BTCUSDT","ts":1786191780396,"type":"delta","data":{"s":"BTCUSDT","b":[["64975.9","2.33012"],["64975.7","0.115006"],["64964.4","0.00154"],["64963","0"]],"a":[["64986.9","1.517423"]],"u":184066720,"seq":112464948442},"cts":1786191780394}
{"topic":"orderbook.50.BTCUSDT","ts":1786191780416,"type":"delta","data":{"s":"BTCUSDT","b":[["64975.9","2.33392"],["64965.8","0.00154"],["64964.4","0"]],"a":[],"u":184066721,"seq":112464948450},"cts":1786191780414}
{"topic":"orderbook.50.BTCUSDT","ts":1786191780435,"type":"delta","data":{"s":"BTCUSDT","b":[["64975.9","2.3382"],["64967.2","0.00154"],["64966.7","0.099705"],["64966.6","0.210481"],["64965.8","0"],["64960.6","0"]],"a":[],"u":184066722,"seq":112464948464},"cts":1786191780432}
{"topic":"orderbook.50.BTCUSDT","ts":1786191780456,"type":"delta","data":{"s":"BTCUSDT","b":[["64975.9","2.359511"],["64975.7","0.094342"]],"a":[["64981.8","0.023816"]],"u":184066723,"seq":112464948473},"cts":1786191780454}
{"topic":"orderbook.50.BTCUSDT","ts":1786191780476,"type":"delta","data":{"s":"BTCUSDT","b":[["64975.9","2.363311"],["64966.7","0"],["64966.6","0.310186"],["64960.6","0.164822"]],"a":[],"u":184066724,"seq":112464948482},"cts":1786191780474}
{"topic":"orderbook.50.BTCUSDT","ts":1786191780496,"type":"delta","data":{"s":"BTCUSDT","b":[["64975.9","2.360271"],["64966.6","0.210481"],["64966.2","0.099705"],["64960.6","0"]],"a":[],"u":184066725,"seq":112464948490},"cts":1786191780491}
{"topic":"orderbook.50.BTCUSDT","ts":1786191780516,"type":"delta","data":{"s":"BTCUSDT","b":[["64975.9","2.357991"],["64968.5","0.001656"],["64967.2","0"],["64960.6","0.164822"]],"a":[["64982.9","0.023492"],["64989","1.143755"],["64990.9","0"]],"u":184066726,"seq":112464948497},"cts":1786191780501}
{"topic":"orderbook.50.BTCUSDT","ts":1786191780536,"type":"delta","data":{"s":"BTCUSDT","b":[["64975.9","2.356471"]],"a":[["64976","1.702798"]],"u":184066727,"seq":112464948508},"cts":1786191780531}
{"topic":"orderbook.50.BTCUSDT","ts":1786191780556,"type":"delta","data":{"s":"BTCUSDT","b":[["64975.9","2.354191"]],"a":[["64976","1.698869"]],"u":184066728,"seq":112464948519},"cts":1786191780552}
{"topic":"orderbook.50.BTCUSDT","ts":1786191780575,"type":"delta","data":{"s":"BTCUSDT","b":[["64975.9","2.356471"]],"a":[],"u":184066729,"seq":112464948527},"cts":1786191780574}
{"topic":"orderbook.50.BTCUSDT","ts":1786191780596,"type":"delta","data":{"s":"BTCUSDT","b":[["64975.9","2.357231"]],"a":[],"u":184066730,"seq":112464948531},"cts":1786191780581}
{"topic":"orderbook.50.BTCUSDT","ts":1786191780619,"type":"delta","data":{"s":"BTCUSDT","b":[["64975.9","2.360271"],["64966.2","0"],["64964.1","0.099707"]],"a":[],"u":184066731,"seq":112464948541},"cts":1786191780612}
{"topic":"orderbook.50.BTCUSDT","ts":1786191780636,"type":"delta","data":{"s":"BTCUSDT","b":[["64975.9","2.359511"]],"a":[],"u":184066732,"seq":112464948544},"cts":1786191780630}
{"topic":"orderbook.50.BTCUSDT","ts":1786191780656,"type":"delta","data":{"s":"BTCUSDT","b":[["64975.9","2.357231"],["64966.2","0.099706"],["64964.1","0"]],"a":[],"u":184066733,"seq":112464948551},"cts":1786191780652}
{"topic":"orderbook.50.BTCUSDT","ts":1786191780676,"type":"delta","data":{"s":"BTCUSDT","b":[["64975.9","2.356471"]],"a":[],"u":184066734,"seq":112464948554},"cts":1786191780674}
{"topic":"orderbook.50.BTCUSDT","ts":1786191780696,"type":"delta","data":{"s":"BTCUSDT","b":[["64975.9","2.353431"]],"a":[],"u":184066735,"seq":112464948559},"cts":1786191780686}
{"topic":"orderbook.50.BTCUSDT","ts":1786191780716,"type":"delta","data":{"s":"BTCUSDT","b":[["64975.9","2.354292"],["64975.7","0.093481"]],"a":[],"u":184066736,"seq":112464948561},"cts":1786191780714}
{"topic":"orderbook.50.BTCUSDT","ts":1786191780736,"type":"delta","data":{"s":"BTCUSDT","b":[],"a":[["64986.9","2.649797"]],"u":184066737,"seq":112464948564},"cts":1786191780718}
{"topic":"orderbook.50.BTCUSDT","ts":1786191780756,"type":"delta","data":{"s":"BTCUSDT","b":[["64966.2","0"],["64964.1","0.099706"]],"a":[],"u":184066738,"seq":112464948566},"cts":1786191780738}
{"topic":"orderbook.50.BTCUSDT","ts":1786191780916,"type":"delta","data":{"s":"BTCUSDT","b":[["64975.9","2.416992"],["64975.7","0.030781"]],"a":[],"u":184066739,"seq":112464948575},"cts":1786191780912}
{"topic":"orderbook.50.BTCUSDT","ts":1786191780936,"type":"delta","data":{"s":"BTCUSDT","b":[["64975.6","0.000093"],["64974.2","0.000093"],["64973.1","0.000093"],["64962.3","0"],["64962","0"],["64960.6","0"]],"a":[],"u":184066740,"seq":112464948590},"cts":1786191780933}
{"topic":"orderbook.50.BTCUSDT","ts":1786191781016,"type":"delta","data":{"s":"BTCUSDT","b":[["64975.9","2.422312"]],"a":[],"u":184066741,"seq":112464948604},"cts":1786191781010}
{"topic":"orderbook.50.BTCUSDT","ts":1786191781055,"type":"delta","data":{"s":"BTCUSDT","b":[["64975.9","2.125022"]],"a":[],"u":184066742,"seq":112464948608},"cts":1786191781054}
{"topic":"orderbook.50.BTCUSDT","ts":1786191781096,"type":"delta","data":{"s":"BTCUSDT","b":[["64975.9","2.119702"]],"a":[],"u":184066743,"seq":112464948621},"cts":1786191781091}
{"topic":"orderbook.50.BTCUSDT","ts":1786191781136,"type":"delta","data":{"s":"BTCUSDT","b":[["64975.9","2.121982"]],"a":[],"u":184066744,"seq":112464948626},"cts":1786191781130}
{"topic":"orderbook.50.BTCUSDT","ts":1786191781175,"type":"delta","data":{"s":"BTCUSDT","b":[["64975.9","2.125782"],["64966.7","0.099705"],["64964.1","0"]],"a":[],"u":184066745,"seq":112464948635},"cts":1786191781174}
{"topic":"orderbook.50.BTCUSDT","ts":1786191781196,"type":"delta","data":{"s":"BTCUSDT","b":[["64966.7","0"],["64966.6","0.310186"],["64962.3","0.000324"]],"a":[],"u":184066746,"seq":112464948637},"cts":1786191781193}
{"topic":"orderbook.50.BTCUSDT","ts":1786191781216,"type":"delta","data":{"s":"BTCUSDT","b":[["64975.9","2.128062"],["64974.2","0"],["64966.6","0.210481"],["64964.1","0.099706"]],"a":[["64976","1.668869"]],"u":184066747,"seq":112464948650},"cts":1786191781209}
{"topic":"orderbook.50.BTCUSDT","ts":1786191781256,"type":"delta","data":{"s":"BTCUSDT","b":[["64975.9","2.124262"]],"a":[],"u":184066748,"seq":112464948660},"cts":1786191781252}
{"topic":"orderbook.50.BTCUSDT","ts":1786191781296,"type":"delta","data":{"s":"BTCUSDT","b":[["64975.9","2.119702"]],"a":[],"u":184066749,"seq":112464948668},"cts":1786191781291}
{"topic":"orderbook.50.BTCUSDT","ts":1786191781316,"type":"delta","data":{"s":"BTCUSDT","b":[["64975.9","3.658734"],["64975.8","0.627647"]],"a":[],"u":184066750,"seq":112464948670},"cts":1786191781314}
{"topic":"orderbook.50.BTCUSDT","ts":1786191781335,"type":"delta","data":{"s":"BTCUSDT","b":[["64975.9","3.661014"]],"a":[],"u":184066751,"seq":112464948677},"cts":1786191781334}
{"topic":"orderbook.50.BTCUSDT","ts":1786191781376,"type":"delta","data":{"s":"BTCUSDT","b":[["64975.9","3.663294"]],"a":[],"u":184066752,"seq":112464948682},"cts":1786191781373}
{"topic":"orderbook.50.BTCUSDT","ts":1786191781419,"type":"delta","data":{"s":"BTCUSDT","b":[["64975.9","3.661014"]],"a":[],"u":184066753,"seq":112464948687},"cts":1786191781411}
{"topic":"orderbook.50.BTCUSDT","ts":1786191781456,"type":"delta","data":{"s":"BTCUSDT","b":[["64975.9","3.659494"]],"a":[],"u":184066754,"seq":112464948693},"cts":1786191781452}
{"topic":"orderbook.50.BTCUSDT","ts":1786191781476,"type":"delta","data":{"s":"BTCUSDT","b":[["64975.9","3.664814"]],"a":[],"u":184066755,"seq":112464948700},"cts":1786191781463}
{"topic":"orderbook.50.BTCUSDT","ts":1786191781496,"type":"delta","data":{"s":"BTCUSDT","b":[["64975.9","3.564814"]],"a":[["64976","1.668683"]],"u":184066756,"seq":112464948709},"cts":1786191781492}
{"topic":"orderbook.50.BTCUSDT","ts":1786191781536,"type":"delta","data":{"s":"BTCUSDT","b":[["64975.9","3.564054"]],"a":[],"u":184066757,"seq":112464948723},"cts":1786191781532}
{"topic":"orderbook.50.BTCUSDT","ts":1786191781556,"type":"delta","data":{"s":"BTCUSDT","b":[["64975.9","3.561014"]],"a":[],"u":184066758,"seq":112464948729},"cts":1786191781544}
{"topic":"orderbook.50.BTCUSDT","ts":1786191781616,"type":"delta","data":{"s":"BTCUSDT","b":[["64975.9","3.562534"],["64966.6","0.310186"],["64964.1","0"],["64962","0.000116"]],"a":[],"u":184066759,"seq":112464948753},"cts":1786191781615}
{"topic":"orderbook.50.BTCUSDT","ts":1786191781636,"type":"delta","data":{"s":"BTCUSDT","b":[["64975.9","3.563294"],["64966.6","0.210481"],["64964.1","0.099707"],["64962","0"]],"a":[["64976","1.866183"]],"u":184066760,"seq":112464948760},"cts":1786191781627}
{"topic":"orderbook.50.BTCUSDT","ts":1786191781656,"type":"delta","data":{"s":"BTCUSDT","b":[["64975.9","3.563064"]],"a":[["64976","1.668683"]],"u":184066761,"seq":112464948766},"cts":1786191781652}
{"topic":"orderbook.50.BTCUSDT","ts":1786191781696,"type":"delta","data":{"s":"BTCUSDT","b":[["64975.9","3.559264"]],"a":[],"u":184066762,"seq":112464948777},"cts":1786191781693}
{"topic":"orderbook.50.BTCUSDT","ts":1786191781716,"type":"delta","data":{"s":"BTCUSDT","b":[["64975.9","3.562304"]],"a":[],"u":184066763,"seq":112464948788},"cts":1786191781714}
{"topic":"orderbook.50.BTCUSDT","ts":1786191781736,"type":"delta","data":{"s":"BTCUSDT","b":[["64973.1","0"],["64962","0.000116"]],"a":[],"u":184066764,"seq":112464948789},"cts":1786191781718}
{"topic":"orderbook.50.BTCUSDT","ts":1786191781796,"type":"delta","data":{"s":"BTCUSDT","b":[["64975.9","3.558504"]],"a":[],"u":184066765,"seq":112464948799},"cts":1786191781782}
{"topic":"orderbook.50.BTCUSDT","ts":1786191781836,"type":"delta","data":{"s":"BTCUSDT","b":[["64975.9","3.658504"],["64975.8","0.527647"]],"a":[],"u":184066766,"seq":112464948804},"cts":1786191781826}
{"topic":"orderbook.50.BTCUSDT","ts":1786191781876,"type":"delta","data":{"s":"BTCUSDT","b":[["64975.9","3.663064"]],"a":[],"u":184066767,"seq":112464948811},"cts":1786191781875}
{"topic":"orderbook.50.BTCUSDT","ts":1786191781896,"type":"delta","data":{"s":"BTCUSDT","b":[["64975.9","3.664584"]],"a":[],"u":184066768,"seq":112464948813},"cts":1786191781876}
{"topic":"orderbook.50.BTCUSDT","ts":1786191781956,"type":"delta","data":{"s":"BTCUSDT","b":[["64975.9","3.658504"]],"a":[["64987.7","0.014785"],["64990","0"]],"u":184066769,"seq":112464948827},"cts":1786191781951}
{"topic":"orderbook.50.BTCUSDT","ts":1786191781996,"type":"delta","data":{"s":"BTCUSDT","b":[["64975.6","0"],["64960.6","0.164822"]],"a":[],"u":184066770,"seq":112464948831},"cts":1786191781989}
{"topic":"orderbook.50.BTCUSDT","ts":1786191782316,"type":"delta","data":{"s":"BTCUSDT","b":[],"a":[["64976","1.668836"]],"u":184066771,"seq":112464948854},"cts":1786191782312}
{"topic":"orderbook.50.BTCUSDT","ts":1786191782336,"type":"delta","data":{"s":"BTCUSDT","b":[],"a":[["64976","1.684349"]],"u":184066772,"seq":112464948855},"cts":1786191782320}
{"topic":"orderbook.50.BTCUSDT","ts":1786191782356,"type":"delta","data":{"s":"BTCUSDT","b":[["64966.6","0.310186"],["64964.1","0"],["64960.5","0.617969"]],"a":[["64976","1.700591"]],"u":184066773,"seq":112464948862},"cts":1786191782351}
{"topic":"orderbook.50.BTCUSDT","ts":1786191782376,"type":"delta","data":{"s":"BTCUSDT","b":[["64966.6","0.210481"],["64964.1","0.099706"],["64960.5","0"]],"a":[["64976","1.716632"]],"u":184066774,"seq":112464948865},"cts":1786191782374}
{"topic":"orderbook.50.BTCUSDT","ts":1786191782396,"type":"delta","data":{"s":"BTCUSDT","b":[["64975.6","0.000093"],["64974.4","0.200093"],["64973.4","0.000093"],["64962","0"],["64960.6","0"]],"a":[],"u":184066775,"seq":112464948870},"cts":1786191782383}
{"topic":"orderbook.50.BTCUSDT","ts":1786191782416,"type":"delta","data":{"s":"BTCUSDT","b":[["64975.9","3.666104"]],"a":[],"u":184066776,"seq":112464948881},"cts":1786191782413}
{"topic":"orderbook.50.BTCUSDT","ts":1786191782436,"type":"delta","data":{"s":"BTCUSDT","b":[["64975.9","3.669144"]],"a":[["64976","1.700591"]],"u":184066777,"seq":112464948892},"cts":1786191782428}
{"topic":"orderbook.50.BTCUSDT","ts":1786191782456,"type":"delta","data":{"s":"BTCUSDT","b":[],"a":[["64976","1.684349"]],"u":184066778,"seq":112464948894},"cts":1786191782451}
{"topic":"orderbook.50.BTCUSDT","ts":1786191782496,"type":"delta","data":{"s":"BTCUSDT","b":[["64975.9","3.660784"]],"a":[],"u":184066779,"seq":112464948906},"cts":1786191782491}
{"topic":"orderbook.50.BTCUSDT","ts":1786191782516,"type":"delta","data":{"s":"BTCUSDT","b":[["64975.9","3.659264"]],"a":[],"u":184066780,"seq":112464948909},"cts":1786191782506}
{"topic":"orderbook.50.BTCUSDT","ts":1786191782536,"type":"delta","data":{"s":"BTCUSDT","b":[["64975.9","3.658504"]],"a":[],"u":184066781,"seq":112464948914},"cts":1786191782528}
{"topic":"orderbook.50.BTCUSDT","ts":1786191782576,"type":"delta","data":{"s":"BTCUSDT","b":[["64975.9","3.661544"]],"a":[],"u":184066782,"seq":112464948923},"cts":1786191782565}
{"topic":"orderbook.50.BTCUSDT","ts":1786191782596,"type":"delta","data":{"s":"BTCUSDT","b":[],"a":[["64976","1.668836"]],"u":184066783,"seq":112464948924},"cts":1786191782580}
{"topic":"orderbook.50.BTCUSDT","ts":1786191782616,"type":"delta","data":{"s":"BTCUSDT","b":[["64975.9","3.666104"]],"a":[],"u":184066784,"seq":112464948933},"cts":1786191782608}
{"topic":"orderbook.50.BTCUSDT","ts":1786191782636,"type":"delta","data":{"s":"BTCUSDT","b":[["64975.9","3.666864"]],"a":[],"u":184066785,"seq":112464948934},"cts":1786191782622}
{"topic":"orderbook.50.BTCUSDT","ts":1786191782656,"type":"delta","data":{"s":"BTCUSDT","b":[["64975.9","3.663824"]],"a":[],"u":184066786,"seq":112464948939},"cts":1786191782654}
{"topic":"orderbook.50.BTCUSDT","ts":1786191782696,"type":"delta","data":{"s":"BTCUSDT","b":[["64975.9","3.661544"],["64974.4","0.2"]],"a":[],"u":184066787,"seq":112464948949},"cts":1786191782693}
{"topic":"orderbook.50.BTCUSDT","ts":1786191782716,"type":"delta","data":{"s":"BTCUSDT","b":[["64975.9","3.660784"]],"a":[],"u":184066788,"seq":112464948952},"cts":1786191782709}
{"topic":"orderbook.50.BTCUSDT","ts":1786191782755,"type":"delta","data":{"s":"BTCUSDT","b":[["64975.9","3.660024"]],"a":[],"u":184066789,"seq":112464948960},"cts":1786191782755}
{"topic":"orderbook.50.BTCUSDT","ts":1786191782776,"type":"delta","data":{"s":"BTCUSDT","b":[["64975.9","3.663824"]],"a":[],"u":184066790,"seq":112464948966},"cts":1786191782771}
{"topic":"orderbook.50.BTCUSDT","ts":1786191782856,"type":"delta","data":{"s":"BTCUSDT","b":[["64975.9","3.659264"]],"a":[["64976","1.866336"]],"u":184066791,"seq":112464948983},"cts":1786191782850}
{"topic":"orderbook.50.BTCUSDT","ts":1786191782876,"type":"delta","data":{"s":"BTCUSDT","b":[["64975.9","3.661544"]],"a":[],"u":184066792,"seq":112464948987},"cts":1786191782871}
{"topic":"orderbook.50.BTCUSDT","ts":1786191782936,"type":"delta","data":{"s":"BTCUSDT","b":[["64975.9","3.660024"]],"a":[],"u":184066793,"seq":112464948992},"cts":1786191782931}
{"topic":"orderbook.50.BTCUSDT","ts":1786191782956,"type":"delta","data":{"s":"BTCUSDT","b":[["64975.9","3.658504"]],"a":[],"u":184066794,"seq":112464948995},"cts":1786191782943}
{"topic":"orderbook.50.BTCUSDT","ts":1786191782976,"type":"delta","data":{"s":"BTCUSDT","b":[["64975.9","3.660784"],["64973.4","0"],["64962","0.000116"]],"a":[],"u":184066795,"seq":112464949000},"cts":1786191782965}
{"topic":"orderbook.50.BTCUSDT","ts":1786191783019,"type":"delta","data":{"s":"BTCUSDT","b":[["64975.9","3.662304"]],"a":[],"u":184066796,"seq":112464949003},"cts":1786191783013}
{"topic":"orderbook.50.BTCUSDT","ts":1786191783036,"type":"delta","data":{"s":"BTCUSDT","b":[["64975.9","3.665344"]],"a":[],"u":184066797,"seq":112464949007},"cts":1786191783024}
{"topic":"orderbook.50.BTCUSDT","ts":1786191783056,"type":"delta","data":{"s":"BTCUSDT","b":[["64975.9","3.663824"]],"a":[],"u":184066798,"seq":112464949012},"cts":1786191783050}
{"topic":"orderbook.50.BTCUSDT","ts":1786191783076,"type":"delta","data":{"s":"BTCUSDT","b":[["64975.9","3.666864"]],"a":[["64987.2","0"],["64990","0.915549"]],"u":184066799,"seq":112464949019},"cts":1786191783063}
{"topic":"orderbook.50.BTCUSDT","ts":1786191783096,"type":"delta","data":{"s":"BTCUSDT","b":[["64975.9","3.665344"]],"a":[["64985.9","0.407203"],["64990","0"]],"u":184066800,"seq":112464949022},"cts":1786191783090}
{"topic":"orderbook.50.BTCUSDT","ts":1786191783116,"type":"delta","data":{"s":"BTCUSDT","b":[["64975.9","3.662304"]],"a":[],"u":184066801,"seq":112464949029},"cts":1786191783115}
{"topic":"orderbook.50.BTCUSDT","ts":1786191783136,"type":"delta","data":{"s":"BTCUSDT","b":[["64975.9","3.660024"]],"a":[],"u":184066802,"seq":112464949034},"cts":1786191783133}
{"topic":"orderbook.50.BTCUSDT","ts":1786191783156,"type":"delta","data":{"s":"BTCUSDT","b":[["64975.9","3.658504"]],"a":[],"u":184066803,"seq":112464949039},"cts":1786191783154}
{"topic":"orderbook.50.BTCUSDT","ts":1786191783216,"type":"delta","data":{"s":"BTCUSDT","b":[["64975.9","3.661544"]],"a":[],"u":184066804,"seq":112464949045},"cts":1786191783214}
{"topic":"orderbook.50.BTCUSDT","ts":1786191783236,"type":"delta","data":{"s":"BTCUSDT","b":[["64975.9","3.664584"]],"a":[],"u":184066805,"seq":112464949051},"cts":1786191783235}
{"topic":"orderbook.50.BTCUSDT","ts":1786191783296,"type":"delta","data":{"s":"BTCUSDT","b":[["64975.9","3.660784"]],"a":[],"u":184066806,"seq":112464949060},"cts":1786191783291}
{"topic":"orderbook.50.BTCUSDT","ts":1786191783316,"type":"delta","data":{"s":"BTCUSDT","b":[["64975.9","3.663064"]],"a":[],"u":184066807,"seq":112464949069},"cts":1786191783311}
{"topic":"orderbook.50.BTCUSDT","ts":1786191783376,"type":"delta","data":{"s":"BTCUSDT","b":[["64975.9","3.663824"],["64975.6","0.000186"],["64974.3","0.004399"]],"a":[],"u":184066808,"seq":112464949076},"cts":1786191783367}
{"topic":"orderbook.50.BTCUSDT","ts":1786191783396,"type":"delta","data":{"s":"BTCUSDT","b":[["64975.9","3.659264"]],"a":[],"u":184066809,"seq":112464949082},"cts":1786191783392}
{"topic":"orderbook.50.BTCUSDT","ts":1786191783476,"type":"delta","data":{"s":"BTCUSDT","b":[["64975.9","3.662304"]],"a":[],"u":184066810,"seq":112464949111},"cts":1786191783475}
{"topic":"orderbook.50.BTCUSDT","ts":1786191783496,"type":"delta","data":{"s":"BTCUSDT","b":[["64975.9","3.664584"]],"a":[],"u":184066811,"seq":112464949116},"cts":1786191783490}
{"topic":"orderbook.50.BTCUSDT","ts":1786191783536,"type":"delta","data":{"s":"BTCUSDT","b":[["64975.9","3.663824"]],"a":[["64976","1.896336"],["64986.9","7.672711"]],"u":184066812,"seq":112464949131},"cts":1786191783534}
{"topic":"orderbook.50.BTCUSDT","ts":1786191783556,"type":"delta","data":{"s":"BTCUSDT","b":[["64975.9","3.462524"]],"a":[],"u":184066813,"seq":112464949143},"cts":1786191783554}
{"topic":"orderbook.50.BTCUSDT","ts":1786191783576,"type":"delta","data":{"s":"BTCUSDT","b":[["64975.9","3.465564"]],"a":[],"u":184066814,"seq":112464949155},"cts":1786191783571}
{"topic":"orderbook.50.BTCUSDT","ts":1786191783616,"type":"delta","data":{"s":"BTCUSDT","b":[["64974.3","0.004306"],["64964.1","0"],["64963.6","0.099738"],["64960.6","0.164822"]],"a":[["64980.7","0.022651"],["64981.8","0.000324"],["64989.8","0"]],"u":184066815,"seq":112464949177},"cts":1786191783614}
{"topic":"orderbook.50.BTCUSDT","ts":1786191783636,"type":"delta","data":{"s":"BTCUSDT","b":[["64975.9","3.466324"],["64963.7","0.134651"],["64963.5","0"],["64960.5","0.617969"]],"a":[["64976","2.005936"]],"u":184066816,"seq":112464949193},"cts":1786191783630}
{"topic":"orderbook.50.BTCUSDT","ts":1786191783656,"type":"delta","data":{"s":"BTCUSDT","b":[["64975.9","3.461764"],["64964.1","0.099709"],["64963.6","0.000029"],["64960.5","0"]],"a":[],"u":184066817,"seq":112464949205},"cts":1786191783650}
{"topic":"orderbook.50.BTCUSDT","ts":1786191783676,"type":"delta","data":{"s":"BTCUSDT","b":[["64975.9","3.462524"]],"a":[],"u":184066818,"seq":112464949210},"cts":1786191783669}
{"topic":"orderbook.50.BTCUSDT","ts":1786191783736,"type":"delta","data":{"s":"BTCUSDT","b":[["64975.9","3.464804"]],"a":[],"u":184066819,"seq":112464949224},"cts":1786191783733}
{"topic":"orderbook.50.BTCUSDT","ts":1786191783796,"type":"delta","data":{"s":"BTCUSDT","b":[["64975.9","3.461004"]],"a":[],"u":184066820,"seq":112464949237},"cts":1786191783794}
{"topic":"orderbook.50.BTCUSDT","ts":1786191783819,"type":"delta","data":{"s":"BTCUSDT","b":[["64975.9","3.465564"]],"a":[],"u":184066821,"seq":112464949246},"cts":1786191783810}
{"topic":"orderbook.50.BTCUSDT","ts":1786191783836,"type":"delta","data":{"s":"BTCUSDT","b":[["64975.9","3.467844"],["64975.6","0"],["64960.5","0.617969"]],"a":[],"u":184066822,"seq":112464949253},"cts":1786191783827}
{"topic":"orderbook.50.BTCUSDT","ts":1786191783896,"type":"delta","data":{"s":"BTCUSDT","b":[["64975.9","3.463284"]],"a":[],"u":184066823,"seq":112464949265},"cts":1786191783891}
{"topic":"orderbook.50.BTCUSDT","ts":1786191783916,"type":"delta","data":{"s":"BTCUSDT","b":[["64975.9","3.461004"]],"a":[],"u":184066824,"seq":112464949268},"cts":1786191783901}
{"topic":"orderbook.50.BTCUSDT","ts":1786191783936,"type":"delta","data":{"s":"BTCUSDT","b":[["64974.5","0"],["64960.4","0.507459"]],"a":[],"u":184066825,"seq":112464949275},"cts":1786191783933}
{"topic":"orderbook.50.BTCUSDT","ts":1786191783976,"type":"delta","data":{"s":"BTCUSDT","b":[["64975.9","3.464804"]],"a":[],"u":184066826,"seq":112464949284},"cts":1786191783974}
{"topic":"orderbook.50.BTCUSDT","ts":1786191784056,"type":"delta","data":{"s":"BTCUSDT","b":[["64975.9","3.461764"]],"a":[],"u":184066827,"seq":112464949297},"cts":1786191784052}
{"topic":"orderbook.50.BTCUSDT","ts":1786191784075,"type":"delta","data":{"s":"BTCUSDT","b":[["64975.9","3.465564"]],"a":[],"u":184066828,"seq":112464949302},"cts":1786191784062}
{"topic":"orderbook.50.BTCUSDT","ts":1786191784136,"type":"delta","data":{"s":"BTCUSDT","b":[["64975.9","3.462524"]],"a":[],"u":184066829,"seq":112464949315},"cts":1786191784134}
{"topic":"orderbook.50.BTCUSDT","ts":1786191784156,"type":"delta","data":{"s":"BTCUSDT","b":[["64975.9","3.461004"]],"a":[],"u":184066830,"seq":112464949318},"cts":1786191784146}
{"topic":"orderbook.50.BTCUSDT","ts":1786191784216,"type":"delta","data":{"s":"BTCUSDT","b":[["64975.9","3.463284"]],"a":[],"u":184066831,"seq":112464949322},"cts":1786191784213}
{"topic":"orderbook.50.BTCUSDT","ts":1786191784236,"type":"delta","data":{"s":"BTCUSDT","b":[["64975.9","3.466324"]],"a":[],"u":184066832,"seq":112464949327},"cts":1786191784232}
{"topic":"orderbook.50.BTCUSDT","ts":1786191784296,"type":"delta","data":{"s":"BTCUSDT","b":[["64975.9","3.464804"],["64970.7","0.015387"],["64965.8","0.0015"],["64960.4","0"]],"a":[["64986.6","0.0015"],["64989.7","0"]],"u":184066833,"seq":112464949345},"cts":1786191784291}
{"topic":"orderbook.50.BTCUSDT","ts":1786191784317,"type":"delta","data":{"s":"BTCUSDT","b":[["64975.9","3.466324"]],"a":[],"u":184066834,"seq":112464949359},"cts":1786191784309}
{"topic":"orderbook.50.BTCUSDT","ts":1786191784376,"type":"delta","data":{"s":"BTCUSDT","b":[["64975.6","0.000186"],["64975.1","0.000093"],["64974.3","0.004399"],["64973.3","0.000093"],["64962","0"],["64960.6","0"],["64960.5","0"]],"a":[],"u":184066835,"seq":112464949367},"cts":1786191784363}
{"topic":"orderbook.50.BTCUSDT","ts":1786191784396,"type":"delta","data":{"s":"BTCUSDT","b":[["64975.9","3.461004"]],"a":[],"u":184066836,"seq":112464949375},"cts":1786191784392}
{"topic":"orderbook.50.BTCUSDT","ts":1786191784456,"type":"delta","data":{"s":"BTCUSDT","b":[["64966.7","0.099705"],["64964.1","0"]],"a":[],"u":184066837,"seq":112464949384},"cts":1786191784453}
{"topic":"orderbook.50.BTCUSDT","ts":1786191784476,"type":"delta","data":{"s":"BTCUSDT","b":[["64975.9","3.464044"],["64966.7","0"],["64966.6","0.310186"],["64962","0.000116"]],"a":[],"u":184066838,"seq":112464949389},"cts":1786191784472}
{"topic":"orderbook.50.BTCUSDT","ts":1786191784496,"type":"delta","data":{"s":"BTCUSDT","b":[["64975.9","3.466324"],["64966.6","0.210481"],["64964.1","0.099706"],["64962","0"]],"a":[],"u":184066839,"seq":112464949395},"cts":1786191784483}
{"topic":"orderbook.50.BTCUSDT","ts":1786191784536,"type":"delta","data":{"s":"BTCUSDT","b":[],"a":[["64983.3","0.000679"],["64989.6","0"]],"u":184066840,"seq":112464949397},"cts":1786191784534}
{"topic":"orderbook.50.BTCUSDT","ts":1786191784555,"type":"delta","data":{"s":"BTCUSDT","b":[["64975.9","3.461004"]],"a":[],"u":184066841,"seq":112464949410},"cts":1786191784554}
{"topic":"orderbook.50.BTCUSDT","ts":1786191784596,"type":"delta","data":{"s":"BTCUSDT","b":[["64974.3","0.004306"]],"a":[],"u":184066842,"seq":112464949415},"cts":1786191784594}
{"topic":"orderbook.50.BTCUSDT","ts":1786191784619,"type":"delta","data":{"s":"BTCUSDT","b":[["64966.7","0.099704"],["64964.1","0"]],"a":[],"u":184066843,"seq":112464949421},"cts":1786191784615}
{"topic":"orderbook.50.BTCUSDT","ts":1786191784696,"type":"delta","data":{"s":"BTCUSDT","b":[["64966.7","0"],["64966.6","0.310186"],["64962","0.000116"]],"a":[],"u":184066844,"seq":112464949434},"cts":1786191784689}
{"topic":"orderbook.50.BTCUSDT","ts":1786191784716,"type":"delta","data":{"s":"BTCUSDT","b":[["64966.6","0.210481"],["64966.2","0.099705"],["64962","0"]],"a":[],"u":184066845,"seq":112464949436},"cts":1786191784712}
{"topic":"orderbook.50.BTCUSDT","ts":1786191784876,"type":"delta","data":{"s":"BTCUSDT","b":[["64966.2","0"],["64964.1","0.099706"]],"a":[],"u":184066846,"seq":112464949456},"cts":1786191784871}
{"topic":"orderbook.50.BTCUSDT","ts":1786191785056,"type":"delta","data":{"s":"BTCUSDT","b":[["64975.1","0"],["64962","0.000116"]],"a":[],"u":184066847,"seq":112464949472},"cts":1786191785044}
{"topic":"orderbook.50.BTCUSDT","ts":1786191785296,"type":"delta","data":{"s":"BTCUSDT","b":[["64973.3","0"],["64960.6","0.164822"]],"a":[],"u":184066848,"seq":112464949493},"cts":1786191785294}
{"topic":"orderbook.50.BTCUSDT","ts":1786191785396,"type":"delta","data":{"s":"BTCUSDT","b":[["64963.3","0.080868"]],"a":[],"u":184066849,"seq":112464949500},"cts":1786191785394}
{"topic":"orderbook.50.BTCUSDT","ts":1786191785436,"type":"delta","data":{"s":"BTCUSDT","b":[["64975.9","3.460972"]],"a":[],"u":184066850,"seq":112464949502},"cts":1786191785434}
{"topic":"orderbook.50.BTCUSDT","ts":1786191785456,"type":"delta","data":{"s":"BTCUSDT","b":[["64975.8","0.386382"]],"a":[],"u":184066851,"seq":112464949506},"cts":1786191785451}
{"topic":"orderbook.50.BTCUSDT","ts":1786191785576,"type":"delta","data":{"s":"BTCUSDT","b":[["64966.6","0.310186"],["64964.1","0"],["64960.5","0.617969"]],"a":[],"u":184066852,"seq":112464949515},"cts":1786191785562}
{"topic":"orderbook.50.BTCUSDT","ts":1786191785596,"type":"delta","data":{"s":"BTCUSDT","b":[["64966.6","0.210481"],["64964.1","0.099706"],["64960.5","0"]],"a":[],"u":184066853,"seq":112464949519},"cts":1786191785585}
{"topic":"orderbook.50.BTCUSDT","ts":1786191785617,"type":"delta","data":{"s":"BTCUSDT","b":[],"a":[["64976","2.006397"]],"u":184066854,"seq":112464949521},"cts":1786191785599}
{"topic":"orderbook.50.BTCUSDT","ts":1786191785636,"type":"delta","data":{"s":"BTCUSDT","b":[["64964.2","0.100567"],["64964.1","0"],["64960.5","0.617969"]],"a":[["64976","2.02214"]],"u":184066855,"seq":112464949524},"cts":1786191785630}
{"topic":"orderbook.50.BTCUSDT","ts":1786191785656,"type":"delta","data":{"s":"BTCUSDT","b":[["64975.7","0.030874"],["64974.4","0.200186"],["64964.2","0.000861"],["64964.1","0.099706"],["64960.5","0"]],"a":[["64976","2.037239"]],"u":184066856,"seq":112464949531},"cts":1786191785654}
{"topic":"orderbook.50.BTCUSDT","ts":1786191785736,"type":"delta","data":{"s":"BTCUSDT","b":[["64975.9","3.464012"]],"a":[],"u":184066857,"seq":112464949546},"cts":1786191785732}
{"topic":"orderbook.50.BTCUSDT","ts":1786191785756,"type":"delta","data":{"s":"BTCUSDT","b":[["64975.9","3.464095"]],"a":[],"u":184066858,"seq":112464949552},"cts":1786191785750}
{"topic":"orderbook.50.BTCUSDT","ts":1786191785776,"type":"delta","data":{"s":"BTCUSDT","b":[["64975.9","3.464184"]],"a":[["64976","2.02214"]],"u":184066859,"seq":112464949556},"cts":1786191785760}
{"topic":"orderbook.50.BTCUSDT","ts":1786191785796,"type":"delta","data":{"s":"BTCUSDT","b":[["64975.9","3.464361"]],"a":[],"u":184066860,"seq":112464949557},"cts":1786191785775}
{"topic":"orderbook.50.BTCUSDT","ts":1786191785816,"type":"delta","data":{"s":"BTCUSDT","b":[["64975.9","3.461673"]],"a":[],"u":184066861,"seq":112464949563},"cts":1786191785810}
{"topic":"orderbook.50.BTCUSDT","ts":1786191785856,"type":"delta","data":{"s":"BTCUSDT","b":[],"a":[["64979.5","0.020522"],["64980.7","0"]],"u":184066862,"seq":112464949572},"cts":1786191785853}
{"topic":"orderbook.50.BTCUSDT","ts":1786191785876,"type":"delta","data":{"s":"BTCUSDT","b":[["64974.4","0.200093"]],"a":[],"u":184066863,"seq":112464949574},"cts":1786191785868}
