{"success":true,"ret_msg":"subscribe","conn_id":"d9avrat34tmf5pih98i0-6bn1n","op":"subscribe"}
{"topic":"orderbook.50.BTCUSDT","ts":1786875957276,"type":"snapshot","data":{"s":"BTCUSDT","b":[["63002.4","1.832567"],["63001.5","0.350034"],["63001.3","0.004413"],["63000.3","0.005885"],["63000","0.01209"],["62999.4","0.033594"],["62999.3","0.007356"],["62998.5","1.149735"],["62998.3","0.008828"],["62998.1","0.000158"],["62997.3","0.001738"],["62996.9","0.019615"],["62996.8","0.033595"],["62996.7","0.00052"],["62996.1","0.040597"],["62995.7","0.000156"],["62995.5","0.05"],["62994.1","0.415996"],["62994","0.045864"],["62993.8","0.03418"],["62993.3","0.671124"],["62993","0.00287"],["62992.9","0.120721"],["62992.5","1.190618"],["62992.4","0.01619"],["62992","0.238174"],["62991.4","0.057582"],["62991.1","0.09514"],["62990.7","0.119133"],["62990.6","0.079534"],["62990.4","0.1064"],["62990.3","0.000198"],["62990.2","0.169133"],["62990.1","0.007"],["62989.8","0.08437"],["62989.7","0.079414"],["62989.1","0.015867"],["62988.6","0.435087"],["62988.5","0.157794"],["62988.3","0.068565"],["62988","0.079381"],["62987.6","0.0525"],["62987.4","0.0025"],["62986.8","0.119148"],["62986.3","0.007"],["62985.9","0.285527"],["62985.8","0.157798"],["62985.7","0.158823"],["62985.6","0.209723"],["62985.4","0.0025"]],"a":[["63002.5","0.897013"],["63003.1","0.0025"],["63003.5","0.034594"],["63003.6","0.0157"],["63004.1","0.110143"],["63004.8","0.03012"],["63005.3","0.001819"],["63005.5","0.057574"],["63006.1","0.651574"],["63006.3","0.029221"],["63006.4","0.440158"],["63006.5","1.587137"],["63006.6","0.079423"],["63006.7","0.000086"],["63007","0.064355"],["63007.3","0.039708"],["63007.4","0.003638"],["63007.6","0.476118"],["63007.8","0.020184"],["63007.9","0.0033"],["63008.4","0.004547"],["63008.6","0.069671"],["63008.8","0.040597"],["63008.9","0.008787"],["63009","0.031969"],["63009.1","0.039711"],["63009.3","0.03"],["63009.4","0.005457"],["63009.8","1.190292"],["63009.9","0.043153"],["63010.1","0.1501"],["63010.5","0.032547"],["63011","0.166282"],["63011.1","0.417843"],["63011.5","0.040645"],["63011.6","0.000156"],["63012","0.107312"],["63012.7","0.039201"],["63013.7","0.127733"],["63013.8","0.229421"],["63014.5","0.007"],["63014.7","0.033385"],["63015","0.053127"],["63015.2","0.10638"],["63015.5","0.018374"],["63016.7","0.000571"],["63016.8","0.525456"],["63017.4","0.222419"],["63017.6","0.001166"],["63017.8","0.1501"]],"u":197232062,"seq":112674745987},"cts":1786875957269}
{"topic":"orderbook.50.BTCUSDT","ts":1786875958196,"type":"delta","data":{"s":"BTCUSDT","b":[["62994.7","0.001588"],["62992.9","0.119133"],["62985.4","0"]],"a":[["63002.5","0.880868"]],"u":197232063,"seq":112674746054},"cts":1786875958195}
{"topic":"orderbook.50.BTCUSDT","ts":1786875958218,"type":"delta","data":{"s":"BTCUSDT","b":[["62994.7","0"],["62985.4","0.0025"]],"a":[],"u":197232064,"seq":112674746064},"cts":1786875958216}
{"topic":"orderbook.50.BTCUSDT","ts":1786875958236,"type":"delta","data":{"s":"BTCUSDT","b":[["63002.4","1.834155"]],"a":[],"u":197232065,"seq":112674746066},"cts":1786875958220}
{"topic":"orderbook.50.BTCUSDT","ts":1786875958276,"type":"delta","data":{"s":"BTCUSDT","b":[],"a":[["63012","0.07935"]],"u":197232066,"seq":112674746077},"cts":1786875958268}
{"topic":"orderbook.50.BTCUSDT","ts":1786875958436,"type":"delta","data":{"s":"BTCUSDT","b":[],"a":[["63010.7","0.142975"],["63017.8","0"]],"u":197232067,"seq":112674746098},"cts":1786875958431}
{"topic":"orderbook.50.BTCUSDT","ts":1786875959018,"type":"delta","data":{"s":"BTCUSDT","b":[],"a":[["63011","0.294015"]],"u":197232068,"seq":112674746131},"cts":1786875959001}
{"topic":"orderbook.50.BTCUSDT","ts":1786875960416,"type":"delta","data":{"s":"BTCUSDT","b":[],"a":[["63006.4","0.042435"],["63011","0.166282"]],"u":197232069,"seq":112674746236},"cts":1786875960415}
{"topic":"orderbook.50.BTCUSDT","ts":1786875961116,"type":"delta","data":{"s":"BTCUSDT","b":[],"a":[["63002.5","0.878878"]],"u":197232070,"seq":112674746278},"cts":1786875961112}
{"topic":"orderbook.50.BTCUSDT","ts":1786875961196,"type":"delta","data":{"s":"BTCUSDT","b":[["63002.4","1.83589"]],"a":[],"u":197232071,"seq":112674746287},"cts":1786875961192}
{"topic":"orderbook.50.BTCUSDT","ts":1786875961356,"type":"delta","data":{"s":"BTCUSDT","b":[["63002.4","1.834003"]],"a":[],"u":197232072,"seq":112674746304},"cts":1786875961350}
{"topic":"orderbook.50.BTCUSDT","ts":1786875961476,"type":"delta","data":{"s":"BTCUSDT","b":[],"a":[["63011","0.294015"]],"u":197232073,"seq":112674746336},"cts":1786875961473}
{"topic":"orderbook.50.BTCUSDT","ts":1786875962256,"type":"delta","data":{"s":"BTCUSDT","b":[["63002.4","1.832415"]],"a":[],"u":197232074,"seq":112674746394},"cts":1786875962247}
{"topic":"orderbook.50.BTCUSDT","ts":1786875963575,"type":"delta","data":{"s":"BTCUSDT","b":[],"a":[["63002.5","0.879715"]],"u":197232075,"seq":112674746504},"cts":1786875963567}
{"topic":"orderbook.50.BTCUSDT","ts":1786875964756,"type":"delta","data":{"s":"BTCUSDT","b":[["62997.3","0"],["62985.1","0.006991"]],"a":[],"u":197232076,"seq":112674746582},"cts":1786875964753}
{"topic":"orderbook.50.BTCUSDT","ts":1786875965276,"type":"delta","data":{"s":"BTCUSDT","b":[["62986.3","0"],["62984.9","0.045669"]],"a":[["63014.5","0"],["63017.8","0.1501"]],"u":197232077,"seq":112674746606},"cts":1786875965274}
{"topic":"orderbook.50.BTCUSDT","ts":1786875965296,"type":"delta","data":{"s":"BTCUSDT","b":[["62986.3","0.007"],["62984.9","0"]],"a":[["63014.5","0.007"],["63017.8","0"]],"u":197232078,"seq":112674746611},"cts":1786875965292}
{"topic":"orderbook.50.BTCUSDT","ts":1786875966196,"type":"delta","data":{"s":"BTCUSDT","b":[["63002.4","1.83068"]],"a":[],"u":197232079,"seq":112674746664},"cts":1786875966191}
{"topic":"orderbook.50.BTCUSDT","ts":1786875966276,"type":"delta","data":{"s":"BTCUSDT","b":[["62990.1","0"],["62986.3","0"],["62984.9","0.045669"],["62984.3","0.00012"]],"a":[["63014.5","0"],["63017.8","0.1501"]],"u":197232080,"seq":112674746679},"cts":1786875966273}
{"topic":"orderbook.50.BTCUSDT","ts":1786875966296,"type":"delta","data":{"s":"BTCUSDT","b":[["62990.1","0.007"],["62986.3","0.007"],["62984.9","0"],["62984.3","0"]],"a":[["63014.5","0.007"],["63017.8","0"]],"u":197232081,"seq":112674746691},"cts":1786875966284}
{"topic":"orderbook.50.BTCUSDT","ts":1786875966436,"type":"delta","data":{"s":"BTCUSDT","b":[["62998.9","0.001738"],["62985.1","0"]],"a":[],"u":197232082,"seq":112674746705},"cts":1786875966428}
{"topic":"orderbook.50.BTCUSDT","ts":1786875966996,"type":"delta","data":{"s":"BTCUSDT","b":[["62991.4","0"],["62985.1","0.006991"]],"a":[],"u":197232083,"seq":112674746757},"cts":1786875966984}
{"topic":"orderbook.50.BTCUSDT","ts":1786875967256,"type":"delta","data":{"s":"BTCUSDT","b":[],"a":[["63002.5","0.878878"]],"u":197232084,"seq":112674746773},"cts":1786875967245}
{"topic":"orderbook.50.BTCUSDT","ts":1786875967276,"type":"delta","data":{"s":"BTCUSDT","b":[["62990.1","0"],["62984.9","0.045669"]],"a":[],"u":197232085,"seq":112674746777},"cts":1786875967274}
{"topic":"orderbook.50.BTCUSDT","ts":1786875967296,"type":"delta","data":{"s":"BTCUSDT","b":[["62990.1","0.007"],["62984.9","0"]],"a":[],"u":197232086,"seq":112674746785},"cts":1786875967279}
{"topic":"orderbook.50.BTCUSDT","ts":1786875967995,"type":"delta","data":{"s":"BTCUSDT","b":[],"a":[["63005.5","0"],["63017.8","0.1501"]],"u":197232087,"seq":112674746823},"cts":1786875967987}
{"topic":"orderbook.50.BTCUSDT","ts":1786875968836,"type":"delta","data":{"s":"BTCUSDT","b":[],"a":[["63002.5","0.881527"]],"u":197232088,"seq":112674746886},"cts":1786875968815}
{"topic":"orderbook.50.BTCUSDT","ts":1786875969136,"type":"delta","data":{"s":"BTCUSDT","b":[],"a":[["63002.5","0.882914"]],"u":197232089,"seq":112674746900},"cts":1786875969126}
{"topic":"orderbook.50.BTCUSDT","ts":1786875969536,"type":"delta","data":{"s":"BTCUSDT","b":[["62993.1","0.056641"],["62985.1","0"]],"a":[["63007.2","0.056628"],["63017.8","0"]],"u":197232090,"seq":112674746930},"cts":1786875969534}
{"topic":"orderbook.50.BTCUSDT","ts":1786875969556,"type":"delta","data":{"s":"BTCUSDT","b":[["62994.1","0.584597"]],"a":[],"u":197232091,"seq":112674746932},"cts":1786875969542}
{"topic":"orderbook.50.BTCUSDT","ts":1786875970736,"type":"delta","data":{"s":"BTCUSDT","b":[["62985.4","0"],["62985.1","0.006991"]],"a":[],"u":197232092,"seq":112674747010},"cts":1786875970730}
{"topic":"orderbook.50.BTCUSDT","ts":1786875970756,"type":"delta","data":{"s":"BTCUSDT","b":[],"a":[["63003.1","0.005"]],"u":197232093,"seq":112674747018},"cts":1786875970753}
{"topic":"orderbook.50.BTCUSDT","ts":1786875971195,"type":"delta","data":{"s":"BTCUSDT","b":[["63002.4","1.832415"]],"a":[],"u":197232094,"seq":112674747039},"cts":1786875971182}
{"topic":"orderbook.50.BTCUSDT","ts":1786875971296,"type":"delta","data":{"s":"BTCUSDT","b":[],"a":[["63002.5","0.881527"]],"u":197232095,"seq":112674747056},"cts":1786875971285}
{"topic":"orderbook.50.BTCUSDT","ts":1786875972996,"type":"delta","data":{"s":"BTCUSDT","b":[],"a":[["63007","0"],["63017.8","0.1501"]],"u":197232096,"seq":112674747177},"cts":1786875972984}
{"topic":"orderbook.50.BTCUSDT","ts":1786875973396,"type":"delta","data":{"s":"BTCUSDT","b":[],"a":[["63002.5","0.88732"]],"u":197232097,"seq":112674747217},"cts":1786875973393}
{"topic":"orderbook.50.BTCUSDT","ts":1786875973996,"type":"delta","data":{"s":"BTCUSDT","b":[["62989.8","0.02"]],"a":[],"u":197232098,"seq":112674747250},"cts":1786875973984}
{"topic":"orderbook.50.BTCUSDT","ts":1786875974536,"type":"delta","data":{"s":"BTCUSDT","b":[["62991.7","0.062309"],["62985.1","0"]],"a":[["63008.9","0.071079"]],"u":197232099,"seq":112674747278},"cts":1786875974533}
{"topic":"orderbook.50.BTCUSDT","ts":1786875976196,"type":"delta","data":{"s":"BTCUSDT","b":[["63002.4","1.83068"]],"a":[],"u":197232100,"seq":112674747382},"cts":1786875976179}
{"topic":"orderbook.50.BTCUSDT","ts":1786875976236,"type":"delta","data":{"s":"BTCUSDT","b":[],"a":[["63002.5","0.884727"]],"u":197232101,"seq":112674747389},"cts":1786875976230}
{"topic":"orderbook.50.BTCUSDT","ts":1786875976256,"type":"delta","data":{"s":"BTCUSDT","b":[],"a":[["63006","1.099471"],["63017.8","0"]],"u":197232102,"seq":112674747391},"cts":1786875976242}
{"topic":"orderbook.50.BTCUSDT","ts":1786875976316,"type":"delta","data":{"s":"BTCUSDT","b":[["62995.7","0"],["62995.1","0.000156"]],"a":[["63011.6","0"],["63012.8","0.000156"]],"u":197232103,"seq":112674747405},"cts":1786875976315}
{"topic":"orderbook.50.BTCUSDT","ts":1786875976396,"type":"delta","data":{"s":"BTCUSDT","b":[],"a":[["63006","0"],["63009.8","0"],["63017.8","0.1501"],["63018","0.014258"]],"u":197232104,"seq":112674747413},"cts":1786875976394}
{"topic":"orderbook.50.BTCUSDT","ts":1786875976416,"type":"delta","data":{"s":"BTCUSDT","b":[],"a":[["63007.6","0.119729"]],"u":197232105,"seq":112674747415},"cts":1786875976399}
{"topic":"orderbook.50.BTCUSDT","ts":1786875976476,"type":"delta","data":{"s":"BTCUSDT","b":[["62996.7","0.000676"],["62995.1","0"],["62985.1","0.006991"]],"a":[["63012.8","0"],["63013.7","0.127889"],["63018.3","0.120252"]],"u":197232106,"seq":112674747421},"cts":1786875976463}
{"topic":"orderbook.50.BTCUSDT","ts":1786875976716,"type":"delta","data":{"s":"BTCUSDT","b":[],"a":[["63009.8","1.190292"],["63018.3","0"]],"u":197232107,"seq":112674747435},"cts":1786875976695}
{"topic":"orderbook.50.BTCUSDT","ts":1786875976736,"type":"delta","data":{"s":"BTCUSDT","b":[],"a":[["63007.6","0.501876"]],"u":197232108,"seq":112674747439},"cts":1786875976721}
{"topic":"orderbook.50.BTCUSDT","ts":1786875976795,"type":"delta","data":{"s":"BTCUSDT","b":[["62996.7","0.00052"],["62995.1","0.000156"],["62985.1","0"]],"a":[["63006","1.099471"],["63012.5","0.000156"],["63013.7","0.127733"],["63017.8","0"],["63018","0"]],"u":197232109,"seq":112674747465},"cts":1786875976794}
{"topic":"orderbook.50.BTCUSDT","ts":1786875976996,"type":"delta","data":{"s":"BTCUSDT","b":[],"a":[["63006","0"],["63009.3","1.220301"],["63009.8","0"],["63017.8","0.1501"],["63018","0.014258"]],"u":197232110,"seq":112674747485},"cts":1786875976994}
{"topic":"orderbook.50.BTCUSDT","ts":1786875977196,"type":"delta","data":{"s":"BTCUSDT","b":[],"a":[["63006","1.099471"],["63018","0"]],"u":197232111,"seq":112674747497},"cts":1786875977194}
{"topic":"orderbook.50.BTCUSDT","ts":1786875977396,"type":"delta","data":{"s":"BTCUSDT","b":[],"a":[["63006","0"],["63018","0.014258"]],"u":197232112,"seq":112674747520},"cts":1786875977394}
{"topic":"orderbook.50.BTCUSDT","ts":1786875977716,"type":"delta","data":{"s":"BTCUSDT","b":[],"a":[["63006","1.099471"],["63018","0"]],"u":197232113,"seq":112674747541},"cts":1786875977694}
{"topic":"orderbook.50.BTCUSDT","ts":1786875977796,"type":"delta","data":{"s":"BTCUSDT","b":[],"a":[["63006","0"],["63018","0.014258"]],"u":197232114,"seq":112674747548},"cts":1786875977794}
{"topic":"orderbook.50.BTCUSDT","ts":1786875977995,"type":"delta","data":{"s":"BTCUSDT","b":[],"a":[["63006","1.099471"],["63018","0"]],"u":197232115,"seq":112674747584},"cts":1786875977994}
{"topic":"orderbook.50.BTCUSDT","ts":1786875978196,"type":"delta","data":{"s":"BTCUSDT","b":[],"a":[["63006","0"],["63018","0.014258"]],"u":197232116,"seq":112674747598},"cts":1786875978194}
{"topic":"orderbook.50.BTCUSDT","ts":1786875978396,"type":"delta","data":{"s":"BTCUSDT","b":[],"a":[["63006","1.099471"],["63018","0"]],"u":197232117,"seq":112674747617},"cts":1786875978394}
{"topic":"orderbook.50.BTCUSDT","ts":1786875978556,"type":"delta","data":{"s":"BTCUSDT","b":[],"a":[["63002.5","0.886186"]],"u":197232118,"seq":112674747625},"cts":1786875978549}
{"topic":"orderbook.50.BTCUSDT","ts":1786875978736,"type":"delta","data":{"s":"BTCUSDT","b":[],"a":[["63010","0.254145"],["63017.8","0"]],"u":197232119,"seq":112674747636},"cts":1786875978733}
{"topic":"orderbook.50.BTCUSDT","ts":1786875979296,"type":"delta","data":{"s":"BTCUSDT","b":[["62986.3","0"],["62985.1","0.006991"]],"a":[["63014.5","0"],["63017.8","0.1501"]],"u":197232120,"seq":112674747678},"cts":1786875979294}
{"topic":"orderbook.50.BTCUSDT","ts":1786875979316,"type":"delta","data":{"s":"BTCUSDT","b":[["62986.3","0.007"],["62985.1","0"]],"a":[["63014.5","0.007"],["63017.8","0"]],"u":197232121,"seq":112674747684},"cts":1786875979306}
{"topic":"orderbook.50.BTCUSDT","ts":1786875980295,"type":"delta","data":{"s":"BTCUSDT","b":[["62986.3","0"],["62985.1","0.006991"]],"a":[["63014.5","0"],["63017.8","0.1501"]],"u":197232122,"seq":112674747751},"cts":1786875980294}
{"topic":"orderbook.50.BTCUSDT","ts":1786875980316,"type":"delta","data":{"s":"BTCUSDT","b":[["62986.3","0.007"],["62985.1","0"]],"a":[["63014.5","0.007"],["63017.8","0"]],"u":197232123,"seq":112674747756},"cts":1786875980301}
{"topic":"orderbook.50.BTCUSDT","ts":1786875980596,"type":"delta","data":{"s":"BTCUSDT","b":[],"a":[["63006","0"],["63017.8","0.1501"]],"u":197232124,"seq":112674747781},"cts":1786875980594}
{"topic":"orderbook.50.BTCUSDT","ts":1786875980796,"type":"delta","data":{"s":"BTCUSDT","b":[],"a":[["63006","1.099471"],["63017.8","0"]],"u":197232125,"seq":112674747796},"cts":1786875980794}
{"topic":"orderbook.50.BTCUSDT","ts":1786875980996,"type":"delta","data":{"s":"BTCUSDT","b":[],"a":[["63006","0"],["63017.8","0.1501"]],"u":197232126,"seq":112674747818},"cts":1786875980994}
{"topic":"orderbook.50.BTCUSDT","ts":1786875981096,"type":"delta","data":{"s":"BTCUSDT","b":[],"a":[["63002.5","0.884727"],["63006","1.099471"],["63017.8","0"]],"u":197232127,"seq":112674747827},"cts":1786875981094}
{"topic":"orderbook.50.BTCUSDT","ts":1786875981196,"type":"delta","data":{"s":"BTCUSDT","b":[["63002.4","1.832415"]],"a":[["63004.1","0"],["63007.8","0.000184"],["63010.9","0.127733"],["63011","0.166282"],["63011.1","0.02012"],["63012.3","0.397723"],["63013.7","0"]],"u":197232128,"seq":112674747860},"cts":1786875981195}
{"topic":"orderbook.50.BTCUSDT","ts":1786875981216,"type":"delta","data":{"s":"BTCUSDT","b":[["62988.6","0.307354"]],"a":[["63006","0"],["63009.3","0.03"],["63017.8","0.1501"]],"u":197232129,"seq":112674747974},"cts":1786875981215}
{"topic":"orderbook.50.BTCUSDT","ts":1786875981236,"type":"delta","data":{"s":"BTCUSDT","b":[],"a":[["63007.6","0"],["63008.8","0.237058"],["63018","0.014258"]],"u":197232130,"seq":112674748044},"cts":1786875981234}
{"topic":"orderbook.50.BTCUSDT","ts":1786875981256,"type":"delta","data":{"s":"BTCUSDT","b":[["62998.9","0"],["62985.1","0.006991"]],"a":[],"u":197232131,"seq":112674748102},"cts":1786875981254}
{"topic":"orderbook.50.BTCUSDT","ts":1786875981296,"type":"delta","data":{"s":"BTCUSDT","b":[["62996.7","0.000676"],["62995.1","0"],["62990.1","0"],["62986.3","0"],["62984.9","0.030669"],["62984.3","0.00012"],["62984","0.000238"]],"a":[["63012.5","0"],["63013.7","0.000156"],["63014.5","0"],["63018.3","0.113252"]],"u":197232132,"seq":112674748113},"cts":1786875981294}
{"topic":"orderbook.50.BTCUSDT","ts":1786875981316,"type":"delta","data":{"s":"BTCUSDT","b":[["62990.1","0.007"],["62986.3","0.007"],["62984.3","0"],["62984","0"]],"a":[["63014.5","0.007"],["63018.3","0"]],"u":197232133,"seq":112674748123},"cts":1786875981314}
{"topic":"orderbook.50.BTCUSDT","ts":1786875981376,"type":"delta","data":{"s":"BTCUSDT","b":[],"a":[["63004.1","0.110143"],["63018","0"]],"u":197232134,"seq":112674748140},"cts":1786875981373}
{"topic":"orderbook.50.BTCUSDT","ts":1786875981996,"type":"delta","data":{"s":"BTCUSDT","b":[],"a":[["63008.6","0"],["63018","0.014258"]],"u":197232135,"seq":112674748204},"cts":1786875981984}
{"topic":"orderbook.50.BTCUSDT","ts":1786875982116,"type":"delta","data":{"s":"BTCUSDT","b":[],"a":[["63002.5","0.734627"],["63010.9","0"],["63018.3","0.120252"]],"u":197232136,"seq":112674748260},"cts":1786875982114}
{"topic":"orderbook.50.BTCUSDT","ts":1786875982995,"type":"delta","data":{"s":"BTCUSDT","b":[],"a":[["63009.8","1.190292"],["63018.3","0"]],"u":197232137,"seq":112674748497},"cts":1786875982994}
{"topic":"orderbook.50.BTCUSDT","ts":1786875983019,"type":"delta","data":{"s":"BTCUSDT","b":[],"a":[["63008.8","0.567243"]],"u":197232138,"seq":112674748500},"cts":1786875983018}
{"topic":"orderbook.50.BTCUSDT","ts":1786875983036,"type":"delta","data":{"s":"BTCUSDT","b":[],"a":[["63002.5","0.704627"]],"u":197232139,"seq":112674748519},"cts":1786875983033}
{"topic":"orderbook.50.BTCUSDT","ts":1786875983056,"type":"delta","data":{"s":"BTCUSDT","b":[],"a":[["63009.8","0"],["63018.3","0.120252"]],"u":197232140,"seq":112674748548},"cts":1786875983054}
{"topic":"orderbook.50.BTCUSDT","ts":1786875983076,"type":"delta","data":{"s":"BTCUSDT","b":[],"a":[["63008.8","0.237058"]],"u":197232141,"seq":112674748560},"cts":1786875983064}
{"topic":"orderbook.50.BTCUSDT","ts":1786875983096,"type":"delta","data":{"s":"BTCUSDT","b":[],"a":[["63009.8","1.190292"],["63018.3","0"]],"u":197232142,"seq":112674748584},"cts":1786875983094}
{"topic":"orderbook.50.BTCUSDT","ts":1786875983116,"type":"delta","data":{"s":"BTCUSDT","b":[],"a":[["63008.8","0.567243"]],"u":197232143,"seq":112674748587},"cts":1786875983105}
{"topic":"orderbook.50.BTCUSDT","ts":1786875983196,"type":"delta","data":{"s":"BTCUSDT","b":[],"a":[["63009.8","0"],["63018.3","0.120252"]],"u":197232144,"seq":112674748653},"cts":1786875983194}
{"topic":"orderbook.50.BTCUSDT","ts":1786875983216,"type":"delta","data":{"s":"BTCUSDT","b":[],"a":[["63008.8","0.237058"]],"u":197232145,"seq":112674748654},"cts":1786875983198}
{"topic":"orderbook.50.BTCUSDT","ts":1786875983616,"type":"delta","data":{"s":"BTCUSDT","b":[],"a":[["63002.5","0.696642"]],"u":197232146,"seq":112674748699},"cts":1786875983615}
{"topic":"orderbook.50.BTCUSDT","ts":1786875983916,"type":"delta","data":{"s":"BTCUSDT","b":[],"a":[["63002.5","0.700098"]],"u":197232147,"seq":112674748757},"cts":1786875983913}
{"topic":"orderbook.50.BTCUSDT","ts":1786875984316,"type":"delta","data":{"s":"BTCUSDT","b":[],"a":[["63010.7","0"],["63018.5","0.039726"]],"u":197232148,"seq":112674748804},"cts":1786875984310}
{"topic":"orderbook.50.BTCUSDT","ts":1786875984376,"type":"delta","data":{"s":"BTCUSDT","b":[["62999","0.001738"],["62984.9","0"]],"a":[],"u":197232149,"seq":112674748810},"cts":1786875984365}
{"topic":"orderbook.50.BTCUSDT","ts":1786875984476,"type":"delta","data":{"s":"BTCUSDT","b":[],"a":[["63014.6","0.72"],["63018.5","0"]],"u":197232150,"seq":112674748813},"cts":1786875984467}
{"topic":"orderbook.50.BTCUSDT","ts":1786875984496,"type":"delta","data":{"s":"BTCUSDT","b":[],"a":[["63013.8","0.40776"]],"u":197232151,"seq":112674748820},"cts":1786875984486}
{"topic":"orderbook.50.BTCUSDT","ts":1786875984516,"type":"delta","data":{"s":"BTCUSDT","b":[],"a":[["63013.7","0.127889"]],"u":197232152,"seq":112674748823},"cts":1786875984501}
{"topic":"orderbook.50.BTCUSDT","ts":1786875984536,"type":"delta","data":{"s":"BTCUSDT","b":[["62990.5","0.068565"],["62988.3","0"]],"a":[["63010.8","0.071892"],["63018.3","0"]],"u":197232153,"seq":112674748825},"cts":1786875984533}
{"topic":"orderbook.50.BTCUSDT","ts":1786875984636,"type":"delta","data":{"s":"BTCUSDT","b":[],"a":[["63014.6","0"],["63018.3","0.120252"]],"u":197232154,"seq":112674748833},"cts":1786875984626}
{"topic":"orderbook.50.BTCUSDT","ts":1786875984656,"type":"delta","data":{"s":"BTCUSDT","b":[],"a":[["63013.8","0.222171"]],"u":197232155,"seq":112674748837},"cts":1786875984642}
{"topic":"orderbook.50.BTCUSDT","ts":1786875984797,"type":"delta","data":{"s":"BTCUSDT","b":[],"a":[["63010.7","0.085046"],["63018.3","0"]],"u":197232156,"seq":112674748851},"cts":1786875984790}
{"topic":"orderbook.50.BTCUSDT","ts":1786875985116,"type":"delta","data":{"s":"BTCUSDT","b":[],"a":[["63010.7","0"],["63018.3","0.120252"]],"u":197232157,"seq":112674748873},"cts":1786875985102}
{"topic":"orderbook.50.BTCUSDT","ts":1786875985276,"type":"delta","data":{"s":"BTCUSDT","b":[],"a":[["63014.6","0.72"],["63018.3","0"]],"u":197232158,"seq":112674748903},"cts":1786875985262}
{"topic":"orderbook.50.BTCUSDT","ts":1786875985296,"type":"delta","data":{"s":"BTCUSDT","b":[],"a":[["63013.8","0.408687"]],"u":197232159,"seq":112674748905},"cts":1786875985280}
{"topic":"orderbook.50.BTCUSDT","ts":1786875985736,"type":"delta","data":{"s":"BTCUSDT","b":[],"a":[["63014.6","0"],["63018.3","0.120252"]],"u":197232160,"seq":112674748954},"cts":1786875985732}
{"topic":"orderbook.50.BTCUSDT","ts":1786875985756,"type":"delta","data":{"s":"BTCUSDT","b":[],"a":[["63013.8","0.222171"]],"u":197232161,"seq":112674748966},"cts":1786875985746}
{"topic":"orderbook.50.BTCUSDT","ts":1786875985916,"type":"delta","data":{"s":"BTCUSDT","b":[],"a":[["63010.7","0.084157"],["63018.3","0"]],"u":197232162,"seq":112674748976},"cts":1786875985908}
{"topic":"orderbook.50.BTCUSDT","ts":1786875986196,"type":"delta","data":{"s":"BTCUSDT","b":[["63002.4","1.83068"]],"a":[],"u":197232163,"seq":112674748997},"cts":1786875986180}
{"topic":"orderbook.50.BTCUSDT","ts":1786875986218,"type":"delta","data":{"s":"BTCUSDT","b":[],"a":[["63010.7","0"],["63018.3","0.120252"]],"u":197232164,"seq":112674749000},"cts":1786875986214}
{"topic":"orderbook.50.BTCUSDT","ts":1786875986236,"type":"delta","data":{"s":"BTCUSDT","b":[],"a":[["63002.5","0.696642"]],"u":197232165,"seq":112674749012},"cts":1786875986234}
{"topic":"orderbook.50.BTCUSDT","ts":1786875986516,"type":"delta","data":{"s":"BTCUSDT","b":[],"a":[["63014.6","0.72"],["63018.3","0"]],"u":197232166,"seq":112674749068},"cts":1786875986508}
{"topic":"orderbook.50.BTCUSDT","ts":1786875986535,"type":"delta","data":{"s":"BTCUSDT","b":[],"a":[["63013.8","0.408687"],["63014.6","0"],["63018.3","0.120252"]],"u":197232167,"seq":112674749074},"cts":1786875986532}
{"topic":"orderbook.50.BTCUSDT","ts":1786875986556,"type":"delta","data":{"s":"BTCUSDT","b":[],"a":[["63013.8","0.222171"]],"u":197232168,"seq":112674749080},"cts":1786875986549}
{"topic":"orderbook.50.BTCUSDT","ts":1786875986716,"type":"delta","data":{"s":"BTCUSDT","b":[],"a":[["63010.7","0.078418"],["63018.3","0"]],"u":197232169,"seq":112674749089},"cts":1786875986705}
{"topic":"orderbook.50.BTCUSDT","ts":1786875987916,"type":"delta","data":{"s":"BTCUSDT","b":[],"a":[["63002.5","0.846105"]],"u":197232170,"seq":112674749216},"cts":1786875987915}
{"topic":"orderbook.50.BTCUSDT","ts":1786875988296,"type":"delta","data":{"s":"BTCUSDT","b":[],"a":[["63010.7","0"],["63018.3","0.120252"]],"u":197232171,"seq":112674749268},"cts":1786875988284}
{"topic":"orderbook.50.BTCUSDT","ts":1786875988496,"type":"delta","data":{"s":"BTCUSDT","b":[],"a":[["63002.5","0.848027"]],"u":197232172,"seq":112674749290},"cts":1786875988488}
{"topic":"orderbook.50.BTCUSDT","ts":1786875988556,"type":"delta","data":{"s":"BTCUSDT","b":[],"a":[["63013.8","0.408687"],["63014.6","0.72"],["63018.3","0"]],"u":197232173,"seq":112674749298},"cts":1786875988554}
{"topic":"orderbook.50.BTCUSDT","ts":1786875988756,"type":"delta","data":{"s":"BTCUSDT","b":[],"a":[["63013.8","0.222171"],["63014.6","0"],["63018.3","0.120252"]],"u":197232174,"seq":112674749317},"cts":1786875988754}
{"topic":"orderbook.50.BTCUSDT","ts":1786875988776,"type":"delta","data":{"s":"BTCUSDT","b":[["63002.4","1.832715"]],"a":[],"u":197232175,"seq":112674749320},"cts":1786875988758}
{"topic":"orderbook.50.BTCUSDT","ts":1786875988935,"type":"delta","data":{"s":"BTCUSDT","b":[],"a":[["63010.7","0.069881"],["63018.3","0"]],"u":197232176,"seq":112674749326},"cts":1786875988917}
{"topic":"orderbook.50.BTCUSDT","ts":1786875989076,"type":"delta","data":{"s":"BTCUSDT","b":[],"a":[["63010.7","0"],["63018.3","0.120252"]],"u":197232177,"seq":112674749349},"cts":1786875989074}
{"topic":"orderbook.50.BTCUSDT","ts":1786875989376,"type":"delta","data":{"s":"BTCUSDT","b":[],"a":[["63014.6","0.72"],["63018.3","0"]],"u":197232178,"seq":112674749412},"cts":1786875989366}
{"topic":"orderbook.50.BTCUSDT","ts":1786875989396,"type":"delta","data":{"s":"BTCUSDT","b":[],"a":[["63013.8","0.408687"]],"u":197232179,"seq":112674749413},"cts":1786875989378}
{"topic":"orderbook.50.BTCUSDT","ts":1786875989556,"type":"delta","data":{"s":"BTCUSDT","b":[],"a":[["63014.6","0"],["63018.3","0.120252"]],"u":197232180,"seq":112674749436},"cts":1786875989551}
{"topic":"orderbook.50.BTCUSDT","ts":1786875989576,"type":"delta","data":{"s":"BTCUSDT","b":[],"a":[["63013.8","0.222171"]],"u":197232181,"seq":112674749448},"cts":1786875989567}
{"topic":"orderbook.50.BTCUSDT","ts":1786875989796,"type":"delta","data":{"s":"BTCUSDT","b":[],"a":[["63010.7","0.081002"],["63018.3","0"]],"u":197232182,"seq":112674749519},"cts":1786875989792}
{"topic":"orderbook.50.BTCUSDT","ts":1786875990219,"type":"delta","data":{"s":"BTCUSDT","b":[],"a":[["63009.8","1.190292"],["63018","0"]],"u":197232183,"seq":112674749639},"cts":1786875990195}
{"topic":"orderbook.50.BTCUSDT","ts":1786875990236,"type":"delta","data":{"s":"BTCUSDT","b":[],"a":[["63008.8","0.567243"]],"u":197232184,"seq":112674749644},"cts":1786875990228}
{"topic":"orderbook.50.BTCUSDT","ts":1786875990296,"type":"delta","data":{"s":"BTCUSDT","b":[["62996.7","0.00052"],["62995.2","0.000156"],["62985.1","0"]],"a":[["63012.2","0.000156"],["63013.7","0.127733"],["63017.8","0"]],"u":197232185,"seq":112674749669},"cts":1786875990284}
{"topic":"orderbook.50.BTCUSDT","ts":1786875990316,"type":"delta","data":{"s":"BTCUSDT","b":[],"a":[["63009.8","0"],["63017.8","0.1501"]],"u":197232186,"seq":112674749678},"cts":1786875990312}
{"topic":"orderbook.50.BTCUSDT","ts":1786875990336,"type":"delta","data":{"s":"BTCUSDT","b":[],"a":[["63008.8","0.237058"]],"u":197232187,"seq":112674749697},"cts":1786875990334}
{"topic":"orderbook.50.BTCUSDT","ts":1786875990395,"type":"delta","data":{"s":"BTCUSDT","b":[["62996.7","0.000676"],["62995.2","0"],["62985.1","0.006991"]],"a":[["63012.2","0"],["63013.6","0.000156"]],"u":197232188,"seq":112674749723},"cts":1786875990383}
{"topic":"orderbook.50.BTCUSDT","ts":1786875990416,"type":"delta","data":{"s":"BTCUSDT","b":[],"a":[["63009.8","1.190292"],["63017.8","0"]],"u":197232189,"seq":112674749734},"cts":1786875990402}
{"topic":"orderbook.50.BTCUSDT","ts":1786875990436,"type":"delta","data":{"s":"BTCUSDT","b":[],"a":[["63008.8","0.567243"]],"u":197232190,"seq":112674749736},"cts":1786875990431}
{"topic":"orderbook.50.BTCUSDT","ts":1786875990495,"type":"delta","data":{"s":"BTCUSDT","b":[["62996.7","0.00052"],["62995.2","0.000156"],["62985.1","0"]],"a":[["63009.8","0"],["63012.2","0.000156"],["63013.6","0"],["63017.8","0.1501"]],"u":197232191,"seq":112674749740},"cts":1786875990494}
{"topic":"orderbook.50.BTCUSDT","ts":1786875990516,"type":"delta","data":{"s":"BTCUSDT","b":[],"a":[["63008.8","0.237058"]],"u":197232192,"seq":112674749751},"cts":1786875990501}
{"topic":"orderbook.50.BTCUSDT","ts":1786875990576,"type":"delta","data":{"s":"BTCUSDT","b":[["62996.7","0.000676"],["62995.2","0"],["62985.1","0.006991"]],"a":[["63002.5","0.878027"],["63012.2","0"],["63013.6","0.000156"]],"u":197232193,"seq":112674749800},"cts":1786875990569}
{"topic":"orderbook.50.BTCUSDT","ts":1786875990596,"type":"delta","data":{"s":"BTCUSDT","b":[],"a":[["63009.8","1.190292"],["63017.8","0"]],"u":197232194,"seq":112674749812},"cts":1786875990582}
{"topic":"orderbook.50.BTCUSDT","ts":1786875990616,"type":"delta","data":{"s":"BTCUSDT","b":[],"a":[["63008.8","0.567243"]],"u":197232195,"seq":112674749823},"cts":1786875990601}
{"topic":"orderbook.50.BTCUSDT","ts":1786875990656,"type":"delta","data":{"s":"BTCUSDT","b":[["62989.1","0"],["62984.9","0.030669"]],"a":[],"u":197232196,"seq":112674749828},"cts":1786875990643}
{"topic":"orderbook.50.BTCUSDT","ts":1786875990676,"type":"delta","data":{"s":"BTCUSDT","b":[["62996.7","0.00052"],["62995.2","0.000156"],["62984.9","0"]],"a":[["63012.2","0.000156"],["63013.6","0"]],"u":197232197,"seq":112674749845},"cts":1786875990672}
{"topic":"orderbook.50.BTCUSDT","ts":1786875990696,"type":"delta","data":{"s":"BTCUSDT","b":[],"a":[["63009.8","0"],["63017.8","0.1501"]],"u":197232198,"seq":112674749847},"cts":1786875990694}
{"topic":"orderbook.50.BTCUSDT","ts":1786875990716,"type":"delta","data":{"s":"BTCUSDT","b":[],"a":[["63008.8","0.237058"]],"u":197232199,"seq":112674749858},"cts":1786875990702}
{"topic":"orderbook.50.BTCUSDT","ts":1786875990816,"type":"delta","data":{"s":"BTCUSDT","b":[],"a":[["63009.8","1.190292"],["63017.8","0"]],"u":197232200,"seq":112674749878},"cts":1786875990804}
{"topic":"orderbook.50.BTCUSDT","ts":1786875990835,"type":"delta","data":{"s":"BTCUSDT","b":[],"a":[["63008.8","0.567243"]],"u":197232201,"seq":112674749887},"cts":1786875990834}
{"topic":"orderbook.50.BTCUSDT","ts":1786875990876,"type":"delta","data":{"s":"BTCUSDT","b":[],"a":[["63003.1","0.0075"]],"u":197232202,"seq":112674749891},"cts":1786875990873}
{"topic":"orderbook.50.BTCUSDT","ts":1786875990896,"type":"delta","data":{"s":"BTCUSDT","b":[],"a":[["63009.8","0"],["63017.8","0.1501"]],"u":197232203,"seq":112674749893},"cts":1786875990894}
{"topic":"orderbook.50.BTCUSDT","ts":1786875990916,"type":"delta","data":{"s":"BTCUSDT","b":[],"a":[["63008.8","0.237058"]],"u":197232204,"seq":112674749925},"cts":1786875990913}
{"topic":"orderbook.50.BTCUSDT","ts":1786875990976,"type":"delta","data":{"s":"BTCUSDT","b":[["62996.7","0.000676"],["62995.2","0"],["62984.9","0.030669"]],"a":[["63012.2","0"],["63013.6","0.000156"]],"u":197232205,"seq":112674749943},"cts":1786875990964}
{"topic":"orderbook.50.BTCUSDT","ts":1786875991019,"type":"delta","data":{"s":"BTCUSDT","b":[],"a":[["63009.8","1.190292"],["63017.8","0"]],"u":197232206,"seq":112674749955},"cts":1786875990994}
{"topic":"orderbook.50.BTCUSDT","ts":1786875991036,"type":"delta","data":{"s":"BTCUSDT","b":[],"a":[["63008.8","0.567243"]],"u":197232207,"seq":112674749969},"cts":1786875991024}
{"topic":"orderbook.50.BTCUSDT","ts":1786875991095,"type":"delta","data":{"s":"BTCUSDT","b":[["62996.7","0.00052"],["62995.2","0.000156"],["62984.9","0"]],"a":[["63012.2","0.000156"],["63013.6","0"]],"u":197232208,"seq":112674750039},"cts":1786875991089}
{"topic":"orderbook.50.BTCUSDT","ts":1786875991116,"type":"delta","data":{"s":"BTCUSDT","b":[],"a":[["63009.8","0"],["63017.8","0.1501"]],"u":197232209,"seq":112674750058},"cts":1786875991114}
{"topic":"orderbook.50.BTCUSDT","ts":1786875991136,"type":"delta","data":{"s":"BTCUSDT","b":[],"a":[["63008.8","0.237058"]],"u":197232210,"seq":112674750070},"cts":1786875991120}
{"topic":"orderbook.50.BTCUSDT","ts":1786875991156,"type":"delta","data":{"s":"BTCUSDT","b":[],"a":[["63010.7","0"],["63018","0.014258"]],"u":197232211,"seq":112674750091},"cts":1786875991154}
{"topic":"orderbook.50.BTCUSDT","ts":1786875991196,"type":"delta","data":{"s":"BTCUSDT","b":[["63002.4","1.83445"]],"a":[],"u":197232212,"seq":112674750110},"cts":1786875991190}
{"topic":"orderbook.50.BTCUSDT","ts":1786875991316,"type":"delta","data":{"s":"BTCUSDT","b":[],"a":[["63014.6","0.72"],["63018","0"]],"u":197232213,"seq":112674750162},"cts":1786875991314}
{"topic":"orderbook.50.BTCUSDT","ts":1786875991336,"type":"delta","data":{"s":"BTCUSDT","b":[],"a":[["63013.8","0.408687"]],"u":197232214,"seq":112674750179},"cts":1786875991334}
{"topic":"orderbook.50.BTCUSDT","ts":1786875991375,"type":"delta","data":{"s":"BTCUSDT","b":[],"a":[["63002.5","0.846105"]],"u":197232215,"seq":112674750198},"cts":1786875991374}
{"topic":"orderbook.50.BTCUSDT","ts":1786875991476,"type":"delta","data":{"s":"BTCUSDT","b":[],"a":[["63014.6","0"],["63018","0.014258"]],"u":197232216,"seq":112674750217},"cts":1786875991458}
{"topic":"orderbook.50.BTCUSDT","ts":1786875991496,"type":"delta","data":{"s":"BTCUSDT","b":[],"a":[["63013.8","0.222171"]],"u":197232217,"seq":112674750229},"cts":1786875991493}
{"topic":"orderbook.50.BTCUSDT","ts":1786875991636,"type":"delta","data":{"s":"BTCUSDT","b":[],"a":[["63010.7","0.073224"],["63018","0"]],"u":197232218,"seq":112674750285},"cts":1786875991617}
{"topic":"orderbook.50.BTCUSDT","ts":1786875992316,"type":"delta","data":{"s":"BTCUSDT","b":[],"a":[["63014.5","0"],["63018","0.014258"]],"u":197232219,"seq":112674750697},"cts":1786875992314}
{"topic":"orderbook.50.BTCUSDT","ts":1786875992336,"type":"delta","data":{"s":"BTCUSDT","b":[],"a":[["63014.5","0.007"],["63018","0"]],"u":197232220,"seq":112674750711},"cts":1786875992332}
{"topic":"orderbook.50.BTCUSDT","ts":1786875993036,"type":"delta","data":{"s":"BTCUSDT","b":[["63002.4","1.833813"]],"a":[],"u":197232221,"seq":112674751070},"cts":1786875993033}
{"topic":"orderbook.50.BTCUSDT","ts":1786875993316,"type":"delta","data":{"s":"BTCUSDT","b":[["62986.3","0"],["62984.9","0.030669"]],"a":[["63014.5","0"],["63018","0.014258"]],"u":197232222,"seq":112674751195},"cts":1786875993315}
{"topic":"orderbook.50.BTCUSDT","ts":1786875993336,"type":"delta","data":{"s":"BTCUSDT","b":[["62986.3","0.007"],["62984.9","0"]],"a":[["63014.5","0.007"],["63018","0"]],"u":197232223,"seq":112674751199},"cts":1786875993321}
{"topic":"orderbook.50.BTCUSDT","ts":1786875993976,"type":"delta","data":{"s":"BTCUSDT","b":[],"a":[["63006.5","0"],["63007","1.587125"]],"u":197232224,"seq":112674751429},"cts":1786875993973}
{"topic":"orderbook.50.BTCUSDT","ts":1786875994176,"type":"delta","data":{"s":"BTCUSDT","b":[],"a":[["63002.5","0.847196"]],"u":197232225,"seq":112674751600},"cts":1786875994174}
{"topic":"orderbook.50.BTCUSDT","ts":1786875994456,"type":"delta","data":{"s":"BTCUSDT","b":[],"a":[["63006.5","1.587137"],["63007","0"]],"u":197232226,"seq":112674751739},"cts":1786875994451}
{"topic":"orderbook.50.BTCUSDT","ts":1786875994696,"type":"delta","data":{"s":"BTCUSDT","b":[["62991","0.015867"],["62985.1","0"]],"a":[],"u":197232227,"seq":112674751812},"cts":1786875994681}
{"topic":"orderbook.50.BTCUSDT","ts":1786875995276,"type":"delta","data":{"s":"BTCUSDT","b":[],"a":[["63010.7","0"],["63018","0.014258"]],"u":197232228,"seq":112674752106},"cts":1786875995272}
{"topic":"orderbook.50.BTCUSDT","ts":1786875995316,"type":"delta","data":{"s":"BTCUSDT","b":[["62990.1","0"],["62985.1","0.006991"]],"a":[],"u":197232229,"seq":112674752133},"cts":1786875995314}
{"topic":"orderbook.50.BTCUSDT","ts":1786875995336,"type":"delta","data":{"s":"BTCUSDT","b":[["62990.1","0.007"],["62985.1","0"]],"a":[],"u":197232230,"seq":112674752160},"cts":1786875995329}
{"topic":"orderbook.50.BTCUSDT","ts":1786875995436,"type":"delta","data":{"s":"BTCUSDT","b":[],"a":[["63014.6","0.678666"],["63018","0"]],"u":197232231,"seq":112674752205},"cts":1786875995430}
{"topic":"orderbook.50.BTCUSDT","ts":1786875995456,"type":"delta","data":{"s":"BTCUSDT","b":[],"a":[["63013.8","0.396349"]],"u":197232232,"seq":112674752217},"cts":1786875995454}
{"topic":"orderbook.50.BTCUSDT","ts":1786875995596,"type":"delta","data":{"s":"BTCUSDT","b":[],"a":[["63014.6","0"],["63018","0.014258"]],"u":197232233,"seq":112674752275},"cts":1786875995589}
{"topic":"orderbook.50.BTCUSDT","ts":1786875995616,"type":"delta","data":{"s":"BTCUSDT","b":[],"a":[["63013.8","0.222171"]],"u":197232234,"seq":112674752294},"cts":1786875995610}
{"topic":"orderbook.50.BTCUSDT","ts":1786875995776,"type":"delta","data":{"s":"BTCUSDT","b":[],"a":[["63010.7","0.065209"],["63018","0"]],"u":197232235,"seq":112674752343},"cts":1786875995766}
{"topic":"orderbook.50.BTCUSDT","ts":1786875996196,"type":"delta","data":{"s":"BTCUSDT","b":[["63002.4","1.832078"]],"a":[],"u":197232236,"seq":112674752378},"cts":1786875996182}
{"topic":"orderbook.50.BTCUSDT","ts":1786875996236,"type":"delta","data":{"s":"BTCUSDT","b":[],"a":[["63010.7","0"],["63018","0.014258"]],"u":197232237,"seq":112674752382},"cts":1786875996231}
{"topic":"orderbook.50.BTCUSDT","ts":1786875996396,"type":"delta","data":{"s":"BTCUSDT","b":[],"a":[["63014.6","0.72"],["63018","0"]],"u":197232238,"seq":112674752411},"cts":1786875996393}
{"topic":"orderbook.50.BTCUSDT","ts":1786875996416,"type":"delta","data":{"s":"BTCUSDT","b":[],"a":[["63013.8","0.408687"]],"u":197232239,"seq":112674752412},"cts":1786875996398}
{"topic":"orderbook.50.BTCUSDT","ts":1786875996696,"type":"delta","data":{"s":"BTCUSDT","b":[],"a":[["63014.6","0"],["63018","0.014258"]],"u":197232240,"seq":112674752428},"cts":1786875996684}
{"topic":"orderbook.50.BTCUSDT","ts":1786875996716,"type":"delta","data":{"s":"BTCUSDT","b":[],"a":[["63013.8","0.222171"]],"u":197232241,"seq":112674752429},"cts":1786875996697}
{"topic":"orderbook.50.BTCUSDT","ts":1786875996916,"type":"delta","data":{"s":"BTCUSDT","b":[],"a":[["63002.5","0.846252"]],"u":197232242,"seq":112674752448},"cts":1786875996914}
{"topic":"orderbook.50.BTCUSDT","ts":1786875997016,"type":"delta","data":{"s":"BTCUSDT","b":[],"a":[["63010.7","0.06787"],["63018","0"]],"u":197232243,"seq":112674752486},"cts":1786875997001}
{"topic":"orderbook.50.BTCUSDT","ts":1786875997096,"type":"delta","data":{"s":"BTCUSDT","b":[],"a":[["63002.5","0.845161"]],"u":197232244,"seq":112674752567},"cts":1786875997093}
{"topic":"orderbook.50.BTCUSDT","ts":1786875998136,"type":"delta","data":{"s":"BTCUSDT","b":[],"a":[["63010.7","0"],["63018","0.014258"]],"u":197232245,"seq":112674752754},"cts":1786875998134}
{"topic":"orderbook.50.BTCUSDT","ts":1786875998196,"type":"delta","data":{"s":"BTCUSDT","b":[["63002.4","1.830183"]],"a":[],"u":197232246,"seq":112674752769},"cts":1786875998179}
{"topic":"orderbook.50.BTCUSDT","ts":1786875998296,"type":"delta","data":{"s":"BTCUSDT","b":[],"a":[["63014.6","0.72"],["63018","0"]],"u":197232247,"seq":112674752814},"cts":1786875998292}
{"topic":"orderbook.50.BTCUSDT","ts":1786875998316,"type":"delta","data":{"s":"BTCUSDT","b":[],"a":[["63013.8","0.408687"]],"u":197232248,"seq":112674752818},"cts":1786875998308}
{"topic":"orderbook.50.BTCUSDT","ts":1786875998756,"type":"delta","data":{"s":"BTCUSDT","b":[],"a":[["63013.8","0.222171"],["63014.6","0"],["63018","0.014258"]],"u":197232249,"seq":112674753034},"cts":1786875998754}
{"topic":"orderbook.50.BTCUSDT","ts":1786875998836,"type":"delta","data":{"s":"BTCUSDT","b":[],"a":[["63002.5","0.8099"]],"u":197232250,"seq":112674753065},"cts":1786875998832}
{"topic":"orderbook.50.BTCUSDT","ts":1786875998936,"type":"delta","data":{"s":"BTCUSDT","b":[],"a":[["63010.7","0.067872"],["63018","0"]],"u":197232251,"seq":112674753108},"cts":1786875998931}
{"topic":"orderbook.50.BTCUSDT","ts":1786875999316,"type":"delta","data":{"s":"BTCUSDT","b":[],"a":[["63010.7","0"],["63018","0.014258"]],"u":197232252,"seq":112674753251},"cts":1786875999313}
{"topic":"orderbook.50.BTCUSDT","ts":1786875999356,"type":"delta","data":{"s":"BTCUSDT","b":[["62999","0"],["62985.1","0.006991"]],"a":[],"u":197232253,"seq":112674753285},"cts":1786875999354}
{"topic":"orderbook.50.BTCUSDT","ts":1786875999416,"type":"delta","data":{"s":"BTCUSDT","b":[],"a":[["63002.5","0.811499"],["63014.6","0.72"],["63018","0"]],"u":197232254,"seq":112674753323},"cts":1786875999414}
{"topic":"orderbook.50.BTCUSDT","ts":1786875999435,"type":"delta","data":{"s":"BTCUSDT","b":[],"a":[["63013.8","0.408687"]],"u":197232255,"seq":112674753337},"cts":1786875999431}
{"topic":"orderbook.50.BTCUSDT","ts":1786875999576,"type":"delta","data":{"s":"BTCUSDT","b":[],"a":[["63014.6","0"],["63018","0.014258"]],"u":197232256,"seq":112674753415},"cts":1786875999572}
{"topic":"orderbook.50.BTCUSDT","ts":1786875999596,"type":"delta","data":{"s":"BTCUSDT","b":[],"a":[["63013.8","0.222171"]],"u":197232257,"seq":112674753436},"cts":1786875999588}
{"topic":"orderbook.50.BTCUSDT","ts":1786875999936,"type":"delta","data":{"s":"BTCUSDT","b":[],"a":[["63010.7","0.067793"],["63018","0"]],"u":197232258,"seq":112674753567},"cts":1786875999922}
{"topic":"orderbook.50.BTCUSDT","ts":1786876000075,"type":"delta","data":{"s":"BTCUSDT","b":[],"a":[["63010.7","0"],["63018","0.014258"]],"u":197232259,"seq":112674753638},"cts":1786876000074}
{"topic":"orderbook.50.BTCUSDT","ts":1786876000236,"type":"delta","data":{"s":"BTCUSDT","b":[],"a":[["63014.6","0.718398"],["63018","0"]],"u":197232260,"seq":112674753718},"cts":1786876000232}
